Workbook
Name Print_Area_MI: #N/A
Name Print_Titles_MI: #N/A
Name SPRING: #N/A
Name SPRING2: #N/A
Name TABLES: #N/A

Sheet Gila Hot Springs
CH4: New Mexico Interstate Stream Commission | CL4: Gila Hot Springs Ditch near Pinos Altos, New Mexico
A6: Gila Hot Springs near Pinos Altos, New Mexico (09429980)
CH7: Source: | CI7: Gila River - West Fork | CM7: Gila - San Francisco Basins
CH8: Location: | CI8: 33.1155, -108.1219 | CM8: DAILY DISCHARGE IN C/F/S
E9: JANUARY | L9: FEBRUARY | S9: MARCH | Z9: APRIL | AG9: MAY | AN9: JUNE | AU9: JULY | BB9: AUGUST | BI9: SEPTEMBER | BP9: OCTOBER | BW9: NOVEMBER | CD9: DECEMBER | CH9: Measuring Device: 12" Parshall Flume
A10: 2025
D11: PEN | E11: GHT | F11: CFS | K11: PEN | L11: GHT | M11: CFS | R11: PEN | S11: GHT | T11: CFS | Y11: PEN | Z11: GHT | AA11: CFS | AF11: PEN | AG11: GHT | AH11: CFS | AM11: PEN | AN11: GHT | AO11: CFS | AT11: PEN | AU11: GHT | AV11: CFS | BA11: PEN | BB11: GHT | BC11: CFS | BH11: PEN | BI11: GHT | BJ11: CFS | BO11: PEN | BP11: GHT | BQ11: CFS | BV11: PEN | BW11: GHT | BX11: CFS | CC11: PEN | CD11: GHT | CE11: CFS | CH11: Calendar Year 2025 | CR11: Site ID# 09429980
A12: DAY | B12: HRS | C12: GHT | D12: SHIFT | E12: AMOUNT | F12: PER TABLE | I12: HRS | J12: GHT | K12: SHIFT | L12: AMOUNT | M12: PER TABLE | P12: HRS | Q12: GHT | R12: SHIFT | S12: AMOUNT | T12: PER TABLE | W12: HRS | X12: GHT | Y12: SHIFT | Z12: AMOUNT | AA12: PER TABLE | AD12: HRS | AE12: GHT | AF12: SHIFT | AG12: AMOUNT | AH12: PER TABLE | AK12: HRS | AL12: GHT | AM12: SHIFT | AN12: AMOUNT | AO12: PER TABLE | AR12: HRS | AS12: GHT | AT12: SHIFT | AU12: AMOUNT | AV12: PER TABLE | AY12: HRS | AZ12: GHT | BA12: SHIFT | BB12: AMOUNT | BC12: PER TABLE | BF12: HRS | BG12: GHT | BH12: SHIFT | BI12: AMOUNT | BJ12: PER TABLE | BM12: HRS | BN12: GHT | BO12: SHIFT | BP12: AMOUNT | BQ12: PER TABLE | BT12: HRS | BU12: GHT | BV12: SHIFT | BW12: AMOUNT | BX12: PER TABLE | CA12: HRS | CB12: GHT | CC12: SHIFT | CD12: AMOUNT | CE12: PER TABLE | CH12: JANUARY | CI12: FEBRUARY | CJ12: MARCH | CK12: APRIL | CL12: MAY | CM12: JUNE | CN12: JULY | CO12: AUGUST | CP12: SEPTEMBER | CQ12: OCTOBER | CR12: NOVEMBER | CS12: DECEMBER
A13: - | B13: - | C13: - | D13: - | E13: - | F13: - | I13: - | J13: - | K13: - | L13: - | M13: - | P13: - | Q13: - | R13: - | S13: - | T13: - | W13: - | Y13: - | Z13: - | AA13: - | AD13: - | AE13: - | AF13: - | AG13: - | AH13: - | AK13: - | AL13: - | AM13: - | AN13: - | AO13: - | AR13: - | AS13: - | AT13: - | AU13: - | AV13: - | AY13: - | AZ13: - | BA13: - | BB13: - | BC13: - | BF13: - | BG13: - | BH13: - | BI13: - | BJ13: - | BM13: - | BN13: - | BO13: - | BP13: - | BQ13: - | BT13: - | BU13: - | BV13: - | BW13: - | BX13: - | CA13: - | CB13: - | CC13: - | CD13: - | CE13: -
A14: 1 | C14: 0 | D14: 0 | E14: =IF(C14=" ",0,ROUND(SUM(C14:D14),2)) -> 0 | F14: =VLOOKUP(E14,$IK$5000:$IU$5300,3) -> 0 | I14: 0 | J14: 0 | K14: 0 | L14: =IF(J14=" ",0,ROUND(SUM(J14:K14),2)) -> 0 | M14: =VLOOKUP(L14,$IK$5000:$IU$5300,3) -> 0 | S14: =IF(Q14=" ",0,ROUND(SUM(Q14:R14),2)) -> 0 | T14: =VLOOKUP(S14,$IK$5000:$IU$5300,3) -> 0 | X14: 0.81 | Z14: =IF(X14=" ",0,ROUND(SUM(X14:Y14),2)) -> 0.81 | AA14: =VLOOKUP(Z14,$IK$5000:$IU$5300,3) -> 2.9 | AE14: 0.93 | AG14: =IF(AE14=" ",0,ROUND(SUM(AE14:AF14),2)) -> 0.93 | AH14: =VLOOKUP(AG14,$IK$5000:$IU$5300,3) -> 3.6 | AL14: 0.65 | AN14: =IF(AL14=" ",0,ROUND(SUM(AL14:AM14),2)) -> 0.65 | AO14: =VLOOKUP(AN14,$IK$5000:$IU$5300,3) -> 2.1 | AS14: 0.06 | AU14: =IF(AS14=" ",0,ROUND(SUM(AS14:AT14),2)) -> 0.06 | AV14: =VLOOKUP(AU14,$IK$5000:$IU$5300,3) -> 0.168 | AZ14: 0.42 | BB14: =IF(AZ14=" ",0,ROUND(SUM(AZ14:BA14),2)) -> 0.42 | BC14: =VLOOKUP(BB14,$IK$5000:$IU$5300,3) -> 1.176 | BG14: 0.69 | BI14: =IF(BG14=" ",0,ROUND(SUM(BG14:BH14),2)) -> 0.69 | BJ14: =VLOOKUP(BI14,$IK$5000:$IU$5300,3) -> 2.3 | BN14: 0.6 | BP14: =IF(BN14=" ",0,ROUND(SUM(BN14:BO14),2)) -> 0.6 | BQ14: =VLOOKUP(BP14,$IK$5000:$IU$5300,3) -> 1.8 | BU14: 0.55 | BW14: =IF(BU14=" ",0,ROUND(SUM(BU14:BV14),2)) -> 0.55 | BX14: =VLOOKUP(BW14,$IK$5000:$IU$5300,3) -> 1.6 | CD14: =IF(CB14=" ",0,ROUND(SUM(CB14:CC14),2)) -> 0 | CE14: =VLOOKUP(CD14,$IK$5000:$IU$5300,3) -> 0 | CG14: 1 | CH14: =IF(B14=" ",F14,B14*F14/24) -> 0 | CI14: =IF(I14=" ",M14,I14*M14/24) -> 0 | CJ14: =IF(P14=" ",T14,P14*T14/24) -> 0 | CK14: =IF(W14=" ",AA14,W14*AA14/24) -> 2.9 | CL14: =IF(AD14=" ",AH14,AD14*AH14/24) -> 3.6 | CM14: =IF(AK14=" ",AO14,AK14*AO14/24) -> 2.1 | CN14: =IF(AR14=" ",AV14,AR14*AV14/24) -> 0.168 | CO14: =IF(AY14=" ",BC14,AY14*BC14/24) -> 1.176 | CP14: =IF(BF14=" ",BJ14,BF14*BJ14/24) -> 2.3 | CQ14: =IF(BM14=" ",BQ14,BM14*BQ14/24) -> 1.8 | CR14: =IF(BT14=" ",BX14,BT14*BX14/24) -> 1.6 | CS14: =IF(CA14=" ",CE14,CA14*CE14/24) -> 0
A15: 2 | C15: 0 | D15: 0 | E15: =IF(C15=" ",0,ROUND(SUM(C15:D15),2)) -> 0 | F15: =VLOOKUP(E15,$IK$5000:$IU$5300,3) -> 0 | I15: 0 | J15: 0 | K15: 0 | L15: =IF(J15=" ",0,ROUND(SUM(J15:K15),2)) -> 0 | M15: =VLOOKUP(L15,$IK$5000:$IU$5300,3) -> 0 | S15: =IF(Q15=" ",0,ROUND(SUM(Q15:R15),2)) -> 0 | T15: =VLOOKUP(S15,$IK$5000:$IU$5300,3) -> 0 | X15: 0.7 | Z15: =IF(X15=" ",0,ROUND(SUM(X15:Y15),2)) -> 0.7 | AA15: =VLOOKUP(Z15,$IK$5000:$IU$5300,3) -> 2.3 | AE15: 0.88 | AG15: =IF(AE15=" ",0,ROUND(SUM(AE15:AF15),2)) -> 0.88 | AH15: =VLOOKUP(AG15,$IK$5000:$IU$5300,3) -> 3.3 | AL15: 0.85 | AN15: =IF(AL15=" ",0,ROUND(SUM(AL15:AM15),2)) -> 0.85 | AO15: =VLOOKUP(AN15,$IK$5000:$IU$5300,3) -> 3.1 | AS15: 0.41 | AU15: =IF(AS15=" ",0,ROUND(SUM(AS15:AT15),2)) -> 0.41 | AV15: =VLOOKUP(AU15,$IK$5000:$IU$5300,3) -> 1.148 | AZ15: 0.43 | BB15: =IF(AZ15=" ",0,ROUND(SUM(AZ15:BA15),2)) -> 0.43 | BC15: =VLOOKUP(BB15,$IK$5000:$IU$5300,3) -> 1.204 | BG15: 0.83 | BI15: =IF(BG15=" ",0,ROUND(SUM(BG15:BH15),2)) -> 0.83 | BJ15: =VLOOKUP(BI15,$IK$5000:$IU$5300,3) -> 3 | BN15: 0.85 | BP15: =IF(BN15=" ",0,ROUND(SUM(BN15:BO15),2)) -> 0.85 | BQ15: =VLOOKUP(BP15,$IK$5000:$IU$5300,3) -> 3.1 | BU15: 0.55 | BW15: =IF(BU15=" ",0,ROUND(SUM(BU15:BV15),2)) -> 0.55 | BX15: =VLOOKUP(BW15,$IK$5000:$IU$5300,3) -> 1.6 | CD15: =IF(CB15=" ",0,ROUND(SUM(CB15:CC15),2)) -> 0 | CE15: =VLOOKUP(CD15,$IK$5000:$IU$5300,3) -> 0 | CG15: 2 | CH15: =IF(B15=" ",F15,B15*F15/24) -> 0 | CI15: =IF(I15=" ",M15,I15*M15/24) -> 0 | CJ15: =IF(P15=" ",T15,P15*T15/24) -> 0 | CK15: =IF(W15=" ",AA15,W15*AA15/24) -> 2.3 | CL15: =IF(AD15=" ",AH15,AD15*AH15/24) -> 3.3 | CM15: =IF(AK15=" ",AO15,AK15*AO15/24) -> 3.1 | CN15: =IF(AR15=" ",AV15,AR15*AV15/24) -> 1.148 | CO15: =IF(AY15=" ",BC15,AY15*BC15/24) -> 1.204 | CP15: =IF(BF15=" ",BJ15,BF15*BJ15/24) -> 3 | CQ15: =IF(BM15=" ",BQ15,BM15*BQ15/24) -> 3.1 | CR15: =IF(BT15=" ",BX15,BT15*BX15/24) -> 1.6 | CS15: =IF(CA15=" ",CE15,CA15*CE15/24) -> 0
A16: 3 | C16: 0 | D16: 0 | E16: =IF(C16=" ",0,ROUND(SUM(C16:D16),2)) -> 0 | F16: =VLOOKUP(E16,$IK$5000:$IU$5300,3) -> 0 | I16: 0 | J16: 0 | K16: 0 | L16: =IF(J16=" ",0,ROUND(SUM(J16:K16),2)) -> 0 | M16: =VLOOKUP(L16,$IK$5000:$IU$5300,3) -> 0 | S16: =IF(Q16=" ",0,ROUND(SUM(Q16:R16),2)) -> 0 | T16: =VLOOKUP(S16,$IK$5000:$IU$5300,3) -> 0 | X16: 0.69 | Z16: =IF(X16=" ",0,ROUND(SUM(X16:Y16),2)) -> 0.69 | AA16: =VLOOKUP(Z16,$IK$5000:$IU$5300,3) -> 2.3 | AE16: 0.96 | AG16: =IF(AE16=" ",0,ROUND(SUM(AE16:AF16),2)) -> 0.96 | AH16: =VLOOKUP(AG16,$IK$5000:$IU$5300,3) -> 3.8 | AL16: 0.96 | AN16: =IF(AL16=" ",0,ROUND(SUM(AL16:AM16),2)) -> 0.96 | AO16: =VLOOKUP(AN16,$IK$5000:$IU$5300,3) -> 3.8 | AS16: 0.68 | AU16: =IF(AS16=" ",0,ROUND(SUM(AS16:AT16),2)) -> 0.68 | AV16: =VLOOKUP(AU16,$IK$5000:$IU$5300,3) -> 2.2 | AZ16: 0.43 | BB16: =IF(AZ16=" ",0,ROUND(SUM(AZ16:BA16),2)) -> 0.43 | BC16: =VLOOKUP(BB16,$IK$5000:$IU$5300,3) -> 1.204 | BG16: 0.93 | BI16: =IF(BG16=" ",0,ROUND(SUM(BG16:BH16),2)) -> 0.93 | BJ16: =VLOOKUP(BI16,$IK$5000:$IU$5300,3) -> 3.6 | BN16: 0.85 | BP16: =IF(BN16=" ",0,ROUND(SUM(BN16:BO16),2)) -> 0.85 | BQ16: =VLOOKUP(BP16,$IK$5000:$IU$5300,3) -> 3.1 | BU16: 0.55 | BW16: =IF(BU16=" ",0,ROUND(SUM(BU16:BV16),2)) -> 0.55 | BX16: =VLOOKUP(BW16,$IK$5000:$IU$5300,3) -> 1.6 | CD16: =IF(CB16=" ",0,ROUND(SUM(CB16:CC16),2)) -> 0 | CE16: =VLOOKUP(CD16,$IK$5000:$IU$5300,3) -> 0 | CG16: 3 | CH16: =IF(B16=" ",F16,B16*F16/24) -> 0 | CI16: =IF(I16=" ",M16,I16*M16/24) -> 0 | CJ16: =IF(P16=" ",T16,P16*T16/24) -> 0 | CK16: =IF(W16=" ",AA16,W16*AA16/24) -> 2.3 | CL16: =IF(AD16=" ",AH16,AD16*AH16/24) -> 3.8 | CM16: =IF(AK16=" ",AO16,AK16*AO16/24) -> 3.8 | CN16: =IF(AR16=" ",AV16,AR16*AV16/24) -> 2.2 | CO16: =IF(AY16=" ",BC16,AY16*BC16/24) -> 1.204 | CP16: =IF(BF16=" ",BJ16,BF16*BJ16/24) -> 3.6 | CQ16: =IF(BM16=" ",BQ16,BM16*BQ16/24) -> 3.1 | CR16: =IF(BT16=" ",BX16,BT16*BX16/24) -> 1.6 | CS16: =IF(CA16=" ",CE16,CA16*CE16/24) -> 0
A17: 4 | C17: 0 | D17: 0 | E17: =IF(C17=" ",0,ROUND(SUM(C17:D17),2)) -> 0 | F17: =VLOOKUP(E17,$IK$5000:$IU$5300,3) -> 0 | I17: 0 | J17: 0 | K17: 0 | L17: =IF(J17=" ",0,ROUND(SUM(J17:K17),2)) -> 0 | M17: =VLOOKUP(L17,$IK$5000:$IU$5300,3) -> 0 | S17: =IF(Q17=" ",0,ROUND(SUM(Q17:R17),2)) -> 0 | T17: =VLOOKUP(S17,$IK$5000:$IU$5300,3) -> 0 | X17: 0.69 | Z17: =IF(X17=" ",0,ROUND(SUM(X17:Y17),2)) -> 0.69 | AA17: =VLOOKUP(Z17,$IK$5000:$IU$5300,3) -> 2.3 | AE17: 0.87 | AG17: =IF(AE17=" ",0,ROUND(SUM(AE17:AF17),2)) -> 0.87 | AH17: =VLOOKUP(AG17,$IK$5000:$IU$5300,3) -> 3.2 | AL17: 0.82 | AN17: =IF(AL17=" ",0,ROUND(SUM(AL17:AM17),2)) -> 0.82 | AO17: =VLOOKUP(AN17,$IK$5000:$IU$5300,3) -> 3 | AS17: 0.74 | AU17: =IF(AS17=" ",0,ROUND(SUM(AS17:AT17),2)) -> 0.74 | AV17: =VLOOKUP(AU17,$IK$5000:$IU$5300,3) -> 2.5 | AZ17: 0.53 | BB17: =IF(AZ17=" ",0,ROUND(SUM(AZ17:BA17),2)) -> 0.53 | BC17: =VLOOKUP(BB17,$IK$5000:$IU$5300,3) -> 1.5 | BG17: 0.71 | BI17: =IF(BG17=" ",0,ROUND(SUM(BG17:BH17),2)) -> 0.71 | BJ17: =VLOOKUP(BI17,$IK$5000:$IU$5300,3) -> 2.4 | BN17: 0.66 | BP17: =IF(BN17=" ",0,ROUND(SUM(BN17:BO17),2)) -> 0.66 | BQ17: =VLOOKUP(BP17,$IK$5000:$IU$5300,3) -> 2.1 | BU17: 0.55 | BW17: =IF(BU17=" ",0,ROUND(SUM(BU17:BV17),2)) -> 0.55 | BX17: =VLOOKUP(BW17,$IK$5000:$IU$5300,3) -> 1.6 | CD17: =IF(CB17=" ",0,ROUND(SUM(CB17:CC17),2)) -> 0 | CE17: =VLOOKUP(CD17,$IK$5000:$IU$5300,3) -> 0 | CG17: 4 | CH17: =IF(B17=" ",F17,B17*F17/24) -> 0 | CI17: =IF(I17=" ",M17,I17*M17/24) -> 0 | CJ17: =IF(P17=" ",T17,P17*T17/24) -> 0 | CK17: =IF(W17=" ",AA17,W17*AA17/24) -> 2.3 | CL17: =IF(AD17=" ",AH17,AD17*AH17/24) -> 3.2 | CM17: =IF(AK17=" ",AO17,AK17*AO17/24) -> 3 | CN17: =IF(AR17=" ",AV17,AR17*AV17/24) -> 2.5 | CO17: =IF(AY17=" ",BC17,AY17*BC17/24) -> 1.5 | CP17: =IF(BF17=" ",BJ17,BF17*BJ17/24) -> 2.4 | CQ17: =IF(BM17=" ",BQ17,BM17*BQ17/24) -> 2.1 | CR17: =IF(BT17=" ",BX17,BT17*BX17/24) -> 1.6 | CS17: =IF(CA17=" ",CE17,CA17*CE17/24) -> 0
A18: 5 | C18: 0 | D18: 0 | E18: =IF(C18=" ",0,ROUND(SUM(C18:D18),2)) -> 0 | F18: =VLOOKUP(E18,$IK$5000:$IU$5300,3) -> 0 | I18: 0 | J18: 0 | K18: 0 | L18: =IF(J18=" ",0,ROUND(SUM(J18:K18),2)) -> 0 | M18: =VLOOKUP(L18,$IK$5000:$IU$5300,3) -> 0 | S18: =IF(Q18=" ",0,ROUND(SUM(Q18:R18),2)) -> 0 | T18: =VLOOKUP(S18,$IK$5000:$IU$5300,3) -> 0 | X18: 0.68 | Z18: =IF(X18=" ",0,ROUND(SUM(X18:Y18),2)) -> 0.68 | AA18: =VLOOKUP(Z18,$IK$5000:$IU$5300,3) -> 2.2 | AE18: 0.96 | AG18: =IF(AE18=" ",0,ROUND(SUM(AE18:AF18),2)) -> 0.96 | AH18: =VLOOKUP(AG18,$IK$5000:$IU$5300,3) -> 3.8 | AL18: 0.64 | AN18: =IF(AL18=" ",0,ROUND(SUM(AL18:AM18),2)) -> 0.64 | AO18: =VLOOKUP(AN18,$IK$5000:$IU$5300,3) -> 2 | AS18: 0.94 | AU18: =IF(AS18=" ",0,ROUND(SUM(AS18:AT18),2)) -> 0.94 | AV18: =VLOOKUP(AU18,$IK$5000:$IU$5300,3) -> 3.6 | AZ18: 0.93 | BB18: =IF(AZ18=" ",0,ROUND(SUM(AZ18:BA18),2)) -> 0.93 | BC18: =VLOOKUP(BB18,$IK$5000:$IU$5300,3) -> 3.6 | BG18: 0.8 | BI18: =IF(BG18=" ",0,ROUND(SUM(BG18:BH18),2)) -> 0.8 | BJ18: =VLOOKUP(BI18,$IK$5000:$IU$5300,3) -> 2.8 | BN18: 0.72 | BP18: =IF(BN18=" ",0,ROUND(SUM(BN18:BO18),2)) -> 0.72 | BQ18: =VLOOKUP(BP18,$IK$5000:$IU$5300,3) -> 2.4 | BU18: 0.55 | BW18: =IF(BU18=" ",0,ROUND(SUM(BU18:BV18),2)) -> 0.55 | BX18: =VLOOKUP(BW18,$IK$5000:$IU$5300,3) -> 1.6 | CD18: =IF(CB18=" ",0,ROUND(SUM(CB18:CC18),2)) -> 0 | CE18: =VLOOKUP(CD18,$IK$5000:$IU$5300,3) -> 0 | CG18: 5 | CH18: =IF(B18=" ",F18,B18*F18/24) -> 0 | CI18: =IF(I18=" ",M18,I18*M18/24) -> 0 | CJ18: =IF(P18=" ",T18,P18*T18/24) -> 0 | CK18: =IF(W18=" ",AA18,W18*AA18/24) -> 2.2 | CL18: =IF(AD18=" ",AH18,AD18*AH18/24) -> 3.8 | CM18: =IF(AK18=" ",AO18,AK18*AO18/24) -> 2 | CN18: =IF(AR18=" ",AV18,AR18*AV18/24) -> 3.6 | CO18: =IF(AY18=" ",BC18,AY18*BC18/24) -> 3.6 | CP18: =IF(BF18=" ",BJ18,BF18*BJ18/24) -> 2.8 | CQ18: =IF(BM18=" ",BQ18,BM18*BQ18/24) -> 2.4 | CR18: =IF(BT18=" ",BX18,BT18*BX18/24) -> 1.6 | CS18: =IF(CA18=" ",CE18,CA18*CE18/24) -> 0
A19: 6 | C19: 0 | D19: 0 | E19: =IF(C19=" ",0,ROUND(SUM(C19:D19),2)) -> 0 | F19: =VLOOKUP(E19,$IK$5000:$IU$5300,3) -> 0 | I19: 0 | J19: 0 | K19: 0 | L19: =IF(J19=" ",0,ROUND(SUM(J19:K19),2)) -> 0 | M19: =VLOOKUP(L19,$IK$5000:$IU$5300,3) -> 0 | S19: =IF(Q19=" ",0,ROUND(SUM(Q19:R19),2)) -> 0 | T19: =VLOOKUP(S19,$IK$5000:$IU$5300,3) -> 0 | X19: 0.68 | Z19: =IF(X19=" ",0,ROUND(SUM(X19:Y19),2)) -> 0.68 | AA19: =VLOOKUP(Z19,$IK$5000:$IU$5300,3) -> 2.2 | AE19: 0.95 | AG19: =IF(AE19=" ",0,ROUND(SUM(AE19:AF19),2)) -> 0.95 | AH19: =VLOOKUP(AG19,$IK$5000:$IU$5300,3) -> 3.7 | AL19: 0.78 | AN19: =IF(AL19=" ",0,ROUND(SUM(AL19:AM19),2)) -> 0.78 | AO19: =VLOOKUP(AN19,$IK$5000:$IU$5300,3) -> 2.7 | AS19: 0.89 | AU19: =IF(AS19=" ",0,ROUND(SUM(AS19:AT19),2)) -> 0.89 | AV19: =VLOOKUP(AU19,$IK$5000:$IU$5300,3) -> 3.3 | AZ19: 0.85 | BB19: =IF(AZ19=" ",0,ROUND(SUM(AZ19:BA19),2)) -> 0.85 | BC19: =VLOOKUP(BB19,$IK$5000:$IU$5300,3) -> 3.1 | BG19: 0.72 | BI19: =IF(BG19=" ",0,ROUND(SUM(BG19:BH19),2)) -> 0.72 | BJ19: =VLOOKUP(BI19,$IK$5000:$IU$5300,3) -> 2.4 | BN19: 0.79 | BP19: =IF(BN19=" ",0,ROUND(SUM(BN19:BO19),2)) -> 0.79 | BQ19: =VLOOKUP(BP19,$IK$5000:$IU$5300,3) -> 2.8 | BU19: 0.55 | BW19: =IF(BU19=" ",0,ROUND(SUM(BU19:BV19),2)) -> 0.55 | BX19: =VLOOKUP(BW19,$IK$5000:$IU$5300,3) -> 1.6 | CD19: =IF(CB19=" ",0,ROUND(SUM(CB19:CC19),2)) -> 0 | CE19: =VLOOKUP(CD19,$IK$5000:$IU$5300,3) -> 0 | CG19: 6 | CH19: =IF(B19=" ",F19,B19*F19/24) -> 0 | CI19: =IF(I19=" ",M19,I19*M19/24) -> 0 | CJ19: =IF(P19=" ",T19,P19*T19/24) -> 0 | CK19: =IF(W19=" ",AA19,W19*AA19/24) -> 2.2 | CL19: =IF(AD19=" ",AH19,AD19*AH19/24) -> 3.7 | CM19: =IF(AK19=" ",AO19,AK19*AO19/24) -> 2.7 | CN19: =IF(AR19=" ",AV19,AR19*AV19/24) -> 3.3 | CO19: =IF(AY19=" ",BC19,AY19*BC19/24) -> 3.1 | CP19: =IF(BF19=" ",BJ19,BF19*BJ19/24) -> 2.4 | CQ19: =IF(BM19=" ",BQ19,BM19*BQ19/24) -> 2.8 | CR19: =IF(BT19=" ",BX19,BT19*BX19/24) -> 1.6 | CS19: =IF(CA19=" ",CE19,CA19*CE19/24) -> 0
A20: 7 | C20: 0 | D20: 0 | E20: =IF(C20=" ",0,ROUND(SUM(C20:D20),2)) -> 0 | F20: =VLOOKUP(E20,$IK$5000:$IU$5300,3) -> 0 | L20: =IF(J20=" ",0,ROUND(SUM(J20:K20),2)) -> 0 | M20: =VLOOKUP(L20,$IK$5000:$IU$5300,3) -> 0 | S20: =IF(Q20=" ",0,ROUND(SUM(Q20:R20),2)) -> 0 | T20: =VLOOKUP(S20,$IK$5000:$IU$5300,3) -> 0 | X20: 0.68 | Z20: =IF(X20=" ",0,ROUND(SUM(X20:Y20),2)) -> 0.68 | AA20: =VLOOKUP(Z20,$IK$5000:$IU$5300,3) -> 2.2 | AE20: 0.84 | AG20: =IF(AE20=" ",0,ROUND(SUM(AE20:AF20),2)) -> 0.84 | AH20: =VLOOKUP(AG20,$IK$5000:$IU$5300,3) -> 3.1 | AL20: 0.85 | AN20: =IF(AL20=" ",0,ROUND(SUM(AL20:AM20),2)) -> 0.85 | AO20: =VLOOKUP(AN20,$IK$5000:$IU$5300,3) -> 3.1 | AS20: 0.85 | AU20: =IF(AS20=" ",0,ROUND(SUM(AS20:AT20),2)) -> 0.85 | AV20: =VLOOKUP(AU20,$IK$5000:$IU$5300,3) -> 3.1 | AZ20: 0.87 | BB20: =IF(AZ20=" ",0,ROUND(SUM(AZ20:BA20),2)) -> 0.87 | BC20: =VLOOKUP(BB20,$IK$5000:$IU$5300,3) -> 3.2 | BG20: 0.67 | BI20: =IF(BG20=" ",0,ROUND(SUM(BG20:BH20),2)) -> 0.67 | BJ20: =VLOOKUP(BI20,$IK$5000:$IU$5300,3) -> 2.2 | BN20: 0.48 | BP20: =IF(BN20=" ",0,ROUND(SUM(BN20:BO20),2)) -> 0.48 | BQ20: =VLOOKUP(BP20,$IK$5000:$IU$5300,3) -> 1.344 | BU20: 0.55 | BW20: =IF(BU20=" ",0,ROUND(SUM(BU20:BV20),2)) -> 0.55 | BX20: =VLOOKUP(BW20,$IK$5000:$IU$5300,3) -> 1.6 | CD20: =IF(CB20=" ",0,ROUND(SUM(CB20:CC20),2)) -> 0 | CE20: =VLOOKUP(CD20,$IK$5000:$IU$5300,3) -> 0 | CG20: 7 | CH20: =IF(B20=" ",F20,B20*F20/24) -> 0 | CI20: =IF(I20=" ",M20,I20*M20/24) -> 0 | CJ20: =IF(P20=" ",T20,P20*T20/24) -> 0 | CK20: =IF(W20=" ",AA20,W20*AA20/24) -> 2.2 | CL20: =IF(AD20=" ",AH20,AD20*AH20/24) -> 3.1 | CM20: =IF(AK20=" ",AO20,AK20*AO20/24) -> 3.1 | CN20: =IF(AR20=" ",AV20,AR20*AV20/24) -> 3.1 | CO20: =IF(AY20=" ",BC20,AY20*BC20/24) -> 3.2 | CP20: =IF(BF20=" ",BJ20,BF20*BJ20/24) -> 2.2 | CQ20: =IF(BM20=" ",BQ20,BM20*BQ20/24) -> 1.344 | CR20: =IF(BT20=" ",BX20,BT20*BX20/24) -> 1.6 | CS20: =IF(CA20=" ",CE20,CA20*CE20/24) -> 0
A21: 8 | C21: 0 | D21: 0 | E21: =IF(C21=" ",0,ROUND(SUM(C21:D21),2)) -> 0 | F21: =VLOOKUP(E21,$IK$5000:$IU$5300,3) -> 0 | L21: =IF(J21=" ",0,ROUND(SUM(J21:K21),2)) -> 0 | M21: =VLOOKUP(L21,$IK$5000:$IU$5300,3) -> 0 | S21: =IF(Q21=" ",0,ROUND(SUM(Q21:R21),2)) -> 0 | T21: =VLOOKUP(S21,$IK$5000:$IU$5300,3) -> 0 | X21: 0.81 | Z21: =IF(X21=" ",0,ROUND(SUM(X21:Y21),2)) -> 0.81 | AA21: =VLOOKUP(Z21,$IK$5000:$IU$5300,3) -> 2.9 | AE21: 0.67 | AG21: =IF(AE21=" ",0,ROUND(SUM(AE21:AF21),2)) -> 0.67 | AH21: =VLOOKUP(AG21,$IK$5000:$IU$5300,3) -> 2.2 | AL21: 0.74 | AN21: =IF(AL21=" ",0,ROUND(SUM(AL21:AM21),2)) -> 0.74 | AO21: =VLOOKUP(AN21,$IK$5000:$IU$5300,3) -> 2.5 | AS21: 0.82 | AU21: =IF(AS21=" ",0,ROUND(SUM(AS21:AT21),2)) -> 0.82 | AV21: =VLOOKUP(AU21,$IK$5000:$IU$5300,3) -> 3 | AZ21: 0.84 | BB21: =IF(AZ21=" ",0,ROUND(SUM(AZ21:BA21),2)) -> 0.84 | BC21: =VLOOKUP(BB21,$IK$5000:$IU$5300,3) -> 3.1 | BG21: 0.95 | BI21: =IF(BG21=" ",0,ROUND(SUM(BG21:BH21),2)) -> 0.95 | BJ21: =VLOOKUP(BI21,$IK$5000:$IU$5300,3) -> 3.7 | BN21: 0.47 | BP21: =IF(BN21=" ",0,ROUND(SUM(BN21:BO21),2)) -> 0.47 | BQ21: =VLOOKUP(BP21,$IK$5000:$IU$5300,3) -> 1.316 | BU21: 0.55 | BW21: =IF(BU21=" ",0,ROUND(SUM(BU21:BV21),2)) -> 0.55 | BX21: =VLOOKUP(BW21,$IK$5000:$IU$5300,3) -> 1.6 | CD21: =IF(CB21=" ",0,ROUND(SUM(CB21:CC21),2)) -> 0 | CE21: =VLOOKUP(CD21,$IK$5000:$IU$5300,3) -> 0 | CG21: 8 | CH21: =IF(B21=" ",F21,B21*F21/24) -> 0 | CI21: =IF(I21=" ",M21,I21*M21/24) -> 0 | CJ21: =IF(P21=" ",T21,P21*T21/24) -> 0 | CK21: =IF(W21=" ",AA21,W21*AA21/24) -> 2.9 | CL21: =IF(AD21=" ",AH21,AD21*AH21/24) -> 2.2 | CM21: =IF(AK21=" ",AO21,AK21*AO21/24) -> 2.5 | CN21: =IF(AR21=" ",AV21,AR21*AV21/24) -> 3 | CO21: =IF(AY21=" ",BC21,AY21*BC21/24) -> 3.1 | CP21: =IF(BF21=" ",BJ21,BF21*BJ21/24) -> 3.7 | CQ21: =IF(BM21=" ",BQ21,BM21*BQ21/24) -> 1.316 | CR21: =IF(BT21=" ",BX21,BT21*BX21/24) -> 1.6 | CS21: =IF(CA21=" ",CE21,CA21*CE21/24) -> 0
A22: 9 | C22: 0 | D22: 0 | E22: =IF(C22=" ",0,ROUND(SUM(C22:D22),2)) -> 0 | F22: =VLOOKUP(E22,$IK$5000:$IU$5300,3) -> 0 | L22: =IF(J22=" ",0,ROUND(SUM(J22:K22),2)) -> 0 | M22: =VLOOKUP(L22,$IK$5000:$IU$5300,3) -> 0 | S22: =IF(Q22=" ",0,ROUND(SUM(Q22:R22),2)) -> 0 | T22: =VLOOKUP(S22,$IK$5000:$IU$5300,3) -> 0 | X22: 0.96 | Z22: =IF(X22=" ",0,ROUND(SUM(X22:Y22),2)) -> 0.96 | AA22: =VLOOKUP(Z22,$IK$5000:$IU$5300,3) -> 3.8 | AE22: 0.72 | AG22: =IF(AE22=" ",0,ROUND(SUM(AE22:AF22),2)) -> 0.72 | AH22: =VLOOKUP(AG22,$IK$5000:$IU$5300,3) -> 2.4 | AL22: 0.91 | AN22: =IF(AL22=" ",0,ROUND(SUM(AL22:AM22),2)) -> 0.91 | AO22: =VLOOKUP(AN22,$IK$5000:$IU$5300,3) -> 3.5 | AS22: 0.73 | AU22: =IF(AS22=" ",0,ROUND(SUM(AS22:AT22),2)) -> 0.73 | AV22: =VLOOKUP(AU22,$IK$5000:$IU$5300,3) -> 2.5 | AZ22: 0.68 | BB22: =IF(AZ22=" ",0,ROUND(SUM(AZ22:BA22),2)) -> 0.68 | BC22: =VLOOKUP(BB22,$IK$5000:$IU$5300,3) -> 2.2 | BG22: 0.8 | BI22: =IF(BG22=" ",0,ROUND(SUM(BG22:BH22),2)) -> 0.8 | BJ22: =VLOOKUP(BI22,$IK$5000:$IU$5300,3) -> 2.8 | BN22: 0.46 | BP22: =IF(BN22=" ",0,ROUND(SUM(BN22:BO22),2)) -> 0.46 | BQ22: =VLOOKUP(BP22,$IK$5000:$IU$5300,3) -> 1.288 | BU22: 0.55 | BW22: =IF(BU22=" ",0,ROUND(SUM(BU22:BV22),2)) -> 0.55 | BX22: =VLOOKUP(BW22,$IK$5000:$IU$5300,3) -> 1.6 | CD22: =IF(CB22=" ",0,ROUND(SUM(CB22:CC22),2)) -> 0 | CE22: =VLOOKUP(CD22,$IK$5000:$IU$5300,3) -> 0 | CG22: 9 | CH22: =IF(B22=" ",F22,B22*F22/24) -> 0 | CI22: =IF(I22=" ",M22,I22*M22/24) -> 0 | CJ22: =IF(P22=" ",T22,P22*T22/24) -> 0 | CK22: =IF(W22=" ",AA22,W22*AA22/24) -> 3.8 | CL22: =IF(AD22=" ",AH22,AD22*AH22/24) -> 2.4 | CM22: =IF(AK22=" ",AO22,AK22*AO22/24) -> 3.5 | CN22: =IF(AR22=" ",AV22,AR22*AV22/24) -> 2.5 | CO22: =IF(AY22=" ",BC22,AY22*BC22/24) -> 2.2 | CP22: =IF(BF22=" ",BJ22,BF22*BJ22/24) -> 2.8 | CQ22: =IF(BM22=" ",BQ22,BM22*BQ22/24) -> 1.288 | CR22: =IF(BT22=" ",BX22,BT22*BX22/24) -> 1.6 | CS22: =IF(CA22=" ",CE22,CA22*CE22/24) -> 0
A23: 10 | C23: 0 | D23: 0 | E23: =IF(C23=" ",0,ROUND(SUM(C23:D23),2)) -> 0 | F23: =VLOOKUP(E23,$IK$5000:$IU$5300,3) -> 0 | L23: =IF(J23=" ",0,ROUND(SUM(J23:K23),2)) -> 0 | M23: =VLOOKUP(L23,$IK$5000:$IU$5300,3) -> 0 | P23: 9 | Q23: 0.61 | S23: =IF(Q23=" ",0,ROUND(SUM(Q23:R23),2)) -> 0.61 | T23: =VLOOKUP(S23,$IK$5000:$IU$5300,3) -> 1.9 | X23: 0.81 | Z23: =IF(X23=" ",0,ROUND(SUM(X23:Y23),2)) -> 0.81 | AA23: =VLOOKUP(Z23,$IK$5000:$IU$5300,3) -> 2.9 | AE23: 0.81 | AG23: =IF(AE23=" ",0,ROUND(SUM(AE23:AF23),2)) -> 0.81 | AH23: =VLOOKUP(AG23,$IK$5000:$IU$5300,3) -> 2.9 | AL23: 0.66 | AN23: =IF(AL23=" ",0,ROUND(SUM(AL23:AM23),2)) -> 0.66 | AO23: =VLOOKUP(AN23,$IK$5000:$IU$5300,3) -> 2.1 | AS23: 0.62 | AU23: =IF(AS23=" ",0,ROUND(SUM(AS23:AT23),2)) -> 0.62 | AV23: =VLOOKUP(AU23,$IK$5000:$IU$5300,3) -> 1.9 | AZ23: 0.76 | BB23: =IF(AZ23=" ",0,ROUND(SUM(AZ23:BA23),2)) -> 0.76 | BC23: =VLOOKUP(BB23,$IK$5000:$IU$5300,3) -> 2.6 | BG23: 0.5 | BI23: =IF(BG23=" ",0,ROUND(SUM(BG23:BH23),2)) -> 0.5 | BJ23: =VLOOKUP(BI23,$IK$5000:$IU$5300,3) -> 1.4 | BN23: 0.46 | BP23: =IF(BN23=" ",0,ROUND(SUM(BN23:BO23),2)) -> 0.46 | BQ23: =VLOOKUP(BP23,$IK$5000:$IU$5300,3) -> 1.288 | BU23: 0.54 | BW23: =IF(BU23=" ",0,ROUND(SUM(BU23:BV23),2)) -> 0.54 | BX23: =VLOOKUP(BW23,$IK$5000:$IU$5300,3) -> 1.6 | CD23: =IF(CB23=" ",0,ROUND(SUM(CB23:CC23),2)) -> 0 | CE23: =VLOOKUP(CD23,$IK$5000:$IU$5300,3) -> 0 | CG23: 10 | CH23: =IF(B23=" ",F23,B23*F23/24) -> 0 | CI23: =IF(I23=" ",M23,I23*M23/24) -> 0 | CJ23: =IF(P23=" ",T23,P23*T23/24) -> 0.7125 | CK23: =IF(W23=" ",AA23,W23*AA23/24) -> 2.9 | CL23: =IF(AD23=" ",AH23,AD23*AH23/24) -> 2.9 | CM23: =IF(AK23=" ",AO23,AK23*AO23/24) -> 2.1 | CN23: =IF(AR23=" ",AV23,AR23*AV23/24) -> 1.9 | CO23: =IF(AY23=" ",BC23,AY23*BC23/24) -> 2.6 | CP23: =IF(BF23=" ",BJ23,BF23*BJ23/24) -> 1.4 | CQ23: =IF(BM23=" ",BQ23,BM23*BQ23/24) -> 1.288 | CR23: =IF(BT23=" ",BX23,BT23*BX23/24) -> 1.6 | CS23: =IF(CA23=" ",CE23,CA23*CE23/24) -> 0
A24: 11 | C24: 0 | D24: 0 | E24: =IF(C24=" ",0,ROUND(SUM(C24:D24),2)) -> 0 | F24: =VLOOKUP(E24,$IK$5000:$IU$5300,3) -> 0 | L24: =IF(J24=" ",0,ROUND(SUM(J24:K24),2)) -> 0 | M24: =VLOOKUP(L24,$IK$5000:$IU$5300,3) -> 0 | Q24: 0.75 | S24: =IF(Q24=" ",0,ROUND(SUM(Q24:R24),2)) -> 0.75 | T24: =VLOOKUP(S24,$IK$5000:$IU$5300,3) -> 2.6 | X24: 0.65 | Z24: =IF(X24=" ",0,ROUND(SUM(X24:Y24),2)) -> 0.65 | AA24: =VLOOKUP(Z24,$IK$5000:$IU$5300,3) -> 2.1 | AE24: 0.65 | AG24: =IF(AE24=" ",0,ROUND(SUM(AE24:AF24),2)) -> 0.65 | AH24: =VLOOKUP(AG24,$IK$5000:$IU$5300,3) -> 2.1 | AL24: 0.63 | AN24: =IF(AL24=" ",0,ROUND(SUM(AL24:AM24),2)) -> 0.63 | AO24: =VLOOKUP(AN24,$IK$5000:$IU$5300,3) -> 2 | AS24: 0.65 | AU24: =IF(AS24=" ",0,ROUND(SUM(AS24:AT24),2)) -> 0.65 | AV24: =VLOOKUP(AU24,$IK$5000:$IU$5300,3) -> 2.1 | AZ24: 0.93 | BB24: =IF(AZ24=" ",0,ROUND(SUM(AZ24:BA24),2)) -> 0.93 | BC24: =VLOOKUP(BB24,$IK$5000:$IU$5300,3) -> 3.6 | BG24: 0.5 | BI24: =IF(BG24=" ",0,ROUND(SUM(BG24:BH24),2)) -> 0.5 | BJ24: =VLOOKUP(BI24,$IK$5000:$IU$5300,3) -> 1.4 | BN24: 0.46 | BP24: =IF(BN24=" ",0,ROUND(SUM(BN24:BO24),2)) -> 0.46 | BQ24: =VLOOKUP(BP24,$IK$5000:$IU$5300,3) -> 1.288 | BU24: 0.54 | BW24: =IF(BU24=" ",0,ROUND(SUM(BU24:BV24),2)) -> 0.54 | BX24: =VLOOKUP(BW24,$IK$5000:$IU$5300,3) -> 1.6 | CD24: =IF(CB24=" ",0,ROUND(SUM(CB24:CC24),2)) -> 0 | CE24: =VLOOKUP(CD24,$IK$5000:$IU$5300,3) -> 0 | CG24: 11 | CH24: =IF(B24=" ",F24,B24*F24/24) -> 0 | CI24: =IF(I24=" ",M24,I24*M24/24) -> 0 | CJ24: =IF(P24=" ",T24,P24*T24/24) -> 2.6 | CK24: =IF(W24=" ",AA24,W24*AA24/24) -> 2.1 | CL24: =IF(AD24=" ",AH24,AD24*AH24/24) -> 2.1 | CM24: =IF(AK24=" ",AO24,AK24*AO24/24) -> 2 | CN24: =IF(AR24=" ",AV24,AR24*AV24/24) -> 2.1 | CO24: =IF(AY24=" ",BC24,AY24*BC24/24) -> 3.6 | CP24: =IF(BF24=" ",BJ24,BF24*BJ24/24) -> 1.4 | CQ24: =IF(BM24=" ",BQ24,BM24*BQ24/24) -> 1.288 | CR24: =IF(BT24=" ",BX24,BT24*BX24/24) -> 1.6 | CS24: =IF(CA24=" ",CE24,CA24*CE24/24) -> 0
A25: 12 | C25: 0 | D25: 0 | E25: =IF(C25=" ",0,ROUND(SUM(C25:D25),2)) -> 0 | F25: =VLOOKUP(E25,$IK$5000:$IU$5300,3) -> 0 | L25: =IF(J25=" ",0,ROUND(SUM(J25:K25),2)) -> 0 | M25: =VLOOKUP(L25,$IK$5000:$IU$5300,3) -> 0 | Q25: 0.77 | S25: =IF(Q25=" ",0,ROUND(SUM(Q25:R25),2)) -> 0.77 | T25: =VLOOKUP(S25,$IK$5000:$IU$5300,3) -> 2.7 | X25: 0.86 | Z25: =IF(X25=" ",0,ROUND(SUM(X25:Y25),2)) -> 0.86 | AA25: =VLOOKUP(Z25,$IK$5000:$IU$5300,3) -> 3.2 | AE25: 0.84 | AG25: =IF(AE25=" ",0,ROUND(SUM(AE25:AF25),2)) -> 0.84 | AH25: =VLOOKUP(AG25,$IK$5000:$IU$5300,3) -> 3.1 | AL25: 0.63 | AN25: =IF(AL25=" ",0,ROUND(SUM(AL25:AM25),2)) -> 0.63 | AO25: =VLOOKUP(AN25,$IK$5000:$IU$5300,3) -> 2 | AS25: 0.84 | AU25: =IF(AS25=" ",0,ROUND(SUM(AS25:AT25),2)) -> 0.84 | AV25: =VLOOKUP(AU25,$IK$5000:$IU$5300,3) -> 3.1 | AZ25: 0.85 | BB25: =IF(AZ25=" ",0,ROUND(SUM(AZ25:BA25),2)) -> 0.85 | BC25: =VLOOKUP(BB25,$IK$5000:$IU$5300,3) -> 3.1 | BG25: 0.5 | BI25: =IF(BG25=" ",0,ROUND(SUM(BG25:BH25),2)) -> 0.5 | BJ25: =VLOOKUP(BI25,$IK$5000:$IU$5300,3) -> 1.4 | BN25: 0.46 | BP25: =IF(BN25=" ",0,ROUND(SUM(BN25:BO25),2)) -> 0.46 | BQ25: =VLOOKUP(BP25,$IK$5000:$IU$5300,3) -> 1.288 | BU25: 0.53 | BW25: =IF(BU25=" ",0,ROUND(SUM(BU25:BV25),2)) -> 0.53 | BX25: =VLOOKUP(BW25,$IK$5000:$IU$5300,3) -> 1.5 | CD25: =IF(CB25=" ",0,ROUND(SUM(CB25:CC25),2)) -> 0 | CE25: =VLOOKUP(CD25,$IK$5000:$IU$5300,3) -> 0 | CG25: 12 | CH25: =IF(B25=" ",F25,B25*F25/24) -> 0 | CI25: =IF(I25=" ",M25,I25*M25/24) -> 0 | CJ25: =IF(P25=" ",T25,P25*T25/24) -> 2.7 | CK25: =IF(W25=" ",AA25,W25*AA25/24) -> 3.2 | CL25: =IF(AD25=" ",AH25,AD25*AH25/24) -> 3.1 | CM25: =IF(AK25=" ",AO25,AK25*AO25/24) -> 2 | CN25: =IF(AR25=" ",AV25,AR25*AV25/24) -> 3.1 | CO25: =IF(AY25=" ",BC25,AY25*BC25/24) -> 3.1 | CP25: =IF(BF25=" ",BJ25,BF25*BJ25/24) -> 1.4 | CQ25: =IF(BM25=" ",BQ25,BM25*BQ25/24) -> 1.288 | CR25: =IF(BT25=" ",BX25,BT25*BX25/24) -> 1.5 | CS25: =IF(CA25=" ",CE25,CA25*CE25/24) -> 0
A26: 13 | C26: 0 | D26: 0 | E26: =IF(C26=" ",0,ROUND(SUM(C26:D26),2)) -> 0 | F26: =VLOOKUP(E26,$IK$5000:$IU$5300,3) -> 0 | L26: =IF(J26=" ",0,ROUND(SUM(J26:K26),2)) -> 0 | M26: =VLOOKUP(L26,$IK$5000:$IU$5300,3) -> 0 | Q26: 0.61 | S26: =IF(Q26=" ",0,ROUND(SUM(Q26:R26),2)) -> 0.61 | T26: =VLOOKUP(S26,$IK$5000:$IU$5300,3) -> 1.9 | X26: 0.92 | Z26: =IF(X26=" ",0,ROUND(SUM(X26:Y26),2)) -> 0.92 | AA26: =VLOOKUP(Z26,$IK$5000:$IU$5300,3) -> 3.5 | AE26: 0.95 | AG26: =IF(AE26=" ",0,ROUND(SUM(AE26:AF26),2)) -> 0.95 | AH26: =VLOOKUP(AG26,$IK$5000:$IU$5300,3) -> 3.7 | AL26: 0.69 | AN26: =IF(AL26=" ",0,ROUND(SUM(AL26:AM26),2)) -> 0.69 | AO26: =VLOOKUP(AN26,$IK$5000:$IU$5300,3) -> 2.3 | AS26: 0.94 | AU26: =IF(AS26=" ",0,ROUND(SUM(AS26:AT26),2)) -> 0.94 | AV26: =VLOOKUP(AU26,$IK$5000:$IU$5300,3) -> 3.6 | AZ26: 0.69 | BB26: =IF(AZ26=" ",0,ROUND(SUM(AZ26:BA26),2)) -> 0.69 | BC26: =VLOOKUP(BB26,$IK$5000:$IU$5300,3) -> 2.3 | BG26: 0.41 | BI26: =IF(BG26=" ",0,ROUND(SUM(BG26:BH26),2)) -> 0.41 | BJ26: =VLOOKUP(BI26,$IK$5000:$IU$5300,3) -> 1.148 | BN26: 0.46 | BP26: =IF(BN26=" ",0,ROUND(SUM(BN26:BO26),2)) -> 0.46 | BQ26: =VLOOKUP(BP26,$IK$5000:$IU$5300,3) -> 1.288 | BU26: 0.53 | BW26: =IF(BU26=" ",0,ROUND(SUM(BU26:BV26),2)) -> 0.53 | BX26: =VLOOKUP(BW26,$IK$5000:$IU$5300,3) -> 1.5 | CD26: =IF(CB26=" ",0,ROUND(SUM(CB26:CC26),2)) -> 0 | CE26: =VLOOKUP(CD26,$IK$5000:$IU$5300,3) -> 0 | CG26: 13 | CH26: =IF(B26=" ",F26,B26*F26/24) -> 0 | CI26: =IF(I26=" ",M26,I26*M26/24) -> 0 | CJ26: =IF(P26=" ",T26,P26*T26/24) -> 1.9 | CK26: =IF(W26=" ",AA26,W26*AA26/24) -> 3.5 | CL26: =IF(AD26=" ",AH26,AD26*AH26/24) -> 3.7 | CM26: =IF(AK26=" ",AO26,AK26*AO26/24) -> 2.3 | CN26: =IF(AR26=" ",AV26,AR26*AV26/24) -> 3.6 | CO26: =IF(AY26=" ",BC26,AY26*BC26/24) -> 2.3 | CP26: =IF(BF26=" ",BJ26,BF26*BJ26/24) -> 1.148 | CQ26: =IF(BM26=" ",BQ26,BM26*BQ26/24) -> 1.288 | CR26: =IF(BT26=" ",BX26,BT26*BX26/24) -> 1.5 | CS26: =IF(CA26=" ",CE26,CA26*CE26/24) -> 0
A27: 14 | C27: 0 | D27: 0 | E27: =IF(C27=" ",0,ROUND(SUM(C27:D27),2)) -> 0 | F27: =VLOOKUP(E27,$IK$5000:$IU$5300,3) -> 0 | L27: =IF(J27=" ",0,ROUND(SUM(J27:K27),2)) -> 0 | M27: =VLOOKUP(L27,$IK$5000:$IU$5300,3) -> 0 | Q27: 0.61 | S27: =IF(Q27=" ",0,ROUND(SUM(Q27:R27),2)) -> 0.61 | T27: =VLOOKUP(S27,$IK$5000:$IU$5300,3) -> 1.9 | X27: 0.94 | Z27: =IF(X27=" ",0,ROUND(SUM(X27:Y27),2)) -> 0.94 | AA27: =VLOOKUP(Z27,$IK$5000:$IU$5300,3) -> 3.6 | AE27: 0.93 | AG27: =IF(AE27=" ",0,ROUND(SUM(AE27:AF27),2)) -> 0.93 | AH27: =VLOOKUP(AG27,$IK$5000:$IU$5300,3) -> 3.6 | AL27: 0.83 | AN27: =IF(AL27=" ",0,ROUND(SUM(AL27:AM27),2)) -> 0.83 | AO27: =VLOOKUP(AN27,$IK$5000:$IU$5300,3) -> 3 | AS27: 0.9 | AU27: =IF(AS27=" ",0,ROUND(SUM(AS27:AT27),2)) -> 0.9 | AV27: =VLOOKUP(AU27,$IK$5000:$IU$5300,3) -> 3.4 | AZ27: 0.68 | BB27: =IF(AZ27=" ",0,ROUND(SUM(AZ27:BA27),2)) -> 0.68 | BC27: =VLOOKUP(BB27,$IK$5000:$IU$5300,3) -> 2.2 | BG27: 0.31 | BI27: =IF(BG27=" ",0,ROUND(SUM(BG27:BH27),2)) -> 0.31 | BJ27: =VLOOKUP(BI27,$IK$5000:$IU$5300,3) -> 0.86 | BN27: 0.47 | BP27: =IF(BN27=" ",0,ROUND(SUM(BN27:BO27),2)) -> 0.47 | BQ27: =VLOOKUP(BP27,$IK$5000:$IU$5300,3) -> 1.316 | BU27: 0.53 | BW27: =IF(BU27=" ",0,ROUND(SUM(BU27:BV27),2)) -> 0.53 | BX27: =VLOOKUP(BW27,$IK$5000:$IU$5300,3) -> 1.5 | CD27: =IF(CB27=" ",0,ROUND(SUM(CB27:CC27),2)) -> 0 | CE27: =VLOOKUP(CD27,$IK$5000:$IU$5300,3) -> 0 | CG27: 14 | CH27: =IF(B27=" ",F27,B27*F27/24) -> 0 | CI27: =IF(I27=" ",M27,I27*M27/24) -> 0 | CJ27: =IF(P27=" ",T27,P27*T27/24) -> 1.9 | CK27: =IF(W27=" ",AA27,W27*AA27/24) -> 3.6 | CL27: =IF(AD27=" ",AH27,AD27*AH27/24) -> 3.6 | CM27: =IF(AK27=" ",AO27,AK27*AO27/24) -> 3 | CN27: =IF(AR27=" ",AV27,AR27*AV27/24) -> 3.4 | CO27: =IF(AY27=" ",BC27,AY27*BC27/24) -> 2.2 | CP27: =IF(BF27=" ",BJ27,BF27*BJ27/24) -> 0.86 | CQ27: =IF(BM27=" ",BQ27,BM27*BQ27/24) -> 1.316 | CR27: =IF(BT27=" ",BX27,BT27*BX27/24) -> 1.5 | CS27: =IF(CA27=" ",CE27,CA27*CE27/24) -> 0
A28: 15 | C28: 0 | D28: 0 | E28: =IF(C28=" ",0,ROUND(SUM(C28:D28),2)) -> 0 | F28: =VLOOKUP(E28,$IK$5000:$IU$5300,3) -> 0 | L28: =IF(J28=" ",0,ROUND(SUM(J28:K28),2)) -> 0 | M28: =VLOOKUP(L28,$IK$5000:$IU$5300,3) -> 0 | Q28: 0.81 | S28: =IF(Q28=" ",0,ROUND(SUM(Q28:R28),2)) -> 0.81 | T28: =VLOOKUP(S28,$IK$5000:$IU$5300,3) -> 2.9 | X28: 0.96 | Z28: =IF(X28=" ",0,ROUND(SUM(X28:Y28),2)) -> 0.96 | AA28: =VLOOKUP(Z28,$IK$5000:$IU$5300,3) -> 3.8 | AE28: 0.88 | AG28: =IF(AE28=" ",0,ROUND(SUM(AE28:AF28),2)) -> 0.88 | AH28: =VLOOKUP(AG28,$IK$5000:$IU$5300,3) -> 3.3 | AL28: 0.82 | AN28: =IF(AL28=" ",0,ROUND(SUM(AL28:AM28),2)) -> 0.82 | AO28: =VLOOKUP(AN28,$IK$5000:$IU$5300,3) -> 3 | AS28: 0.85 | AU28: =IF(AS28=" ",0,ROUND(SUM(AS28:AT28),2)) -> 0.85 | AV28: =VLOOKUP(AU28,$IK$5000:$IU$5300,3) -> 3.1 | AZ28: 0.89 | BB28: =IF(AZ28=" ",0,ROUND(SUM(AZ28:BA28),2)) -> 0.89 | BC28: =VLOOKUP(BB28,$IK$5000:$IU$5300,3) -> 3.3 | BG28: 0.49 | BI28: =IF(BG28=" ",0,ROUND(SUM(BG28:BH28),2)) -> 0.49 | BJ28: =VLOOKUP(BI28,$IK$5000:$IU$5300,3) -> 1.372 | BN28: 0.46 | BP28: =IF(BN28=" ",0,ROUND(SUM(BN28:BO28),2)) -> 0.46 | BQ28: =VLOOKUP(BP28,$IK$5000:$IU$5300,3) -> 1.288 | BU28: 0.53 | BW28: =IF(BU28=" ",0,ROUND(SUM(BU28:BV28),2)) -> 0.53 | BX28: =VLOOKUP(BW28,$IK$5000:$IU$5300,3) -> 1.5 | CD28: =IF(CB28=" ",0,ROUND(SUM(CB28:CC28),2)) -> 0 | CE28: =VLOOKUP(CD28,$IK$5000:$IU$5300,3) -> 0 | CG28: 15 | CH28: =IF(B28=" ",F28,B28*F28/24) -> 0 | CI28: =IF(I28=" ",M28,I28*M28/24) -> 0 | CJ28: =IF(P28=" ",T28,P28*T28/24) -> 2.9 | CK28: =IF(W28=" ",AA28,W28*AA28/24) -> 3.8 | CL28: =IF(AD28=" ",AH28,AD28*AH28/24) -> 3.3 | CM28: =IF(AK28=" ",AO28,AK28*AO28/24) -> 3 | CN28: =IF(AR28=" ",AV28,AR28*AV28/24) -> 3.1 | CO28: =IF(AY28=" ",BC28,AY28*BC28/24) -> 3.3 | CP28: =IF(BF28=" ",BJ28,BF28*BJ28/24) -> 1.372 | CQ28: =IF(BM28=" ",BQ28,BM28*BQ28/24) -> 1.288 | CR28: =IF(BT28=" ",BX28,BT28*BX28/24) -> 1.5 | CS28: =IF(CA28=" ",CE28,CA28*CE28/24) -> 0
A29: 16 | C29: 0 | D29: 0 | E29: =IF(C29=" ",0,ROUND(SUM(C29:D29),2)) -> 0 | F29: =VLOOKUP(E29,$IK$5000:$IU$5300,3) -> 0 | L29: =IF(J29=" ",0,ROUND(SUM(J29:K29),2)) -> 0 | M29: =VLOOKUP(L29,$IK$5000:$IU$5300,3) -> 0 | Q29: 0.8 | S29: =IF(Q29=" ",0,ROUND(SUM(Q29:R29),2)) -> 0.8 | T29: =VLOOKUP(S29,$IK$5000:$IU$5300,3) -> 2.8 | X29: 0.89 | Z29: =IF(X29=" ",0,ROUND(SUM(X29:Y29),2)) -> 0.89 | AA29: =VLOOKUP(Z29,$IK$5000:$IU$5300,3) -> 3.3 | AE29: 0.75 | AG29: =IF(AE29=" ",0,ROUND(SUM(AE29:AF29),2)) -> 0.75 | AH29: =VLOOKUP(AG29,$IK$5000:$IU$5300,3) -> 2.6 | AL29: 0.81 | AN29: =IF(AL29=" ",0,ROUND(SUM(AL29:AM29),2)) -> 0.81 | AO29: =VLOOKUP(AN29,$IK$5000:$IU$5300,3) -> 2.9 | AS29: 0.66 | AU29: =IF(AS29=" ",0,ROUND(SUM(AS29:AT29),2)) -> 0.66 | AV29: =VLOOKUP(AU29,$IK$5000:$IU$5300,3) -> 2.1 | AZ29: 0.83 | BB29: =IF(AZ29=" ",0,ROUND(SUM(AZ29:BA29),2)) -> 0.83 | BC29: =VLOOKUP(BB29,$IK$5000:$IU$5300,3) -> 3 | BG29: 0.48 | BI29: =IF(BG29=" ",0,ROUND(SUM(BG29:BH29),2)) -> 0.48 | BJ29: =VLOOKUP(BI29,$IK$5000:$IU$5300,3) -> 1.344 | BN29: 0.46 | BP29: =IF(BN29=" ",0,ROUND(SUM(BN29:BO29),2)) -> 0.46 | BQ29: =VLOOKUP(BP29,$IK$5000:$IU$5300,3) -> 1.288 | BU29: 0.53 | BW29: =IF(BU29=" ",0,ROUND(SUM(BU29:BV29),2)) -> 0.53 | BX29: =VLOOKUP(BW29,$IK$5000:$IU$5300,3) -> 1.5 | CD29: =IF(CB29=" ",0,ROUND(SUM(CB29:CC29),2)) -> 0 | CE29: =VLOOKUP(CD29,$IK$5000:$IU$5300,3) -> 0 | CG29: 16 | CH29: =IF(B29=" ",F29,B29*F29/24) -> 0 | CI29: =IF(I29=" ",M29,I29*M29/24) -> 0 | CJ29: =IF(P29=" ",T29,P29*T29/24) -> 2.8 | CK29: =IF(W29=" ",AA29,W29*AA29/24) -> 3.3 | CL29: =IF(AD29=" ",AH29,AD29*AH29/24) -> 2.6 | CM29: =IF(AK29=" ",AO29,AK29*AO29/24) -> 2.9 | CN29: =IF(AR29=" ",AV29,AR29*AV29/24) -> 2.1 | CO29: =IF(AY29=" ",BC29,AY29*BC29/24) -> 3 | CP29: =IF(BF29=" ",BJ29,BF29*BJ29/24) -> 1.344 | CQ29: =IF(BM29=" ",BQ29,BM29*BQ29/24) -> 1.288 | CR29: =IF(BT29=" ",BX29,BT29*BX29/24) -> 1.5 | CS29: =IF(CA29=" ",CE29,CA29*CE29/24) -> 0
A30: 17 | C30: 0 | D30: 0 | E30: =IF(C30=" ",0,ROUND(SUM(C30:D30),2)) -> 0 | F30: =VLOOKUP(E30,$IK$5000:$IU$5300,3) -> 0 | L30: =IF(J30=" ",0,ROUND(SUM(J30:K30),2)) -> 0 | M30: =VLOOKUP(L30,$IK$5000:$IU$5300,3) -> 0 | Q30: 0.62 | S30: =IF(Q30=" ",0,ROUND(SUM(Q30:R30),2)) -> 0.62 | T30: =VLOOKUP(S30,$IK$5000:$IU$5300,3) -> 1.9 | X30: 0.74 | Z30: =IF(X30=" ",0,ROUND(SUM(X30:Y30),2)) -> 0.74 | AA30: =VLOOKUP(Z30,$IK$5000:$IU$5300,3) -> 2.5 | AE30: 0.8 | AG30: =IF(AE30=" ",0,ROUND(SUM(AE30:AF30),2)) -> 0.8 | AH30: =VLOOKUP(AG30,$IK$5000:$IU$5300,3) -> 2.8 | AL30: 0.81 | AN30: =IF(AL30=" ",0,ROUND(SUM(AL30:AM30),2)) -> 0.81 | AO30: =VLOOKUP(AN30,$IK$5000:$IU$5300,3) -> 2.9 | AS30: 0.66 | AU30: =IF(AS30=" ",0,ROUND(SUM(AS30:AT30),2)) -> 0.66 | AV30: =VLOOKUP(AU30,$IK$5000:$IU$5300,3) -> 2.1 | AZ30: 0.76 | BB30: =IF(AZ30=" ",0,ROUND(SUM(AZ30:BA30),2)) -> 0.76 | BC30: =VLOOKUP(BB30,$IK$5000:$IU$5300,3) -> 2.6 | BG30: 0.42 | BI30: =IF(BG30=" ",0,ROUND(SUM(BG30:BH30),2)) -> 0.42 | BJ30: =VLOOKUP(BI30,$IK$5000:$IU$5300,3) -> 1.176 | BN30: 0.46 | BP30: =IF(BN30=" ",0,ROUND(SUM(BN30:BO30),2)) -> 0.46 | BQ30: =VLOOKUP(BP30,$IK$5000:$IU$5300,3) -> 1.288 | BU30: 0.53 | BW30: =IF(BU30=" ",0,ROUND(SUM(BU30:BV30),2)) -> 0.53 | BX30: =VLOOKUP(BW30,$IK$5000:$IU$5300,3) -> 1.5 | CD30: =IF(CB30=" ",0,ROUND(SUM(CB30:CC30),2)) -> 0 | CE30: =VLOOKUP(CD30,$IK$5000:$IU$5300,3) -> 0 | CG30: 17 | CH30: =IF(B30=" ",F30,B30*F30/24) -> 0 | CI30: =IF(I30=" ",M30,I30*M30/24) -> 0 | CJ30: =IF(P30=" ",T30,P30*T30/24) -> 1.9 | CK30: =IF(W30=" ",AA30,W30*AA30/24) -> 2.5 | CL30: =IF(AD30=" ",AH30,AD30*AH30/24) -> 2.8 | CM30: =IF(AK30=" ",AO30,AK30*AO30/24) -> 2.9 | CN30: =IF(AR30=" ",AV30,AR30*AV30/24) -> 2.1 | CO30: =IF(AY30=" ",BC30,AY30*BC30/24) -> 2.6 | CP30: =IF(BF30=" ",BJ30,BF30*BJ30/24) -> 1.176 | CQ30: =IF(BM30=" ",BQ30,BM30*BQ30/24) -> 1.288 | CR30: =IF(BT30=" ",BX30,BT30*BX30/24) -> 1.5 | CS30: =IF(CA30=" ",CE30,CA30*CE30/24) -> 0
A31: 18 | C31: 0 | D31: 0 | E31: =IF(C31=" ",0,ROUND(SUM(C31:D31),2)) -> 0 | F31: =VLOOKUP(E31,$IK$5000:$IU$5300,3) -> 0 | L31: =IF(J31=" ",0,ROUND(SUM(J31:K31),2)) -> 0 | M31: =VLOOKUP(L31,$IK$5000:$IU$5300,3) -> 0 | Q31: 0.6 | S31: =IF(Q31=" ",0,ROUND(SUM(Q31:R31),2)) -> 0.6 | T31: =VLOOKUP(S31,$IK$5000:$IU$5300,3) -> 1.8 | X31: 0.96 | Z31: =IF(X31=" ",0,ROUND(SUM(X31:Y31),2)) -> 0.96 | AA31: =VLOOKUP(Z31,$IK$5000:$IU$5300,3) -> 3.8 | AE31: 0.64 | AG31: =IF(AE31=" ",0,ROUND(SUM(AE31:AF31),2)) -> 0.64 | AH31: =VLOOKUP(AG31,$IK$5000:$IU$5300,3) -> 2 | AL31: 0.84 | AN31: =IF(AL31=" ",0,ROUND(SUM(AL31:AM31),2)) -> 0.84 | AO31: =VLOOKUP(AN31,$IK$5000:$IU$5300,3) -> 3.1 | AS31: 0.65 | AU31: =IF(AS31=" ",0,ROUND(SUM(AS31:AT31),2)) -> 0.65 | AV31: =VLOOKUP(AU31,$IK$5000:$IU$5300,3) -> 2.1 | AZ31: 0.94 | BB31: =IF(AZ31=" ",0,ROUND(SUM(AZ31:BA31),2)) -> 0.94 | BC31: =VLOOKUP(BB31,$IK$5000:$IU$5300,3) -> 3.6 | BG31: 0.27 | BI31: =IF(BG31=" ",0,ROUND(SUM(BG31:BH31),2)) -> 0.27 | BJ31: =VLOOKUP(BI31,$IK$5000:$IU$5300,3) -> 0.75 | BN31: 0.46 | BP31: =IF(BN31=" ",0,ROUND(SUM(BN31:BO31),2)) -> 0.46 | BQ31: =VLOOKUP(BP31,$IK$5000:$IU$5300,3) -> 1.288 | BU31: 0.53 | BW31: =IF(BU31=" ",0,ROUND(SUM(BU31:BV31),2)) -> 0.53 | BX31: =VLOOKUP(BW31,$IK$5000:$IU$5300,3) -> 1.5 | CD31: =IF(CB31=" ",0,ROUND(SUM(CB31:CC31),2)) -> 0 | CE31: =VLOOKUP(CD31,$IK$5000:$IU$5300,3) -> 0 | CG31: 18 | CH31: =IF(B31=" ",F31,B31*F31/24) -> 0 | CI31: =IF(I31=" ",M31,I31*M31/24) -> 0 | CJ31: =IF(P31=" ",T31,P31*T31/24) -> 1.8 | CK31: =IF(W31=" ",AA31,W31*AA31/24) -> 3.8 | CL31: =IF(AD31=" ",AH31,AD31*AH31/24) -> 2 | CM31: =IF(AK31=" ",AO31,AK31*AO31/24) -> 3.1 | CN31: =IF(AR31=" ",AV31,AR31*AV31/24) -> 2.1 | CO31: =IF(AY31=" ",BC31,AY31*BC31/24) -> 3.6 | CP31: =IF(BF31=" ",BJ31,BF31*BJ31/24) -> 0.75 | CQ31: =IF(BM31=" ",BQ31,BM31*BQ31/24) -> 1.288 | CR31: =IF(BT31=" ",BX31,BT31*BX31/24) -> 1.5 | CS31: =IF(CA31=" ",CE31,CA31*CE31/24) -> 0
A32: 19 | C32: 0 | D32: 0 | E32: =IF(C32=" ",0,ROUND(SUM(C32:D32),2)) -> 0 | F32: =VLOOKUP(E32,$IK$5000:$IU$5300,3) -> 0 | L32: =IF(J32=" ",0,ROUND(SUM(J32:K32),2)) -> 0 | M32: =VLOOKUP(L32,$IK$5000:$IU$5300,3) -> 0 | Q32: 0.51 | S32: =IF(Q32=" ",0,ROUND(SUM(Q32:R32),2)) -> 0.51 | T32: =VLOOKUP(S32,$IK$5000:$IU$5300,3) -> 1.4 | X32: 0.82 | Z32: =IF(X32=" ",0,ROUND(SUM(X32:Y32),2)) -> 0.82 | AA32: =VLOOKUP(Z32,$IK$5000:$IU$5300,3) -> 3 | AE32: 0.85 | AG32: =IF(AE32=" ",0,ROUND(SUM(AE32:AF32),2)) -> 0.85 | AH32: =VLOOKUP(AG32,$IK$5000:$IU$5300,3) -> 3.1 | AL32: 0.85 | AN32: =IF(AL32=" ",0,ROUND(SUM(AL32:AM32),2)) -> 0.85 | AO32: =VLOOKUP(AN32,$IK$5000:$IU$5300,3) -> 3.1 | AS32: 0.64 | AU32: =IF(AS32=" ",0,ROUND(SUM(AS32:AT32),2)) -> 0.64 | AV32: =VLOOKUP(AU32,$IK$5000:$IU$5300,3) -> 2 | AZ32: 0.83 | BB32: =IF(AZ32=" ",0,ROUND(SUM(AZ32:BA32),2)) -> 0.83 | BC32: =VLOOKUP(BB32,$IK$5000:$IU$5300,3) -> 3 | BG32: 0.25 | BI32: =IF(BG32=" ",0,ROUND(SUM(BG32:BH32),2)) -> 0.25 | BJ32: =VLOOKUP(BI32,$IK$5000:$IU$5300,3) -> 0.7 | BN32: 0.46 | BP32: =IF(BN32=" ",0,ROUND(SUM(BN32:BO32),2)) -> 0.46 | BQ32: =VLOOKUP(BP32,$IK$5000:$IU$5300,3) -> 1.288 | BU32: 0.53 | BW32: =IF(BU32=" ",0,ROUND(SUM(BU32:BV32),2)) -> 0.53 | BX32: =VLOOKUP(BW32,$IK$5000:$IU$5300,3) -> 1.5 | CD32: =IF(CB32=" ",0,ROUND(SUM(CB32:CC32),2)) -> 0 | CE32: =VLOOKUP(CD32,$IK$5000:$IU$5300,3) -> 0 | CG32: 19 | CH32: =IF(B32=" ",F32,B32*F32/24) -> 0 | CI32: =IF(I32=" ",M32,I32*M32/24) -> 0 | CJ32: =IF(P32=" ",T32,P32*T32/24) -> 1.4 | CK32: =IF(W32=" ",AA32,W32*AA32/24) -> 3 | CL32: =IF(AD32=" ",AH32,AD32*AH32/24) -> 3.1 | CM32: =IF(AK32=" ",AO32,AK32*AO32/24) -> 3.1 | CN32: =IF(AR32=" ",AV32,AR32*AV32/24) -> 2 | CO32: =IF(AY32=" ",BC32,AY32*BC32/24) -> 3 | CP32: =IF(BF32=" ",BJ32,BF32*BJ32/24) -> 0.7 | CQ32: =IF(BM32=" ",BQ32,BM32*BQ32/24) -> 1.288 | CR32: =IF(BT32=" ",BX32,BT32*BX32/24) -> 1.5 | CS32: =IF(CA32=" ",CE32,CA32*CE32/24) -> 0
A33: 20 | C33: 0 | D33: 0 | E33: =IF(C33=" ",0,ROUND(SUM(C33:D33),2)) -> 0 | F33: =VLOOKUP(E33,$IK$5000:$IU$5300,3) -> 0 | L33: =IF(J33=" ",0,ROUND(SUM(J33:K33),2)) -> 0 | M33: =VLOOKUP(L33,$IK$5000:$IU$5300,3) -> 0 | Q33: 0.55 | S33: =IF(Q33=" ",0,ROUND(SUM(Q33:R33),2)) -> 0.55 | T33: =VLOOKUP(S33,$IK$5000:$IU$5300,3) -> 1.6 | X33: 0.67 | Z33: =IF(X33=" ",0,ROUND(SUM(X33:Y33),2)) -> 0.67 | AA33: =VLOOKUP(Z33,$IK$5000:$IU$5300,3) -> 2.2 | AE33: 0.96 | AG33: =IF(AE33=" ",0,ROUND(SUM(AE33:AF33),2)) -> 0.96 | AH33: =VLOOKUP(AG33,$IK$5000:$IU$5300,3) -> 3.8 | AL33: 0.84 | AN33: =IF(AL33=" ",0,ROUND(SUM(AL33:AM33),2)) -> 0.84 | AO33: =VLOOKUP(AN33,$IK$5000:$IU$5300,3) -> 3.1 | AS33: 0.73 | AU33: =IF(AS33=" ",0,ROUND(SUM(AS33:AT33),2)) -> 0.73 | AV33: =VLOOKUP(AU33,$IK$5000:$IU$5300,3) -> 2.5 | AZ33: 0.69 | BB33: =IF(AZ33=" ",0,ROUND(SUM(AZ33:BA33),2)) -> 0.69 | BC33: =VLOOKUP(BB33,$IK$5000:$IU$5300,3) -> 2.3 | BG33: 0.4 | BI33: =IF(BG33=" ",0,ROUND(SUM(BG33:BH33),2)) -> 0.4 | BJ33: =VLOOKUP(BI33,$IK$5000:$IU$5300,3) -> 1.12 | BN33: 0.46 | BP33: =IF(BN33=" ",0,ROUND(SUM(BN33:BO33),2)) -> 0.46 | BQ33: =VLOOKUP(BP33,$IK$5000:$IU$5300,3) -> 1.288 | BU33: 0.53 | BW33: =IF(BU33=" ",0,ROUND(SUM(BU33:BV33),2)) -> 0.53 | BX33: =VLOOKUP(BW33,$IK$5000:$IU$5300,3) -> 1.5 | CD33: =IF(CB33=" ",0,ROUND(SUM(CB33:CC33),2)) -> 0 | CE33: =VLOOKUP(CD33,$IK$5000:$IU$5300,3) -> 0 | CG33: 20 | CH33: =IF(B33=" ",F33,B33*F33/24) -> 0 | CI33: =IF(I33=" ",M33,I33*M33/24) -> 0 | CJ33: =IF(P33=" ",T33,P33*T33/24) -> 1.6 | CK33: =IF(W33=" ",AA33,W33*AA33/24) -> 2.2 | CL33: =IF(AD33=" ",AH33,AD33*AH33/24) -> 3.8 | CM33: =IF(AK33=" ",AO33,AK33*AO33/24) -> 3.1 | CN33: =IF(AR33=" ",AV33,AR33*AV33/24) -> 2.5 | CO33: =IF(AY33=" ",BC33,AY33*BC33/24) -> 2.3 | CP33: =IF(BF33=" ",BJ33,BF33*BJ33/24) -> 1.12 | CQ33: =IF(BM33=" ",BQ33,BM33*BQ33/24) -> 1.288 | CR33: =IF(BT33=" ",BX33,BT33*BX33/24) -> 1.5 | CS33: =IF(CA33=" ",CE33,CA33*CE33/24) -> 0
A34: 21 | C34: 0 | D34: 0 | E34: =IF(C34=" ",0,ROUND(SUM(C34:D34),2)) -> 0 | F34: =VLOOKUP(E34,$IK$5000:$IU$5300,3) -> 0 | L34: =IF(J34=" ",0,ROUND(SUM(J34:K34),2)) -> 0 | M34: =VLOOKUP(L34,$IK$5000:$IU$5300,3) -> 0 | Q34: 0.71 | S34: =IF(Q34=" ",0,ROUND(SUM(Q34:R34),2)) -> 0.71 | T34: =VLOOKUP(S34,$IK$5000:$IU$5300,3) -> 2.4 | X34: 0.67 | Z34: =IF(X34=" ",0,ROUND(SUM(X34:Y34),2)) -> 0.67 | AA34: =VLOOKUP(Z34,$IK$5000:$IU$5300,3) -> 2.2 | AE34: 0.8 | AG34: =IF(AE34=" ",0,ROUND(SUM(AE34:AF34),2)) -> 0.8 | AH34: =VLOOKUP(AG34,$IK$5000:$IU$5300,3) -> 2.8 | AL34: 0.78 | AN34: =IF(AL34=" ",0,ROUND(SUM(AL34:AM34),2)) -> 0.78 | AO34: =VLOOKUP(AN34,$IK$5000:$IU$5300,3) -> 2.7 | AS34: 0.9 | AU34: =IF(AS34=" ",0,ROUND(SUM(AS34:AT34),2)) -> 0.9 | AV34: =VLOOKUP(AU34,$IK$5000:$IU$5300,3) -> 3.4 | AZ34: 0.68 | BB34: =IF(AZ34=" ",0,ROUND(SUM(AZ34:BA34),2)) -> 0.68 | BC34: =VLOOKUP(BB34,$IK$5000:$IU$5300,3) -> 2.2 | BG34: 0.54 | BI34: =IF(BG34=" ",0,ROUND(SUM(BG34:BH34),2)) -> 0.54 | BJ34: =VLOOKUP(BI34,$IK$5000:$IU$5300,3) -> 1.6 | BN34: 0.46 | BP34: =IF(BN34=" ",0,ROUND(SUM(BN34:BO34),2)) -> 0.46 | BQ34: =VLOOKUP(BP34,$IK$5000:$IU$5300,3) -> 1.288 | BU34: 0.53 | BW34: =IF(BU34=" ",0,ROUND(SUM(BU34:BV34),2)) -> 0.53 | BX34: =VLOOKUP(BW34,$IK$5000:$IU$5300,3) -> 1.5 | CD34: =IF(CB34=" ",0,ROUND(SUM(CB34:CC34),2)) -> 0 | CE34: =VLOOKUP(CD34,$IK$5000:$IU$5300,3) -> 0 | CG34: 21 | CH34: =IF(B34=" ",F34,B34*F34/24) -> 0 | CI34: =IF(I34=" ",M34,I34*M34/24) -> 0 | CJ34: =IF(P34=" ",T34,P34*T34/24) -> 2.4 | CK34: =IF(W34=" ",AA34,W34*AA34/24) -> 2.2 | CL34: =IF(AD34=" ",AH34,AD34*AH34/24) -> 2.8 | CM34: =IF(AK34=" ",AO34,AK34*AO34/24) -> 2.7 | CN34: =IF(AR34=" ",AV34,AR34*AV34/24) -> 3.4 | CO34: =IF(AY34=" ",BC34,AY34*BC34/24) -> 2.2 | CP34: =IF(BF34=" ",BJ34,BF34*BJ34/24) -> 1.6 | CQ34: =IF(BM34=" ",BQ34,BM34*BQ34/24) -> 1.288 | CR34: =IF(BT34=" ",BX34,BT34*BX34/24) -> 1.5 | CS34: =IF(CA34=" ",CE34,CA34*CE34/24) -> 0
A35: 22 | C35: 0 | D35: 0 | E35: =IF(C35=" ",0,ROUND(SUM(C35:D35),2)) -> 0 | F35: =VLOOKUP(E35,$IK$5000:$IU$5300,3) -> 0 | L35: =IF(J35=" ",0,ROUND(SUM(J35:K35),2)) -> 0 | M35: =VLOOKUP(L35,$IK$5000:$IU$5300,3) -> 0 | Q35: 0.94 | S35: =IF(Q35=" ",0,ROUND(SUM(Q35:R35),2)) -> 0.94 | T35: =VLOOKUP(S35,$IK$5000:$IU$5300,3) -> 3.6 | X35: 0.85 | Z35: =IF(X35=" ",0,ROUND(SUM(X35:Y35),2)) -> 0.85 | AA35: =VLOOKUP(Z35,$IK$5000:$IU$5300,3) -> 3.1 | AE35: 0.71 | AG35: =IF(AE35=" ",0,ROUND(SUM(AE35:AF35),2)) -> 0.71 | AH35: =VLOOKUP(AG35,$IK$5000:$IU$5300,3) -> 2.4 | AL35: 0.81 | AN35: =IF(AL35=" ",0,ROUND(SUM(AL35:AM35),2)) -> 0.81 | AO35: =VLOOKUP(AN35,$IK$5000:$IU$5300,3) -> 2.9 | AS35: 0.84 | AU35: =IF(AS35=" ",0,ROUND(SUM(AS35:AT35),2)) -> 0.84 | AV35: =VLOOKUP(AU35,$IK$5000:$IU$5300,3) -> 3.1 | AZ35: 0.67 | BB35: =IF(AZ35=" ",0,ROUND(SUM(AZ35:BA35),2)) -> 0.67 | BC35: =VLOOKUP(BB35,$IK$5000:$IU$5300,3) -> 2.2 | BG35: 0.54 | BI35: =IF(BG35=" ",0,ROUND(SUM(BG35:BH35),2)) -> 0.54 | BJ35: =VLOOKUP(BI35,$IK$5000:$IU$5300,3) -> 1.6 | BN35: 0.46 | BP35: =IF(BN35=" ",0,ROUND(SUM(BN35:BO35),2)) -> 0.46 | BQ35: =VLOOKUP(BP35,$IK$5000:$IU$5300,3) -> 1.288 | BU35: 0.53 | BW35: =IF(BU35=" ",0,ROUND(SUM(BU35:BV35),2)) -> 0.53 | BX35: =VLOOKUP(BW35,$IK$5000:$IU$5300,3) -> 1.5 | CD35: =IF(CB35=" ",0,ROUND(SUM(CB35:CC35),2)) -> 0 | CE35: =VLOOKUP(CD35,$IK$5000:$IU$5300,3) -> 0 | CG35: 22 | CH35: =IF(B35=" ",F35,B35*F35/24) -> 0 | CI35: =IF(I35=" ",M35,I35*M35/24) -> 0 | CJ35: =IF(P35=" ",T35,P35*T35/24) -> 3.6 | CK35: =IF(W35=" ",AA35,W35*AA35/24) -> 3.1 | CL35: =IF(AD35=" ",AH35,AD35*AH35/24) -> 2.4 | CM35: =IF(AK35=" ",AO35,AK35*AO35/24) -> 2.9 | CN35: =IF(AR35=" ",AV35,AR35*AV35/24) -> 3.1 | CO35: =IF(AY35=" ",BC35,AY35*BC35/24) -> 2.2 | CP35: =IF(BF35=" ",BJ35,BF35*BJ35/24) -> 1.6 | CQ35: =IF(BM35=" ",BQ35,BM35*BQ35/24) -> 1.288 | CR35: =IF(BT35=" ",BX35,BT35*BX35/24) -> 1.5 | CS35: =IF(CA35=" ",CE35,CA35*CE35/24) -> 0
... A41: 28 | C41: 0 | D41: 0 | E41: =IF(C41=" ",0,ROUND(SUM(C41:D41),2)) -> 0 | F41: =VLOOKUP(E41,$IK$5000:$IU$5300,3) -> 0 | L41: =IF(J41=" ",0,ROUND(SUM(J41:K41),2)) -> 0 | M41: =VLOOKUP(L41,$IK$5000:$IU$5300,3) -> 0 | Q41: 0.68 | S41: =IF(Q41=" ",0,ROUND(SUM(Q41:R41),2)) -> 0.68 | T41: =VLOOKUP(S41,$IK$5000:$IU$5300,3) -> 2.2 | X41: 0.72 | Z41: =IF(X41=" ",0,ROUND(SUM(X41:Y41),2)) -> 0.72 | AA41: =VLOOKUP(Z41,$IK$5000:$IU$5300,3) -> 2.4 | AE41: 0.88 | AG41: =IF(AE41=" ",0,ROUND(SUM(AE41:AF41),2)) -> 0.88 | AH41: =VLOOKUP(AG41,$IK$5000:$IU$5300,3) -> 3.3 | AL41: 0.83 | AN41: =IF(AL41=" ",0,ROUND(SUM(AL41:AM41),2)) -> 0.83 | AO41: =VLOOKUP(AN41,$IK$5000:$IU$5300,3) -> 3 | AS41: 0.91 | AU41: =IF(AS41=" ",0,ROUND(SUM(AS41:AT41),2)) -> 0.91 | AV41: =VLOOKUP(AU41,$IK$5000:$IU$5300,3) -> 3.5 | AZ41: 0.79 | BB41: =IF(AZ41=" ",0,ROUND(SUM(AZ41:BA41),2)) -> 0.79 | BC41: =VLOOKUP(BB41,$IK$5000:$IU$5300,3) -> 2.8 | BG41: 0.33 | BI41: =IF(BG41=" ",0,ROUND(SUM(BG41:BH41),2)) -> 0.33 | BJ41: =VLOOKUP(BI41,$IK$5000:$IU$5300,3) -> 0.924 | BN41: 0.83 | BP41: =IF(BN41=" ",0,ROUND(SUM(BN41:BO41),2)) -> 0.83 | BQ41: =VLOOKUP(BP41,$IK$5000:$IU$5300,3) -> 3 | BU41: 0.53 | BW41: =IF(BU41=" ",0,ROUND(SUM(BU41:BV41),2)) -> 0.53 | BX41: =VLOOKUP(BW41,$IK$5000:$IU$5300,3) -> 1.5 | CD41: =IF(CB41=" ",0,ROUND(SUM(CB41:CC41),2)) -> 0 | CE41: =VLOOKUP(CD41,$IK$5000:$IU$5300,3) -> 0 | CG41: 28 | CH41: =IF(B41=" ",F41,B41*F41/24) -> 0 | CI41: =IF(I41=" ",M41,I41*M41/24) -> 0 | CJ41: =IF(P41=" ",T41,P41*T41/24) -> 2.2 | CK41: =IF(W41=" ",AA41,W41*AA41/24) -> 2.4 | CL41: =IF(AD41=" ",AH41,AD41*AH41/24) -> 3.3 | CM41: =IF(AK41=" ",AO41,AK41*AO41/24) -> 3 | CN41: =IF(AR41=" ",AV41,AR41*AV41/24) -> 3.5 | CO41: =IF(AY41=" ",BC41,AY41*BC41/24) -> 2.8 | CP41: =IF(BF41=" ",BJ41,BF41*BJ41/24) -> 0.924 | CQ41: =IF(BM41=" ",BQ41,BM41*BQ41/24) -> 3 | CR41: =IF(BT41=" ",BX41,BT41*BX41/24) -> 1.5 | CS41: =IF(CA41=" ",CE41,CA41*CE41/24) -> 0
A42: 29 | C42: 0 | D42: 0 | E42: =IF(C42=" ",0,ROUND(SUM(C42:D42),2)) -> 0 | F42: =VLOOKUP(E42,$IK$5000:$IU$5300,3) -> 0 | J42: 0 | L42: =IF(J42=" ",0,ROUND(SUM(J42:K42),2)) -> 0 | M42: =VLOOKUP(L42,$IK$5000:$IU$5300,3) -> 0 | Q42: 0.62 | S42: =IF(Q42=" ",0,ROUND(SUM(Q42:R42),2)) -> 0.62 | T42: =VLOOKUP(S42,$IK$5000:$IU$5300,3) -> 1.9 | X42: 0.94 | Z42: =IF(X42=" ",0,ROUND(SUM(X42:Y42),2)) -> 0.94 | AA42: =VLOOKUP(Z42,$IK$5000:$IU$5300,3) -> 3.6 | AE42: 0.66 | AG42: =IF(AE42=" ",0,ROUND(SUM(AE42:AF42),2)) -> 0.66 | AH42: =VLOOKUP(AG42,$IK$5000:$IU$5300,3) -> 2.1 | AL42: 0.83 | AN42: =IF(AL42=" ",0,ROUND(SUM(AL42:AM42),2)) -> 0.83 | AO42: =VLOOKUP(AN42,$IK$5000:$IU$5300,3) -> 3 | AS42: 0.85 | AU42: =IF(AS42=" ",0,ROUND(SUM(AS42:AT42),2)) -> 0.85 | AV42: =VLOOKUP(AU42,$IK$5000:$IU$5300,3) -> 3.1 | AZ42: 0.92 | BB42: =IF(AZ42=" ",0,ROUND(SUM(AZ42:BA42),2)) -> 0.92 | BC42: =VLOOKUP(BB42,$IK$5000:$IU$5300,3) -> 3.5 | BG42: 0.33 | BI42: =IF(BG42=" ",0,ROUND(SUM(BG42:BH42),2)) -> 0.33 | BJ42: =VLOOKUP(BI42,$IK$5000:$IU$5300,3) -> 0.924 | BN42: 0.88 | BP42: =IF(BN42=" ",0,ROUND(SUM(BN42:BO42),2)) -> 0.88 | BQ42: =VLOOKUP(BP42,$IK$5000:$IU$5300,3) -> 3.3 | BU42: 0.52 | BW42: =IF(BU42=" ",0,ROUND(SUM(BU42:BV42),2)) -> 0.52 | BX42: =VLOOKUP(BW42,$IK$5000:$IU$5300,3) -> 1.5 | CD42: =IF(CB42=" ",0,ROUND(SUM(CB42:CC42),2)) -> 0 | CE42: =VLOOKUP(CD42,$IK$5000:$IU$5300,3) -> 0 | CG42: 29 | CH42: =IF(B42=" ",F42,B42*F42/24) -> 0 | CI42: ------- | CJ42: =IF(P42=" ",T42,P42*T42/24) -> 1.9 | CK42: =IF(W42=" ",AA42,W42*AA42/24) -> 3.6 | CL42: =IF(AD42=" ",AH42,AD42*AH42/24) -> 2.1 | CM42: =IF(AK42=" ",AO42,AK42*AO42/24) -> 3 | CN42: =IF(AR42=" ",AV42,AR42*AV42/24) -> 3.1 | CO42: =IF(AY42=" ",BC42,AY42*BC42/24) -> 3.5 | CP42: =IF(BF42=" ",BJ42,BF42*BJ42/24) -> 0.924 | CQ42: =IF(BM42=" ",BQ42,BM42*BQ42/24) -> 3.3 | CR42: =IF(BT42=" ",BX42,BT42*BX42/24) -> 1.5 | CS42: =IF(CA42=" ",CE42,CA42*CE42/24) -> 0
A43: 30 | C43: 0 | D43: 0 | E43: =IF(C43=" ",0,ROUND(SUM(C43:D43),2)) -> 0 | F43: =VLOOKUP(E43,$IK$5000:$IU$5300,3) -> 0 | J43: 0 | L43: =IF(J43=" ",0,ROUND(SUM(J43:K43),2)) -> 0 | M43: =VLOOKUP(L43,$IK$5000:$IU$5300,3) -> 0 | Q43: 0.92 | S43: =IF(Q43=" ",0,ROUND(SUM(Q43:R43),2)) -> 0.92 | T43: =VLOOKUP(S43,$IK$5000:$IU$5300,3) -> 3.5 | X43: 0.93 | Z43: =IF(X43=" ",0,ROUND(SUM(X43:Y43),2)) -> 0.93 | AA43: =VLOOKUP(Z43,$IK$5000:$IU$5300,3) -> 3.6 | AE43: 0.72 | AG43: =IF(AE43=" ",0,ROUND(SUM(AE43:AF43),2)) -> 0.72 | AH43: =VLOOKUP(AG43,$IK$5000:$IU$5300,3) -> 2.4 | AL43: 0.6 | AN43: =IF(AL43=" ",0,ROUND(SUM(AL43:AM43),2)) -> 0.6 | AO43: =VLOOKUP(AN43,$IK$5000:$IU$5300,3) -> 1.8 | AS43: 0.65 | AU43: =IF(AS43=" ",0,ROUND(SUM(AS43:AT43),2)) -> 0.65 | AV43: =VLOOKUP(AU43,$IK$5000:$IU$5300,3) -> 2.1 | AZ43: 0.8 | BB43: =IF(AZ43=" ",0,ROUND(SUM(AZ43:BA43),2)) -> 0.8 | BC43: =VLOOKUP(BB43,$IK$5000:$IU$5300,3) -> 2.8 | BG43: 0.38 | BI43: =IF(BG43=" ",0,ROUND(SUM(BG43:BH43),2)) -> 0.38 | BJ43: =VLOOKUP(BI43,$IK$5000:$IU$5300,3) -> 1.064 | BN43: 0.79 | BP43: =IF(BN43=" ",0,ROUND(SUM(BN43:BO43),2)) -> 0.79 | BQ43: =VLOOKUP(BP43,$IK$5000:$IU$5300,3) -> 2.8 | BU43: 0.52 | BW43: =IF(BU43=" ",0,ROUND(SUM(BU43:BV43),2)) -> 0.52 | BX43: =VLOOKUP(BW43,$IK$5000:$IU$5300,3) -> 1.5 | CD43: =IF(CB43=" ",0,ROUND(SUM(CB43:CC43),2)) -> 0 | CE43: =VLOOKUP(CD43,$IK$5000:$IU$5300,3) -> 0 | CG43: 30 | CH43: =IF(B43=" ",F43,B43*F43/24) -> 0 | CI43: ------- | CJ43: =IF(P43=" ",T43,P43*T43/24) -> 3.5 | CK43: =IF(W43=" ",AA43,W43*AA43/24) -> 3.6 | CL43: =IF(AD43=" ",AH43,AD43*AH43/24) -> 2.4 | CM43: =IF(AK43=" ",AO43,AK43*AO43/24) -> 1.8 | CN43: =IF(AR43=" ",AV43,AR43*AV43/24) -> 2.1 | CO43: =IF(AY43=" ",BC43,AY43*BC43/24) -> 2.8 | CP43: =IF(BF43=" ",BJ43,BF43*BJ43/24) -> 1.064 | CQ43: =IF(BM43=" ",BQ43,BM43*BQ43/24) -> 2.8 | CR43: =IF(BT43=" ",BX43,BT43*BX43/24) -> 1.5 | CS43: =IF(CA43=" ",CE43,CA43*CE43/24) -> 0
A44: 31 | C44: 0 | D44: 0 | E44: =IF(C44=" ",0,ROUND(SUM(C44:D44),2)) -> 0 | F44: =VLOOKUP(E44,$IK$5000:$IU$5300,3) -> 0 | L44: =IF(J44=" ",0,ROUND(SUM(J44:K44),2)) -> 0 | M44: =VLOOKUP(L44,$IK$5000:$IU$5300,3) -> 0 | Q44: 0.92 | S44: =IF(Q44=" ",0,ROUND(SUM(Q44:R44),2)) -> 0.92 | T44: =VLOOKUP(S44,$IK$5000:$IU$5300,3) -> 3.5 | Z44: =IF(X44=" ",0,ROUND(SUM(X44:Y44),2)) -> 0 | AA44: =VLOOKUP(Z44,$IK$5000:$IU$5300,3) -> 0 | AE44: 0.87 | AG44: =IF(AE44=" ",0,ROUND(SUM(AE44:AF44),2)) -> 0.87 | AH44: =VLOOKUP(AG44,$IK$5000:$IU$5300,3) -> 3.2 | AS44: 0.33 | AU44: =IF(AS44=" ",0,ROUND(SUM(AS44:AT44),2)) -> 0.33 | AV44: =VLOOKUP(AU44,$IK$5000:$IU$5300,3) -> 0.924 | AZ44: 0.68 | BB44: =IF(AZ44=" ",0,ROUND(SUM(AZ44:BA44),2)) -> 0.68 | BC44: =VLOOKUP(BB44,$IK$5000:$IU$5300,3) -> 2.2 | BN44: 0.56 | BP44: =IF(BN44=" ",0,ROUND(SUM(BN44:BO44),2)) -> 0.56 | BQ44: =VLOOKUP(BP44,$IK$5000:$IU$5300,3) -> 1.7 | BW44: =IF(BU44=" ",0,ROUND(SUM(BU44:BV44),2)) -> 0 | BX44: =VLOOKUP(BW44,$IK$5000:$IU$5300,3) -> 0 | CD44: =IF(CB44=" ",0,ROUND(SUM(CB44:CC44),2)) -> 0 | CE44: =VLOOKUP(CD44,$IK$5000:$IU$5300,3) -> 0 | CG44: 31 | CH44: =IF(B44=" ",F44,B44*F44/24) -> 0 | CI44: ------- | CJ44: =IF(P44=" ",T44,P44*T44/24) -> 3.5 | CK44: ------- | CL44: =IF(AD44=" ",AH44,AD44*AH44/24) -> 3.2 | CM44: ------- | CN44: =IF(AR44=" ",AV44,AR44*AV44/24) -> 0.924 | CO44: =IF(AY44=" ",BC44,AY44*BC44/24) -> 2.2 | CP44: ------- | CQ44: =IF(BM44=" ",BQ44,BM44*BQ44/24) -> 1.7 | CR44: ------- | CS44: =IF(CA44=" ",CE44,CA44*CE44/24) -> 0
A45: = | B45: = | C45: = | D45: = | E45: = | F45: = | I45: = | J45: = | K45: = | L45: = | M45: = | P45: = | Q45: = | R45: = | S45: = | T45: = | W45: = | Y45: = | Z45: = | AA45: = | AD45: = | AE45: = | AF45: = | AG45: = | AH45: = | AK45: = | AL45: = | AR45: = | AS45: = | AT45: = | AU45: = | AV45: = | AY45: = | AZ45: = | BA45: = | BB45: = | BC45: = | BF45: = | BG45: = | BH45: = | BI45: = | BJ45: = | BM45: = | BN45: = | BO45: = | BP45: = | BQ45: = | BT45: = | BU45: = | BV45: = | BW45: = | BX45: = | CA45: = | CB45: = | CC45: = | CD45: = | CE45: =
A46: CFS | X46: . | CH46: C.F.S.
A47: CFS | CH47: =SUM(CH14:CH44) -> 0 | CI47: =SUM(CI14:CI41) -> 0 | CJ47: =SUM(CJ14:CJ44) -> 53.6125 | CK47: =SUM(CK14:CK43) -> 89.4 | CL47: =SUM(CL14:CL44) -> 93.9 | CM47: =SUM(CM14:CM43) -> 84.2 | CN47: =SUM(CN14:CN44) -> 77.14 | CO47: =SUM(CO14:CO44) -> 83.184 | CP47: =SUM(CP14:CP43) -> 49.05 | CQ47: =SUM(CQ14:CQ44) -> 54.972 | CR47: =SUM(CR14:CR43) -> 46.1 | CS47: =SUM(CS14:CS44) -> 0
A48: AC/FT | CH48: ACRE FEET
A49: AC/FT | CH49: =1.9835*CH47 -> 0 | CI49: =1.9835*CI47 -> 0 | CJ49: =1.9835*CJ47 -> 106.34039 | CK49: =1.9835*CK47 -> 177.3249 | CL49: =1.9835*CL47 -> 186.25065 | CM49: =1.9835*CM47 -> 167.0107 | CN49: =1.9835*CN47 -> 153.00719 | CO49: =1.9835*CO47 -> 164.99546 | ... CS49: =1.9835*CS47 -> 0
...

Sheet Upper Gila
CH4: New Mexico Interstate Stream Commission | CL4: Upper Gila Ditch near Gila, New Mexico
A6: Upper Gila Ditch near Gila, New Mexico (09430815)
CH7: Source: | CI7: Gila River | CM7: Gila - San Francisco Basins
CH8: Location: | CI8: 33.0109, -108.3237 | CM8: DAILY DISCHARGE IN C/F/S
E9: JANUARY | L9: FEBRUARY | S9: MARCH | Z9: APRIL | AG9: MAY | AN9: JUNE | AU9: JULY | BB9: AUGUST | BI9: SEPTEMBER | BP9: OCTOBER | BW9: NOVEMBER | CD9: DECEMBER | CH9: Measuring Device: Natural Channel
A10: 2025
D11: PEN | E11: GHT | F11: CFS | K11: PEN | L11: GHT | M11: CFS | R11: PEN | S11: GHT | T11: CFS | Y11: PEN | Z11: GHT | AA11: CFS | AF11: PEN | AG11: GHT | AH11: CFS | AM11: PEN | AN11: GHT | AO11: CFS | AT11: PEN | AU11: GHT | AV11: CFS | BA11: PEN | BB11: GHT | BC11: CFS | BH11: PEN | BI11: GHT | BJ11: CFS | BO11: PEN | BP11: GHT | BQ11: CFS | BV11: PEN | BW11: GHT | BX11: CFS | CC11: PEN | CD11: GHT | CE11: CFS | CH11: Calendar Year 2025 | CR11: Site ID# 09430815
A12: DAY | B12: HRS | C12: GHT | D12: SHIFT | E12: AMOUNT | F12: PER TABLE | I12: HRS | J12: GHT | K12: SHIFT | L12: AMOUNT | M12: PER TABLE | P12: HRS | Q12: GHT | R12: SHIFT | S12: AMOUNT | T12: PER TABLE | W12: HRS | X12: GHT | Y12: SHIFT | Z12: AMOUNT | AA12: PER TABLE | AD12: HRS | AE12: GHT | AF12: SHIFT | AG12: AMOUNT | AH12: PER TABLE | AK12: HRS | AL12: GHT | AM12: SHIFT | AN12: AMOUNT | AO12: PER TABLE | AR12: HRS | AS12: GHT | AT12: SHIFT | AU12: AMOUNT | AV12: PER TABLE | AY12: HRS | AZ12: GHT | BA12: SHIFT | BB12: AMOUNT | BC12: PER TABLE | BF12: HRS | BG12: GHT | BH12: SHIFT | BI12: AMOUNT | BJ12: PER TABLE | BM12: HRS | BN12: GHT | BO12: SHIFT | BP12: AMOUNT | BQ12: PER TABLE | BT12: HRS | BU12: GHT | BV12: SHIFT | BW12: AMOUNT | BX12: PER TABLE | CA12: HRS | CB12: GHT | CC12: SHIFT | CD12: AMOUNT | CE12: PER TABLE | CH12: JANUARY | CI12: FEBRUARY | CJ12: MARCH | CK12: APRIL | CL12: MAY | CM12: JUNE | CN12: JULY | CO12: AUGUST | CP12: SEPTEMBER | CQ12: OCTOBER | CR12: NOVEMBER | CS12: DECEMBER
A13: - | B13: - | C13: - | D13: - | E13: - | F13: - | I13: - | J13: - | K13: - | L13: - | M13: - | P13: - | Q13: - | R13: - | S13: - | T13: - | W13: - | Y13: - | Z13: - | AA13: - | AD13: - | AE13: - | AF13: - | AG13: - | AH13: - | AK13: - | AL13: - | AM13: - | AN13: - | AO13: - | AR13: - | AS13: - | AT13: - | AU13: - | AV13: - | AY13: - | AZ13: - | BA13: - | BB13: - | BC13: - | BF13: - | BG13: - | BH13: - | BI13: - | BJ13: - | BM13: - | BN13: - | BO13: - | BP13: - | BQ13: - | BT13: - | BU13: - | BV13: - | BW13: - | BX13: - | CA13: - | CB13: - | CC13: - | CD13: - | CE13: -
A14: 1 | C14: 0 | D14: 0 | E14: =IF(C14=" ",0,ROUND(SUM(C14:D14),2)) -> 0 | F14: =VLOOKUP(E14,$IK$5000:$IU$5300,3) -> 0 | I14: 0 | J14: 0 | K14: 0 | L14: =IF(J14=" ",0,ROUND(SUM(J14:K14),2)) -> 0 | M14: =VLOOKUP(L14,$IK$5000:$IU$5300,3) -> 0 | P14: 24 | Q14: 1.64 | R14: 0.51 | S14: =IF(Q14=" ",0,ROUND(SUM(Q14:R14),2)) -> 2.15 | T14: =VLOOKUP(S14,$IK$5000:$IU$5300,3) -> 24.14 | W14: 24 | X14: 1.53 | Y14: 0.41 | Z14: =IF(X14=" ",0,ROUND(SUM(X14:Y14),2)) -> 1.94 | AA14: =VLOOKUP(Z14,$IK$5000:$IU$5300,3) -> 15.18 | AD14: 24 | AE14: 1.59 | AF14: 0.5 | AG14: =IF(AE14=" ",0,ROUND(SUM(AE14:AF14),2)) -> 2.09 | AH14: =VLOOKUP(AG14,$IK$5000:$IU$5300,3) -> 21.34 | AK14: 24 | AL14: 1.06 | AM14: 0.4 | AN14: =IF(AL14=" ",0,ROUND(SUM(AL14:AM14),2)) -> 1.46 | AO14: =VLOOKUP(AN14,$IK$5000:$IU$5300,3) -> 3.14 | AR14: 24 | AS14: 0.97 | AT14: 0.41 | AU14: =IF(AS14=" ",0,ROUND(SUM(AS14:AT14),2)) -> 1.38 | AV14: =VLOOKUP(AU14,$IK$5000:$IU$5300,3) -> 2.1 | AY14: 24 | AZ14: 1.3 | BA14: 0.47 | BB14: =IF(AZ14=" ",0,ROUND(SUM(AZ14:BA14),2)) -> 1.77 | BC14: =VLOOKUP(BB14,$IK$5000:$IU$5300,3) -> 9.65 | BF14: 24 | BG14: 1.51 | BH14: 0.53 | BI14: =IF(BG14=" ",0,ROUND(SUM(BG14:BH14),2)) -> 2.04 | BJ14: =VLOOKUP(BI14,$IK$5000:$IU$5300,3) -> 19.15 | BM14: 24 | BN14: 1.46 | BO14: 0.49 | BP14: =IF(BN14=" ",0,ROUND(SUM(BN14:BO14),2)) -> 1.95 | BQ14: =VLOOKUP(BP14,$IK$5000:$IU$5300,3) -> 15.56 | BT14: 24 | BU14: 1.55 | BV14: 0.49 | BW14: =IF(BU14=" ",0,ROUND(SUM(BU14:BV14),2)) -> 2.04 | BX14: =VLOOKUP(BW14,$IK$5000:$IU$5300,3) -> 19.15 | CD14: =IF(CB14=" ",0,ROUND(SUM(CB14:CC14),2)) -> 0 | CE14: =VLOOKUP(CD14,$IK$5000:$IU$5300,3) -> 0 | CG14: 1 | CH14: =IF(B14=" ",F14,B14*F14/24) -> 0 | CI14: =IF(I14=" ",M14,I14*M14/24) -> 0 | CJ14: =IF(P14=" ",T14,P14*T14/24) -> 24.14 | CK14: =IF(W14=" ",AA14,W14*AA14/24) -> 15.18 | CL14: =IF(AD14=" ",AH14,AD14*AH14/24) -> 21.34 | CM14: =IF(AK14=" ",AO14,AK14*AO14/24) -> 3.14 | CN14: =IF(AR14=" ",AV14,AR14*AV14/24) -> 2.1 | CO14: =IF(AY14=" ",BC14,AY14*BC14/24) -> 9.65 | CP14: =IF(BF14=" ",BJ14,BF14*BJ14/24) -> 19.15 | CQ14: =IF(BM14=" ",BQ14,BM14*BQ14/24) -> 15.56 | CR14: =IF(BT14=" ",BX14,BT14*BX14/24) -> 19.15 | CS14: =IF(CA14=" ",CE14,CA14*CE14/24) -> 0
