Workbook
Name _ftn1: 'stock-dom-com-ind-evap'!#REF!
Name _ftn2: 'stock-dom-com-ind-evap'!#REF!
Name _ftn3: 'stock-dom-com-ind-evap'!#REF!
Name _ftn4: 'stock-dom-com-ind-evap'!#REF!
Name _ftn5: 'stock-dom-com-ind-evap'!#REF!
Name _ftn6: 'stock-dom-com-ind-evap'!#REF!
Name _ftnref1: 'stock-dom-com-ind-evap'!$C$81
Name _ftnref2: 'stock-dom-com-ind-evap'!$C$82
Name _ftnref3: 'stock-dom-com-ind-evap'!$C$107
Name _ftnref4: 'stock-dom-com-ind-evap'!$C$108
Name _ftnref5: 'stock-dom-com-ind-evap'!$C$110
Name _ftnref6: 'stock-dom-com-ind-evap'!$C$111

Sheet stock-dom-com-ind-evap
A1: LIVESTOCK POPULATION
B2: All Cattle* | C2: Sheep** | D2: county ansi | E2: api key | F2: 153C1A44-28F2-3EA4-8C9B-2128CBAB7911
A4: Catron | B4: 33500 | C4: 100 | D4: ‘003 | E4: cattle | F4: quickstats.nass.usda.gov/api/api_GET/?key=153C1A44-28F2-3EA4-8C9B-2128CBAB7911&short_desc=CATTLE, INCL CALVES - INVENTORY&year=2025&state_alpha=NM&county_ansi=003&county_ansi=017&county_ansi=023
A5: Grant | B5: 26500 | C5: 100 | D5: ‘017 | E5: cattle | F5: quickstats.nass.usda.gov/api/api_GET/?key=153C1A44-28F2-3EA4-8C9B-2128CBAB7911&short_desc=sheep, INCL lambs - INVENTORY&year=2025&state_alpha=NM&county_ansi=003&county_ansi=017&county_ansi=023
A6: Hidalgo | B6: 18300 | C6: 0 | D6: ‘023
A7: * National Agricultural Statistics Service website www.nass.usda.gov/Statistics_by_State/New_Mexico/index.php. See New Mexico Publications: Annual Statistical Bulletin.
A8: ** Estimated. National Agricultural Statistics Service reports 1200 sheep for Grant, Catron, Hidalgo, Luna, Sierra, and Socorro counties combined (District 70). Most recent estimate: 2011.
E9: Head Months | F9: Head Cattle
A10: Gila National Forest, Gila/San Francisco watershed only*** | E10: 96983 | F10: =E10/12 -> 8081.9167 | H10: Tao: what is the value of 96983? --> Forest Service cattle surveys are conducted on a ‘grazing year’ calendar and will be available after March 1 of the following year. Enter this value in E10.
B11: 51% In the Gila Drainage: | E11: =E10*0.512 -> 49655.296 | F11: =E11/12 -> 4137.9413
B12: 49% In the San Francisco Drainage: | E12: =E10*0.488 -> 47327.704 | F12: =E12/12 -> 3943.9753
A13: *** per Gila National Forest
L14: aaa
A15: Gila River Basin exclusive of Virden Valley | L15: 44
L16: =L14&L15 -> aaa44
A17: Inside National Forest
B18: =E11/12 -> 4137.9413 | C18: head in National Forest year-around | H18: Tao: why divied by 12?
D19: Total stock use in the National Forest | E19: =B18*10*365/325851 -> 46.350896 | F19: acre-feet/year | H19: Tao: 10 gallon per day per cattle
A21: Outside National Forest
B22: Drainage Basin is 53% of Grant County
B23: =B5*0.53 -> 14045 | C23: =L23&B5&M23 -> is 53% of 26500 head of cattle | L23: is 53% of | M23: head of cattle
B24: =B23-B18 -> 9907.0587 | C24: is head-units outside Forest but within Gila Drainage in Grant County year-around
E25: =B24*10*365/325851 -> 110.97331 | F25: acre-feet/year | H25: Tao: 10 gallon per day per cattle
B26: =C5*0.53 -> 53 | C26: =L26&C4&M26 -> is 53% of 100 head of sheep | E26: =B26*2.2*365/325851 -> 0.13060878 | F26: acre-feet/year | H26: Tao: 2.2 gallon per day per sheep | L26: is 53% of | M26: head of sheep
D27: Total stock use outside the National Forest | E27: =E25+E26 -> 111.10392 | F27: acre-feet/year
B28: Total stock use in the Gila River Basin above Virden Valley | E28: =E19+E25+E26 -> 157.45482 | F28: acre-feet/year
A30: Gila River Basin, Virden Valley
B31: Drainage Basin is 6% of Hidalgo County
B32: =B6*0.06 -> 1098 | C32: =L32&B6&M32 -> is 6% of 18300 head of cattle | E32: =B32*12*365/325851 -> 14.759016 | F32: acre-feet/year | H32: Tao: 10 gallon per day per cattle | L32: is 6% of | M32: head of cattle
B33: =C6*0.06 -> 0 | C33: =L33&C6&M33 -> is 6% of 0 head of sheep | E33: =B33*2.2*365/325851 -> 0 | F33: acre-feet/year | H33: Tao: 2.2 gallon per day per sheep | L33: is 6% of | M33: head of sheep
D34: Total stock use in the Gila River Basin, Virden Valley | E34: =E32+E33 -> 14.759016 | F34: acre-feet/year
A35: San Simon
B36: Drainage Basin is 7% of Hidalgo County
B37: =B6*0.07 -> 1281 | C37: =L37&B6&M37 -> is 7% of 18300 head of cattle | E37: =B37*12*365/325851 -> 17.218852 | F37: acre-feet/year | H37: Tao: 10 gallon per day per cattle | L37: is 7% of | M37: head of cattle
B38: =C6*0.07 -> 0 | C38: =L38&C6&M38 -> is 7% of 0 head of sheep | E38: =B38*2.2*365/325851 -> 0 | F38: acre-feet/year | H38: Tao: 2.2 gallon per day per sheep | L38: is 7% of | M38: head of sheep
D39: Total stock use in the San Simon area | E39: =SUM(E37:E38) -> 17.218852 | F39: acre-feet/year
A41: San Francisco River Basin
A42: Inside National Forest
B43: =E12/12 -> 3943.9753 | C43: head in National Forest year-around
D44: Total stock use in the National Forest | E44: =B43*10*365/325851 -> 44.178198 | F44: acre-feet/year | H44: Tao: 10 gallon per day per cattle
...

Sheet Freeport
A5: Freeport-McMoRan
A7: Diversion & Consumptive Use Accounting
B10: Freeport McMoRan
B11: Units: Acre-Feet
A12: Tyrone Wells diversion under 02260 | B12: 3981.74 | E12: 1
A13: Tyrone diversion under GSF-85 | B13: 600.69 | E13: 1
A14: Diversion from Evans Reservoir to Mine | B14: 0.06 | E14: 1
A15: Evaporation from Bill Evans Reservoir2 | B15: 63.86 | E15: 1
A16: Diversion for T-irrigation | B16: 3000.1 | E16: 1
A17: Consumptive Use for T-irrigation | B17: 1665.48 | E17: 1
A18: T-13/USFS diversion | B18: 8.52 | E18: 1
A19: Seepage credit from Bill Evans Dam | B19: 36.65 | E19: 1
A21: Total Diversion | B21: =+B12+B16+B18 -> 6990.36
A22: Total Consumptive Use | B22: =+B12+B14+B15+B17+B18-B19 -> 5683.01
A24: 1 Freeport-McMoRan provided data
A25: 2 The first 205.28 af of Evans Reservoir evap is assigned to NM Game & Fish

Sheet Diversions
A1: GILA – SAN FRANCISCO & SAN SIMON BASIN DIVERSIONS
C3: Units: Acre-Feet
C4: Measured | D4: Estimated | E4: Dom & Mun | F4: Total
B5: Measuring | C5: Irrigation | D5: Irrigation | E5: Com & Inds
A6: Area | B6: Device | C6: Diversions | D6: Diversions * | E6: Diversions
A8: Luna | B8: Digital | C8: =luna!E24+luna!K24+luna!Q24+luna!W24+luna!AC24+luna!AI24 -> 1176.2474 | F8: =SUM(C8:E8) -> 1176.2474
B9: Totalizer | E9: ='stock-dom-com-ind-evap'!C57 -> 10.47 | F9: =SUM(C9:E9) -> 10.47
B10: Estimated | D10: =M65 -> 264.9978 | F10: =SUM(C10:E10) -> 264.9978
B11: Total | F11: =SUM(F8:F10) -> 1451.7152
A12: * Estimated for non-metered ditches
A13: Apache-Aragon | B13: Digital | C13: =apachearagon!E24 -> 0 | F13: =SUM(C13:E13) -> 0
B14: Totalizer | E14: ='stock-dom-com-ind-evap'!C58 -> 4.38 | F14: =SUM(C14:E14) -> 4.38
B15: Estimated | D15: =M66 -> 59.803244 | F15: =SUM(C15:E15) -> 59.803244
B16: Total | F16: =SUM(F13:F15) -> 64.183244
A17: * Estimated for non-metered ditches
A18: Reserve | B18: Digital | C18: =reserve!E24+reserve!K24+reserve!Q24+reserve!W24+reserve!AC24+reserve!AI24+reserve!AO24 -> 3788.6143 | F18: =SUM(C18:E18) -> 3788.6143
B19: Totalizer | E19: ='stock-dom-com-ind-evap'!C59 -> 65.5 | F19: =SUM(C19:E19) -> 65.5
B20: Estimated | D20: =M67 -> 248.06519 | F20: =SUM(C20:E20) -> 248.06519
B21: Total | F21: =SUM(F18:F20) -> 4102.1795
A22: * Estimated for non-metered ditches
A23: Glenwood | B23: Digital | C23: =+glenwood!K24+glenwood!Q24+glenwood!W24+glenwood!AC24+glenwood!AI24 -> 6998.0458 | F23: =SUM(C23:E23) -> 6998.0458
B24: Totalizer | C24: =glenwood!AI32 -> 116.58 | E24: ='stock-dom-com-ind-evap'!C60 -> 50.25 | F24: =SUM(C24:E24) -> 166.83
B25: Estimated | D25: =M68 -> 1039.1686 | F25: =SUM(C25:E25) -> 1039.1686
B26: Total | F26: =SUM(F23:F25) -> 8204.0444
A27: * Estimated for non-metered ditches
A28: Total San Francisco Basin | F28: =F26+F21+F16+F11 -> 13822.122
A30: Cliff – Gila | B30: Digital | C30: =cliffgila!E24+cliffgila!K24+cliffgila!Q24+cliffgila!AC24+cliffgila!AI24+cliffgila!AO24 -> 27236.215 | F30: =SUM(C30:E30) -> 27236.215
B31: Totalizer | C31: =cliffgila!V49 -> 262.46 | E31: ='stock-dom-com-ind-evap'!C64 -> 7726.85 | F31: =SUM(C31:E31) -> 7989.31
B32: Estimated | D32: =M69 -> 3196.9017 | F32: =SUM(C32:E32) -> 3196.9017
B33: Total | F33: =SUM(F30:F32) -> 38422.426
A34: * Estimated for non-metered ditches
A35: Upper Gila | B35: Digital | C35: =uppergila!E24 -> 1324.3148 | F35: =SUM(C35:E35) -> 1324.3148
B36: Totalizer | E36: ='stock-dom-com-ind-evap'!C63 -> 127.43 | F36: =SUM(C36:E36) -> 127.43
B37: Estimated | D37: =M70 -> 291.07451 | F37: =SUM(C37:E37) -> 291.07451
B38: Total | F38: =SUM(F35:F37) -> 1742.8193
A39: * Estimated for non-metered ditches
A40: Redrock | B40: Digital | C40: =redrock!E24 -> 758.69066 | F40: =SUM(C40:E40) -> 758.69066
B41: Totalizer | C41: =redrock!W42 -> 2.27 | E41: ='stock-dom-com-ind-evap'!C65 -> 9.99 | F41: =SUM(C41:E41) -> 12.26
B42: Estimated | D42: =M71 -> 80.442183 | F42: =SUM(C42:E42) -> 80.442183
B43: Total | F43: =SUM(F40:F42) -> 851.39285
...

Sheet luna
A1: LUNA | B1: Crop acres diversion required for CU = crop acres * CIR / e; Reservoir acres diversion required for CU = reservoir acres * ( (monthly pan evap * 0.8) - precip) / e
A3: "e" = efficiency diversion to consumptive use= | D3: 0.30 | E3: Farm efficiency (40%)a multiplied by canal efficiency (75%)b = 30%
A4: a Gila River Hydrographic Survey Report Volume 5; b 1970 Arizona v. California Report backup computations
A5: Metered Diversions -- Crop Acres and Reservoir Acres
E6: Northside Luna Ditch | K6: William S. Laney Ditch | Q6: A. Laney Ditch | W6: Leslie Laney Ditch | AC6: Adair Luna Ditch
F7: 1.22 | G7: reservoir acres | L7: 1.25 | M7: reservoir acres | R7: 0 | S7: reservoir acres | X7: 0.06 | Y7: reservoir acres | AD7: 0 | AE7: reservoir acres
F8: 0 | G8: pre-plant acres | L8: 0 | M8: pre-plant acres | R8: 0 | S8: pre-plant acres | X8: 0 | Y8: pre-plant acres | AD8: 0 | AE8: pre-plant acres
F9: 77 | G9: crop acres | L9: 38.58 | M9: crop acres | R9: 14.44 | S9: crop acres | X9: 0 | Y9: crop acres | AD9: 12.23 | AE9: crop acres
F10: =SUM(F7:F9) -> 78.22 | G10: total acres | L10: =SUM(L7:L9) -> 39.83 | M10: total acres | R10: =SUM(R7:R9) -> 14.44 | S10: total acres | X10: =SUM(X7:X9) -> 0.06 | Y10: total acres | AD10: =SUM(AD7:AD9) -> 12.23 | AE10: total acres
A11: MONTH | B11: CIR (ft)/e | C11: Average Area Monthly Pan *(0.8) Evaporation (ft) | D11: Precipitation (ft) | E11: Diverted | F11: Reservoir Evap. minus Precip. (ac-ft) | G11: Reservoir Acres Diversion required for CU | H11: Crop Acres Diversion required for CU | I11: Total Diversion required for CU | J11: Total Short to Required Diversion | K11: Diverted | L11: Reservoir Evap. minus Precip. (ac-ft) | M11: Reservoir Acres Diversion required for CU | N11: Crop Acres Diversion required for CU | O11: Total Diversion required for CU | P11: Total Short to Required Diversion | Q11: Diverted | R11: Reservoir Evap. minus Precip. (ac-ft) | S11: Reservoir Acres Diversion required for CU | T11: Crop Acres Diversion required for CU | U11: Total Diversion required for CU | V11: Total Short to Required Diversion | W11: Diverted | X11: Reservoir Evap. minus Precip. (ac-ft) | Y11: Reservoir Acres Diversion required for CU | Z11: Crop Acres Diversion required for CU | AA11: Total Diversion required for CU | AB11: Total Short to Required Diversion | AC11: Diverted | AD11: Reservoir Evap. minus Precip. (ac-ft) | AE11: Reservoir Acres Diversion required for CU | AF11: Crop Acres Diversion required for CU | AG11: Total Diversion required for CU | AH11: Total Short to Required Diversion
A12: January | B12: =F46/$D$3 -> 0 | C12: =1.49/12 -> 0.12416667 | D12: 0.11333333 | E12: 0 | F12: =$F$7*(IF($C12-$D12<0,0,ABS($C12-$D12))) -> 0.013216667 | G12: =F12/$D$3 -> 0.044055556 | H12: =F$9*$B12 -> 0 | I12: =G12+H12 -> 0.044055556 | J12: 0 | K12: 0 | L12: =$L$7*(IF($C12-$D12<0,0,ABS($C12-$D12))) -> 0.013541667 | M12: =L12/$D$3 -> 0.045138889 | N12: =L$9*$B12 -> 0 | O12: =M12+N12 -> 0.045138889 | P12: 0 | Q12: 0 | R12: =R$7*(IF($C12-$D12<0,0,ABS($C12-$D12))) -> 0 | S12: =R12/$D$3 -> 0 | T12: =R$9*$B12 -> 0 | U12: =S12+T12 -> 0 | V12: =IF(Q12-U12>0,0,ABS(Q12-U12)) -> 0 | W12: 0 | X12: =$X$7*(IF($C12-$D12<0,0,ABS($C12-$D12))) -> 0.00065 | Y12: =X12/$D$3 -> 0.0021666667 | Z12: =X$9*$B12 -> 0 | AA12: =Y12+Z12 -> 0.0021666667 | AB12: 0 | AC12: 0 | AD12: =$AD$7*(IF($C12-$D12<0,0,ABS($C12-$D12))) -> 0 | AE12: =AD12/$D$3 -> 0 | AF12: =AD$9*$B12 -> 0 | AG12: =AE12+AF12 -> 0 | AH12: =IF(AC12-AG12>0,0,ABS(AC12-AG12)) -> 0
A13: February | B13: =G46/$D$3 -> 0 | C13: =1.97/12 -> 0.16416667 | D13: 0.11916667 | E13: 0 | F13: =$F$7*(IF($C13-$D13<0,0,ABS($C13-$D13))) -> 0.0549 | G13: =F13/$D$3 -> 0.183 | H13: =F$9*$B13 -> 0 | I13: =G13+H13 -> 0.183 | J13: 0 | K13: 0 | L13: =$L$7*(IF($C13-$D13<0,0,ABS($C13-$D13))) -> 0.05625 | M13: =L13/$D$3 -> 0.1875 | N13: =L$9*$B13 -> 0 | O13: =M13+N13 -> 0.1875 | P13: 0 | Q13: 0 | R13: =R$7*(IF($C13-$D13<0,0,ABS($C13-$D13))) -> 0 | S13: =R13/$D$3 -> 0 | T13: =R$9*$B13 -> 0 | U13: =S13+T13 -> 0 | V13: =IF(Q13-U13>0,0,ABS(Q13-U13)) -> 0 | W13: 0 | X13: =$X$7*(IF($C13-$D13<0,0,ABS($C13-$D13))) -> 0.0027 | Y13: =X13/$D$3 -> 0.009 | Z13: =X$9*$B13 -> 0 | AA13: =Y13+Z13 -> 0.009 | AB13: 0 | AC13: 0 | AD13: =$AD$7*(IF($C13-$D13<0,0,ABS($C13-$D13))) -> 0 | AE13: =AD13/$D$3 -> 0 | AF13: =AD$9*$B13 -> 0 | AG13: =AE13+AF13 -> 0 | AH13: =IF(AC13-AG13>0,0,ABS(AC13-AG13)) -> 0
A14: March | B14: =H46/$D$3 -> 0 | C14: =4.13/12 -> 0.34416667 | D14: 0.18583333 | E14: 5.2165261 | F14: =$F$7*(IF($C14-$D14<0,0,ABS($C14-$D14))) -> 0.19316667 | G14: =F14/$D$3 -> 0.64388889 | H14: =F$9*$B14 -> 0 | I14: =G14+H14 -> 0.64388889 | J14: =IF(E14-I14>0,0,ABS(E14-I14)) -> 0 | K14: 34.43899 | L14: =$L$7*(IF($C14-$D14<0,0,ABS($C14-$D14))) -> 0.19791667 | M14: =L14/$D$3 -> 0.65972222 | N14: =L$9*$B14 -> 0 | O14: =M14+N14 -> 0.65972222 | P14: =IF(K14-O14>0,0,ABS(K14-O14)) -> 0 | Q14: 0 | R14: 36.437914 | S14: 47.197363 | T14: 50.228568 | U14: 32.553598 | V14: 0 | W14: 43.358654 | X14: 0 | Y14: 0 | Z14: =X$9*$B14 -> 0 | AA14: =Y14+Z14 -> 0 | AB14: =IF(W14-AA14>0,0,ABS(W14-AA14)) -> 0 | AC14: 0 | AD14: =$AD$7*(IF($C14-$D14<0,0,ABS($C14-$D14))) -> 0 | AE14: =AD14/$D$3 -> 0 | AF14: =AD$9*$B14 -> 0 | AG14: =AE14+AF14 -> 0 | AH14: =IF(AC14-AG14>0,0,ABS(AC14-AG14)) -> 0
A15: April | B15: =I46/$D$3 -> 0.14971773 | C15: =5.38/12 -> 0.44833333 | D15: 0.040833333 | E15: 16.384123 | F15: =$F$7*(IF($C15-$D15<0,0,ABS($C15-$D15))) -> 0.49715 | G15: =F15/$D$3 -> 1.6571667 | H15: =F$9*$B15 -> 11.528265 | I15: =G15+H15 -> 13.185432 | J15: =IF(E15-I15>0,0,ABS(E15-I15)) -> 0 | K15: 67.273352 | L15: =$L$7*(IF($C15-$D15<0,0,ABS($C15-$D15))) -> 0.509375 | M15: =L15/$D$3 -> 1.6979167 | N15: =L$9*$B15 -> 5.7761101 | O15: =M15+N15 -> 7.4740268 | P15: =IF(K15-O15>0,0,ABS(K15-O15)) -> 0 | Q15: 27.059613 | R15: =R$7*(IF($C15-$D15<0,0,ABS($C15-$D15))) -> 0 | S15: =R15/$D$3 -> 0 | T15: =R$9*$B15 -> 2.161924 | U15: =S15+T15 -> 2.161924 | V15: =IF(Q15-U15>0,0,ABS(Q15-U15)) -> 0 | W15: 32.054859 | X15: =$X$7*(IF($C15-$D15<0,0,ABS($C15-$D15))) -> 0.02445 | Y15: =X15/$D$3 -> 0.0815 | Z15: =X$9*$B15 -> 0 | AA15: =Y15+Z15 -> 0.0815 | AB15: =IF(W15-AA15>0,0,ABS(W15-AA15)) -> 0 | AC15: 2.5999366 | AD15: =$AD$7*(IF($C15-$D15<0,0,ABS($C15-$D15))) -> 0 | AE15: =AD15/$D$3 -> 0 | AF15: =AD$9*$B15 -> 1.8310479 | AG15: =AE15+AF15 -> 1.8310479 | AH15: =IF(AC15-AG15>0,0,ABS(AC15-AG15)) -> 0
A16: May | B16: =J46/$D$3 -> 0.69511804 | C16: =6.19/12 -> 0.51583333 | D16: 0.0041666667 | E16: 2.6088622 | F16: =$F$7*(IF($C16-$D16<0,0,ABS($C16-$D16))) -> 0.62423333 | G16: =F16/$D$3 -> 2.0807778 | H16: =F$9*$B16 -> 53.524089 | I16: =G16+H16 -> 55.604867 | J16: =IF(E16-I16>0,0,ABS(E16-I16)) -> 52.996005 | K16: 91.061108 | L16: =$L$7*(IF($C16-$D16<0,0,ABS($C16-$D16))) -> 0.63958333 | M16: =L16/$D$3 -> 2.1319444 | N16: =L$9*$B16 -> 26.817654 | O16: =M16+N16 -> 28.949598 | P16: =IF(K16-O16>0,0,ABS(K16-O16)) -> 0 | Q16: 42.180473 | R16: =R$7*(IF($C16-$D16<0,0,ABS($C16-$D16))) -> 0 | S16: =R16/$D$3 -> 0 | T16: =R$9*$B16 -> 10.037504 | U16: =S16+T16 -> 10.037504 | V16: =IF(Q16-U16>0,0,ABS(Q16-U16)) -> 0 | W16: 0 | X16: =$X$7*(IF($C16-$D16<0,0,ABS($C16-$D16))) -> 0.0307 | Y16: =X16/$D$3 -> 0.10233333 | Z16: =X$9*$B16 -> 0 | AA16: =Y16+Z16 -> 0.10233333 | AB16: =IF(W16-AA16>0,0,ABS(W16-AA16)) -> 0.10233333 | AC16: 0 | AD16: =$AD$7*(IF($C16-$D16<0,0,ABS($C16-$D16))) -> 0 | AE16: =AD16/$D$3 -> 0 | AF16: =AD$9*$B16 -> 8.5012936 | AG16: =AE16+AF16 -> 8.5012936 | AH16: =IF(AC16-AG16>0,0,ABS(AC16-AG16)) -> 8.5012936
A17: June | B17: =K46/$D$3 -> 1.1710065 | C17: =7.39/12 -> 0.61583333 | D17: 0.045833333 | E17: 109.21554 | F17: =$F$7*(IF($C17-$D17<0,0,ABS($C17-$D17))) -> 0.6954 | G17: =F17/$D$3 -> 2.318 | H17: =F$9*$B17 -> 90.167504 | I17: =G17+H17 -> 92.485504 | J17: =IF(E17-I17>0,0,ABS(E17-I17)) -> 0 | K17: 70.448887 | L17: =$L$7*(IF($C17-$D17<0,0,ABS($C17-$D17))) -> 0.7125 | M17: =L17/$D$3 -> 2.375 | N17: =L$9*$B17 -> 45.177432 | O17: =M17+N17 -> 47.552432 | P17: =IF(K17-O17>0,0,ABS(K17-O17)) -> 0 | Q17: 31.856512 | R17: =R$7*(IF($C17-$D17<0,0,ABS($C17-$D17))) -> 0 | S17: =R17/$D$3 -> 0 | T17: =R$9*$B17 -> 16.909334 | U17: =S17+T17 -> 16.909334 | V17: =IF(Q17-U17>0,0,ABS(Q17-U17)) -> 0 | W17: 0 | X17: =$X$7*(IF($C17-$D17<0,0,ABS($C17-$D17))) -> 0.0342 | Y17: =X17/$D$3 -> 0.114 | Z17: =X$9*$B17 -> 0 | AA17: =Y17+Z17 -> 0.114 | AB17: =IF(W17-AA17>0,0,ABS(W17-AA17)) -> 0.114 | AC17: 0 | AD17: =$AD$7*(IF($C17-$D17<0,0,ABS($C17-$D17))) -> 0 | AE17: =AD17/$D$3 -> 0 | AF17: =AD$9*$B17 -> 14.32141 | AG17: =AE17+AF17 -> 14.32141 | AH17: =IF(AC17-AG17>0,0,ABS(AC17-AG17)) -> 14.32141
A18: July | B18: =L46/$D$3 -> 0.6229327 | C18: =5.66/12 -> 0.47166667 | D18: 0.3425 | E18: 19.840509 | F18: =$F$7*(IF($C18-$D18<0,0,ABS($C18-$D18))) -> 0.15758333 | G18: =F18/$D$3 -> 0.52527778 | H18: =F$9*$B18 -> 47.965818 | I18: =G18+H18 -> 48.491096 | J18: =IF(E18-I18>0,0,ABS(E18-I18)) -> 28.650587 | K18: 65.50608 | L18: =$L$7*(IF($C18-$D18<0,0,ABS($C18-$D18))) -> 0.16145833 | M18: =L18/$D$3 -> 0.53819444 | N18: =L$9*$B18 -> 24.032744 | O18: =M18+N18 -> 24.570938 | P18: =IF(K18-O18>0,0,ABS(K18-O18)) -> 0 | Q18: 39.957003 | R18: =R$7*(IF($C18-$D18<0,0,ABS($C18-$D18))) -> 0 | S18: =R18/$D$3 -> 0 | T18: =R$9*$B18 -> 8.9951483 | U18: =S18+T18 -> 8.9951483 | V18: =IF(Q18-U18>0,0,ABS(Q18-U18)) -> 0 | W18: 0 | X18: =$X$7*(IF($C18-$D18<0,0,ABS($C18-$D18))) -> 0.00775 | Y18: =X18/$D$3 -> 0.025833333 | Z18: =X$9*$B18 -> 0 | AA18: =Y18+Z18 -> 0.025833333 | AB18: =IF(W18-AA18>0,0,ABS(W18-AA18)) -> 0.025833333 | AC18: 0 | AD18: =$AD$7*(IF($C18-$D18<0,0,ABS($C18-$D18))) -> 0 | AE18: =AD18/$D$3 -> 0 | AF18: =AD$9*$B18 -> 7.618467 | AG18: =AE18+AF18 -> 7.618467 | AH18: =IF(AC18-AG18>0,0,ABS(AC18-AG18)) -> 7.618467
A19: August | B19: =M46/$D$3 -> 0.79136515 | C19: =4.7/12 -> 0.39166667 | D19: 0.19833333 | E19: 14.657843 | F19: =$F$7*(IF($C19-$D19<0,0,ABS($C19-$D19))) -> 0.23586667 | G19: =F19/$D$3 -> 0.78622222 | H19: =F$9*$B19 -> 60.935117 | I19: =G19+H19 -> 61.721339 | J19: =IF(E19-I19>0,0,ABS(E19-I19)) -> 47.063496 | K19: 63.106082 | L19: =$L$7*(IF($C19-$D19<0,0,ABS($C19-$D19))) -> 0.24166667 | M19: =L19/$D$3 -> 0.80555556 | N19: =L$9*$B19 -> 30.530868 | O19: =M19+N19 -> 31.336423 | P19: =IF(K19-O19>0,0,ABS(K19-O19)) -> 0 | Q19: 39.550392 | R19: =R$7*(IF($C19-$D19<0,0,ABS($C19-$D19))) -> 0 | S19: =R19/$D$3 -> 0 | T19: =R$9*$B19 -> 11.427313 | U19: =S19+T19 -> 11.427313 | V19: =IF(Q19-U19>0,0,ABS(Q19-U19)) -> 0 | W19: 0 | X19: =$X$7*(IF($C19-$D19<0,0,ABS($C19-$D19))) -> 0.0116 | Y19: =X19/$D$3 -> 0.038666667 | Z19: =X$9*$B19 -> 0 | AA19: =Y19+Z19 -> 0.038666667 | AB19: =IF(W19-AA19>0,0,ABS(W19-AA19)) -> 0.038666667 | AC19: 0 | AD19: =$AD$7*(IF($C19-$D19<0,0,ABS($C19-$D19))) -> 0 | AE19: =AD19/$D$3 -> 0 | AF19: =AD$9*$B19 -> 9.6783958 | AG19: =AE19+AF19 -> 9.6783958 | AH19: =IF(AC19-AG19>0,0,ABS(AC19-AG19)) -> 9.6783958
A20: September | B20: =N46/$D$3 -> 0.78067103 | C20: =4.18/12 -> 0.34833333 | D20: 0.065833333 | E20: 60.989813 | F20: =$F$7*(IF($C20-$D20<0,0,ABS($C20-$D20))) -> 0.34465 | G20: =F20/$D$3 -> 1.1488333 | H20: =F$9*$B20 -> 60.111669 | I20: =G20+H20 -> 61.260503 | J20: =IF(E20-I20>0,0,ABS(E20-I20)) -> 0.27068909 | K20: 72.595002 | L20: =$L$7*(IF($C20-$D20<0,0,ABS($C20-$D20))) -> 0.353125 | M20: =L20/$D$3 -> 1.1770833 | N20: =L$9*$B20 -> 30.118288 | O20: =M20+N20 -> 31.295372 | P20: =IF(K20-O20>0,0,ABS(K20-O20)) -> 0 | Q20: 0 | R20: =R$7*(IF($C20-$D20<0,0,ABS($C20-$D20))) -> 0 | S20: =R20/$D$3 -> 0 | T20: =R$9*$B20 -> 11.27289 | U20: =S20+T20 -> 11.27289 | V20: =IF(Q20-U20>0,0,ABS(Q20-U20)) -> 11.27289 | W20: 0 | X20: =$X$7*(IF($C20-$D20<0,0,ABS($C20-$D20))) -> 0.01695 | Y20: =X20/$D$3 -> 0.0565 | Z20: =X$9*$B20 -> 0 | AA20: =Y20+Z20 -> 0.0565 | AB20: =IF(W20-AA20>0,0,ABS(W20-AA20)) -> 0.0565 | AC20: 0 | AD20: =$AD$7*(IF($C20-$D20<0,0,ABS($C20-$D20))) -> 0 | AE20: =AD20/$D$3 -> 0 | AF20: =AD$9*$B20 -> 9.5476067 | AG20: =AE20+AF20 -> 9.5476067 | AH20: =IF(AC20-AG20>0,0,ABS(AC20-AG20)) -> 9.5476067
A21: October | B21: =O46/$D$3 -> 0.41974435 | C21: =3.5/12 -> 0.29166667 | D21: 0.049166667 | E21: 26.711768 | F21: =$F$7*(IF($C21-$D21<0,0,ABS($C21-$D21))) -> 0.29585 | G21: =F21/$D$3 -> 0.98616667 | H21: =F$9*$B21 -> 32.320315 | I21: =G21+H21 -> 33.306482 | J21: =IF(E21-I21>0,0,ABS(E21-I21)) -> 6.5947137 | K21: 99.994657 | L21: =$L$7*(IF($C21-$D21<0,0,ABS($C21-$D21))) -> 0.303125 | M21: =L21/$D$3 -> 1.0104167 | N21: =L$9*$B21 -> 16.193737 | O21: =M21+N21 -> 17.204154 | P21: =IF(K21-O21>0,0,ABS(K21-O21)) -> 0 | Q21: 0 | R21: =R$7*(IF($C21-$D21<0,0,ABS($C21-$D21))) -> 0 | S21: =R21/$D$3 -> 0 | T21: =R$9*$B21 -> 6.0611085 | U21: =S21+T21 -> 6.0611085 | V21: =IF(Q21-U21>0,0,ABS(Q21-U21)) -> 6.0611085 | W21: 0 | X21: =$X$7*(IF($C21-$D21<0,0,ABS($C21-$D21))) -> 0.01455 | Y21: =X21/$D$3 -> 0.0485 | Z21: =X$9*$B21 -> 0 | AA21: =Y21+Z21 -> 0.0485 | AB21: =IF(W21-AA21>0,0,ABS(W21-AA21)) -> 0.0485 | AC21: 0 | AD21: =$AD$7*(IF($C21-$D21<0,0,ABS($C21-$D21))) -> 0 | AE21: =AD21/$D$3 -> 0 | AF21: =AD$9*$B21 -> 5.1334735 | AG21: =AE21+AF21 -> 5.1334735 | AH21: =IF(AC21-AG21>0,0,ABS(AC21-AG21)) -> 5.1334735
A22: November | B22: =P46/$D$3 -> 0 | C22: =1.82/12 -> 0.15166667 | D22: 0.060833333 | E22: 20.80065 | F22: =$F$7*(IF($C22-$D22<0,0,ABS($C22-$D22))) -> 0.11081667 | G22: =F22/$D$3 -> 0.36938889 | H22: =F$9*$B22 -> 0 | I22: =G22+H22 -> 0.36938889 | J22: =IF(E22-I22>0,0,ABS(E22-I22)) -> 0 | K22: 73.804919 | L22: =$L$7*(IF($C22-$D22<0,0,ABS($C22-$D22))) -> 0.11354167 | M22: =L22/$D$3 -> 0.37847222 | N22: =L$9*$B22 -> 0 | O22: =M22+N22 -> 0.37847222 | P22: =IF(K22-O22>0,0,ABS(K22-O22)) -> 0 | Q22: 0 | R22: =R$7*(IF($C22-$D22<0,0,ABS($C22-$D22))) -> 0 | S22: =R22/$D$3 -> 0 | T22: =R$9*$B22 -> 0 | U22: =S22+T22 -> 0 | V22: =IF(Q22-U22>0,0,ABS(Q22-U22)) -> 0 | W22: 0 | X22: =$X$7*(IF($C22-$D22<0,0,ABS($C22-$D22))) -> 0.00545 | Y22: =X22/$D$3 -> 0.018166667 | Z22: =X$9*$B22 -> 0 | AA22: =Y22+Z22 -> 0.018166667 | AB22: =IF(W22-AA22>0,0,ABS(W22-AA22)) -> 0.018166667 | AC22: 0 | AD22: =$AD$7*(IF($C22-$D22<0,0,ABS($C22-$D22))) -> 0 | AE22: =AD22/$D$3 -> 0 | AF22: =AD$9*$B22 -> 0 | AG22: =AE22+AF22 -> 0 | AH22: =IF(AC22-AG22>0,0,ABS(AC22-AG22)) -> 0
A23: December | B23: =Q46/$D$3 -> 0 | C23: =1.49/12 -> 0.12416667 | D23: 0 | E23: 0.4561981 | F23: =$F$7*(IF($C23-$D23<0,0,ABS($C23-$D23))) -> 0.15148333 | G23: =F23/$D$3 -> 0.50494444 | H23: =F$9*$B23 -> 0 | I23: =G23+H23 -> 0.50494444 | J23: 0 | K23: 2.5190069 | L23: =$L$7*(IF($C23-$D23<0,0,ABS($C23-$D23))) -> 0.15520833 | M23: =L23/$D$3 -> 0.51736111 | N23: =L$9*$B23 -> 0 | O23: =M23+N23 -> 0.51736111 | P23: 0 | Q23: 0 | R23: =R$7*(IF($C23-$D23<0,0,ABS($C23-$D23))) -> 0 | S23: =R23/$D$3 -> 0 | T23: =R$9*$B23 -> 0 | U23: =S23+T23 -> 0 | V23: =IF(Q23-U23>0,0,ABS(Q23-U23)) -> 0 | W23: 0 | X23: =$X$7*(IF($C23-$D23<0,0,ABS($C23-$D23))) -> 0.00745 | Y23: =X23/$D$3 -> 0.024833333 | Z23: =X$9*$B23 -> 0 | AA23: =Y23+Z23 -> 0.024833333 | AB23: 0 | AC23: 0 | AD23: =$AD$7*(IF($C23-$D23<0,0,ABS($C23-$D23))) -> 0 | AE23: =AD23/$D$3 -> 0 | AF23: =AD$9*$B23 -> 0 | AG23: =AE23+AF23 -> 0 | AH23: =IF(AC23-AG23>0,0,ABS(AC23-AG23)) -> 0
A24: TOTALS | B24: =SUM(B12:B23) -> 4.6305556 | C24: =SUM(C12:C23) -> 3.9916667 | D24: =SUM(D12:D23) -> 1.2258333 | E24: =SUM(E12:E23) -> 276.88184 | F24: =SUM(F12:F23) -> 3.3743167 | G24: =SUM(G12:G23) -> 11.247722 | H24: =SUM(H12:H23) -> 356.55278 | I24: =SUM(I12:I23) -> 367.8005 | ... AH24: =SUM(AH12:AH23) -> 54.800647
A25: Daily diversion records were used to assess whether a shortage condition truly existed in months for which only partial daily data were available, e.g. spring and fall at data logger startup/shutdown. | T25: Estimated from partial data.
A26: Reservoirs with small amounts of evaporation exceeding precipitation during winter were assumed to have no shortage in those months, despite the lack of diversion data for that period.
A27: Consumptive Use | F27: Metered | L27: Non-Metered | S27: Total
C28: CIR full season (ft) | D28: CIR Jul-Nov (ft) | F28: Acres Subject to Shortage | G28: CU Demand/Full Supply | H28: Diversion Required for CU * | I28: Diversion Shortage to CU * | J28: Fractional Shortage to Diversion Required | K28: Shortage to CU | M28: Acres Subject to Shortage | N28: CU Demand/Full Supply | O28: Shortage to CU | P28: Acres NOT Subject to Shortage** | Q28: CU Demand/Full Supply | S28: Total Acres | T28: Total CU Demand/Full Supply | U28: Total Shortage to CU Demand | V28: Tota Crop & Pond CU | W28: Incidental Losses | X28: Total Irrigated CU
A29: Full Season | C29: =B24*$D$3 -> 1.3891667 | F29: =($F9+$L9+$R9+$X9+$AD9+$AJ9)-F30 -> 142.25 | G29: =F29*$C29 -> 197.60896 | H29: =H24+N24+T24+Z24+AF24+AL24 -> 708.9251 | K29: =G29*J32 -> 52.764144 | M29: 15.01 | N29: =M29*$C29 -> 20.851392 | O29: =J32*N29 -> 5.5675909 | P29: 26.1 | Q29: =P29*$C29 -> 36.25725 | S29: =F29+M29+P29 -> 183.36 | T29: =G29+N29+Q29 -> 254.7176 | U29: =O29+K29 -> 58.331735 | V29: =T29-U29 -> 196.38586
A30: Pre-Plant | M30: 0 | P30: 0
A31: Reservoir | F31: =F7+L7+R7+X7+AD7+AJ7 -> 2.53 | G31: =F31*($C24-$D24) -> 6.9975583 | H31: =G24+M24+S24+Y24+AE24+AK24 -> 70.490891 | K31: =G31*J32 -> 1.8684385 | M31: 21.92 | N31: =M31*($C24-$D24) -> 60.627067 | O31: =J32*N31 -> 16.18821 | P31: 0 | Q31: =P31*($C24-$D24) -> 0 | S31: =F31+M31+P31 -> 24.45 | T31: =G31+N31+Q31 -> 67.624625 | U31: =O31+K31 -> 18.056648 | V31: =T31-U31 -> 49.567977
A32: Total | F32: =SUM(F29:F31) -> 144.78 | G32: =SUM(G29:G31) -> 204.60652 | H32: =SUM(H29:H31) -> 779.41599 | I32: =J24+P24+V24+AB24+AH24+AN24+AT24 -> 208.11414 | J32: =I32/H32 -> 0.26701292 | K32: =J32*G32 -> 54.632583 | M32: =SUM(M29:M31) -> 36.93 | N32: =SUM(N29:N31) -> 81.478458 | O32: =SUM(O29:O31) -> 21.755801 | P32: =SUM(P29:P31) -> 26.1 | Q32: =SUM(Q29:Q31) -> 36.25725 | S32: =SUM(S29:S31) -> 207.81 | T32: =SUM(T29:T31) -> 322.34223 | U32: =SUM(U29:U31) -> 76.388383 | V32: =SUM(V29:V31) -> 245.95384 | W32: =(V32-Q32)*0.1+(Q32*0.02) -> 21.694804 | X32: =W32+V32 -> 267.64865
A34: * Shortage based on measured surface water diversions; no groundwater supplement
A35: **Groundwater supplied
A36: MONTHLY CIR COMPUTED USING THE SCS MODIFIED BLANEY-CRIDDLE METHOD
F37: Jan | G37: Feb | H37: Mar | I37: Apr | J37: May | K37: Jun | L37: Jul | M37: Aug | N37: Sep | O37: Oct | P37: Nov | Q37: Dec | R37: Total
A39: Weighted CIR - in | F39: 0 | G39: 0 | H39: 0 | I39: 0.56 | J39: 2.6 | K39: 4.38 | L39: 2.33 | M39: 2.96 | N39: 2.92 | O39: 1.57 | P39: 0 | Q39: 0 | R39: =SUM(F39:Q39) -> 17.32
A40: Ratio to Annual Total | F40: =F39/$R39 -> 0 | G40: =G39/$R39 -> 0 | H40: =H39/$R39 -> 0 | I40: =I39/$R39 -> 0.032332564 | J40: =J39/$R39 -> 0.15011547 | K40: =K39/$R39 -> 0.25288684 | L40: =L39/$R39 -> 0.13452656 | M40: =M39/$R39 -> 0.17090069 | ... Q40: =Q39/$R39 -> 0 | R40: =SUM(F40:Q40) -> 1
A42: ORIGINAL BLANEY-CRIDDLE ANNUAL WCIR | F42: 16.67 | G42: inches DISTRIBUTED USING MODIFIED BLANEY-CRIDDLE MONTHLY DISTRIBUTION RATIOS
F43: Jan | G43: Feb | H43: Mar | I43: Apr | J43: May | K43: Jun | L43: Jul | M43: Aug | N43: Sep | O43: Oct | P43: Nov | Q43: Dec | R43: Total
A45: CIR (in) | F45: =F40*$F42 -> 0 | G45: =G40*$F42 -> 0 | H45: =H40*$F42 -> 0 | I45: =I40*$F42 -> 0.53898383 | J45: =J40*$F42 -> 2.5024249 | K45: =K40*$F42 -> 4.2156236 | L45: =L40*$F42 -> 2.2425577 | M45: =M40*$F42 -> 2.8489145 | ... Q45: =Q40*$F42 -> 0 | R45: =SUM(F45:Q45) -> 16.67
...

Sheet apachearagon
A1: APACHE - ARAGON | B1: Crop acres diversion required for CU = crop acres * CIR / e; Reservoir acres diversion required for CU = reservoir acres * ( (monthly pan evap * 0.8) - precip) / e
A3: "e" = efficiency diversion to consumptive use = | D3: 0.375 | E3: Farm efficiency (50%)a multiplied by canal efficiency (75%)b = 37.5%
A4: a Gila River Hydrographic Survey Report Volume 8; b 1970 Arizona v. California Report backup computations
A5: Metered Diversions -- Crop Acres and Reservoir Acres
E6: Tularosa-Cruzville Ditch
F7: 0 | G7: reservoir acres
F8: 0 | G8: pre-plant acres
F9: 17.89 | G9: crop acres
F10: =SUM(F7:F9) -> 17.89 | G10: total acres
A11: MONTH | B11: CIR (ft)/e | C11: Average Area Monthly Pan *(0.8) Evaporation (ft) | D11: Precipitation (ft) | E11: Diverted | F11: Reservoir Evap. minus Precip. (ac-ft) | G11: Reservoir Acres Diversion required for CU | H11: Crop Acres Diversion required for CU | I11: Total Diversion required for CU | J11: Total Short to Required Diversion
A12: January | B12: =F45/$D$3 -> 0 | C12: =1.64/12 -> 0.13666667 | D12: 0.10833333 | E12: 0 | F12: =$F$7*(IF($C12-$D12<0,0,ABS($C12-$D12))) -> 0 | G12: =F12/$D$3 -> 0 | H12: =F$9*$B12 -> 0 | I12: =G12+H12 -> 0 | J12: =IF(E12-I12>0,0,ABS(E12-I12)) -> 0 | M12: =2.48/12 -> 0.20666667 | N12: =M12*12 -> 2.48
A13: February | B13: =G45/$D$3 -> 0 | C13: =2.16/12 -> 0.18 | D13: 0.1075 | E13: 0 | F13: =$F$7*(IF($C13-$D13<0,0,ABS($C13-$D13))) -> 0 | G13: =F13/$D$3 -> 0 | H13: =F$9*$B13 -> 0 | I13: =G13+H13 -> 0 | J13: =IF(E13-I13>0,0,ABS(E13-I13)) -> 0 | M13: =3.28/12 -> 0.27333333 | N13: =M13*12 -> 3.28
A14: March | B14: =H45/$D$3 -> 0 | C14: =4.54/12 -> 0.37833333 | D14: 0.1925 | E14: 0 | F14: =$F$7*(IF($C14-$D14<0,0,ABS($C14-$D14))) -> 0 | G14: =F14/$D$3 -> 0 | H14: =F$9*$B14 -> 0 | I14: =G14+H14 -> 0 | J14: =IF(E14-I14>0,0,ABS(E14-I14)) -> 0 | M14: =6.88/12 -> 0.57333333 | N14: =M14*12 -> 6.88
A15: April | B15: =I45/$D$3 -> 0.22839313 | C15: =5.91/12 -> 0.4925 | D15: 0.028333333 | E15: 0 | F15: =$F$7*(IF($C15-$D15<0,0,ABS($C15-$D15))) -> 0 | G15: =F15/$D$3 -> 0 | H15: =F$9*$B15 -> 4.0859531 | I15: =G15+H15 -> 4.0859531 | J15: =IF(E15-I15>0,0,ABS(E15-I15)) -> 4.0859531 | M15: =8.96/12 -> 0.74666667 | N15: =M15*12 -> 8.96
A16: May | B16: =J45/$D$3 -> 0.58279626 | C16: =6.81/12 -> 0.5675 | D16: 0.0091666667 | E16: 0 | F16: =$F$7*(IF($C16-$D16<0,0,ABS($C16-$D16))) -> 0 | G16: =F16/$D$3 -> 0 | H16: =F$9*$B16 -> 10.426225 | I16: =G16+H16 -> 10.426225 | J16: =IF(E16-I16>0,0,ABS(E16-I16)) -> 10.426225 | M16: =10.32/12 -> 0.86 | N16: =M16*12 -> 10.32
A17: June | B17: =K45/$D$3 -> 0.89782127 | C17: =8.13/12 -> 0.6775 | D17: 0.07 | E17: 0 | F17: =$F$7*(IF($C17-$D17<0,0,ABS($C17-$D17))) -> 0 | G17: =F17/$D$3 -> 0 | H17: =F$9*$B17 -> 16.062022 | I17: =G17+H17 -> 16.062022 | J17: =IF(E17-I17>0,0,ABS(E17-I17)) -> 16.062022 | M17: =12.32/12 -> 1.0266667 | N17: =M17*12 -> 12.32
A18: July | B18: =L45/$D$3 -> 0.66155251 | C18: =6.23/12 -> 0.51916667 | D18: 0.25416667 | E18: 0 | F18: =$F$7*(IF($C18-$D18<0,0,ABS($C18-$D18))) -> 0 | G18: =F18/$D$3 -> 0 | H18: =F$9*$B18 -> 11.835174 | I18: =G18+H18 -> 11.835174 | J18: =IF(E18-I18>0,0,ABS(E18-I18)) -> 11.835174 | M18: =9.44/12 -> 0.78666667 | N18: =M18*12 -> 9.44
A19: August | B19: =M45/$D$3 -> 0.71471298 | C19: =5.17/12 -> 0.43083333 | D19: 0.1575 | E19: 0 | F19: =$F$7*(IF($C19-$D19<0,0,ABS($C19-$D19))) -> 0 | G19: =F19/$D$3 -> 0 | H19: =F$9*$B19 -> 12.786215 | I19: =G19+H19 -> 12.786215 | J19: =IF(E19-I19>0,0,ABS(E19-I19)) -> 12.786215 | M19: =7.84/12 -> 0.65333333 | N19: =M19*12 -> 7.84
A20: September | B20: =N45/$D$3 -> 0.61036095 | C20: =4.59/12 -> 0.3825 | D20: 0.045833333 | E20: 0 | F20: =$F$7*(IF($C20-$D20<0,0,ABS($C20-$D20))) -> 0 | G20: =F20/$D$3 -> 0 | H20: =F$9*$B20 -> 10.919357 | I20: =G20+H20 -> 10.919357 | J20: =IF(E20-I20>0,0,ABS(E20-I20)) -> 10.919357 | M20: =6.96/12 -> 0.58 | N20: =M20*12 -> 6.96
A21: October | B21: =O45/$D$3 -> 0.32486954 | C21: =3.85/12 -> 0.32083333 | D21: 0.053333333 | E21: 0 | F21: =$F$7*(IF($C21-$D21<0,0,ABS($C21-$D21))) -> 0 | G21: =F21/$D$3 -> 0 | H21: =F$9*$B21 -> 5.811916 | I21: =G21+H21 -> 5.811916 | J21: =IF(E21-I21>0,0,ABS(E21-I21)) -> 5.811916 | M21: =5.84/12 -> 0.48666667 | N21: =M21*12 -> 5.84
A22: November | B22: =P45/$D$3 -> 0.0039378126 | C22: =2.01/12 -> 0.1675 | D22: 0.05 | E22: 0 | F22: =$F$7*(IF($C22-$D22<0,0,ABS($C22-$D22))) -> 0 | G22: =F22/$D$3 -> 0 | H22: =F$9*$B22 -> 0.070447467 | I22: =G22+H22 -> 0.070447467 | J22: =IF(E22-I22>0,0,ABS(E22-I22)) -> 0.070447467 | M22: =3.04/12 -> 0.25333333 | N22: =M22*12 -> 3.04
A23: December | B23: =Q45/$D$3 -> 0 | C23: =1.64/12 -> 0.13666667 | D23: 0 | E23: 0 | F23: =$F$7*(IF($C23-$D23<0,0,ABS($C23-$D23))) -> 0 | G23: =F23/$D$3 -> 0 | H23: =F$9*$B23 -> 0 | I23: =G23+H23 -> 0 | J23: =IF(E23-I23>0,0,ABS(E23-I23)) -> 0 | M23: =2.48/12 -> 0.20666667 | N23: =M23*12 -> 2.48
A24: TOTALS | B24: =SUM(B12:B23) -> 4.0244444 | C24: =SUM(C12:C23) -> 4.39 | D24: =SUM(D12:D23) -> 1.0766667 | E24: =SUM(E12:E23) -> 0 | F24: =SUM(F12:F23) -> 0 | G24: =SUM(G12:G23) -> 0 | H24: =SUM(H12:H23) -> 71.997311 | I24: =SUM(I12:I23) -> 71.997311 | J24: =SUM(J12:J23) -> 71.997311
A25: Daily diversion records were used to assess whether a shortage condition truly existed in months for which only partial daily data were available, e.g. spring and fall at data logger startup/shutdown. | T25: Estimated from partial data.
A26: Consumptive Use | F26: Metered | L26: Non-Metered | S26: Total
C27: CIR full season (ft) | D27: CIR Jul-Nov (ft) | F27: Acres Subject to Shortage | G27: CU Demand/Full Supply | H27: Diversion Required for CU * | I27: Diversion Shortage to CU * | J27: Fractional Shortage to Diversion Required | K27: Shortage to CU | M27: Acres Subject to Shortage | N27: CU Demand/Full Supply | O27: Shortage to CU | P27: Acres NOT Subject to Shortage** | Q27: CU Demand/Full Supply | S27: Total Acres | T27: Total CU Demand/Full Supply | U27: Total Shortage to CU Demand | V27: Tota Crop & Pond CU | W27: Incidental Losses | X27: Total Irrigated CU
A28: Full Season | C28: =B24*D3 -> 1.5091667 | F28: =($F9+$L9+$R9+$X9+$AD9+$AJ9)-F29 -> 17.89 | G28: =F28*$C28 -> 26.998992 | H28: =H24+N24+T24+Z24+AF24+AL24 -> 71.997311 | K28: =G28*J31 -> 26.998992 | M28: 124.26 | N28: =M28*$C28 -> 187.52905 | O28: =J31*N28 -> 187.52905 | P28: 14.86 | Q28: =P28*$C28 -> 22.426217 | S28: =F28+M28+P28 -> 157.01 | T28: =G28+N28+Q28 -> 236.95426 | U28: =O28+K28 -> 214.52804 | V28: =T28-U28 -> 22.426217
A29: Pre-Plant | M29: 0 | P29: 0
A30: Reservoir | F30: =F7+L7+R7+X7+AD7+AJ7 -> 0 | G30: =F30*($C24-$D24) -> 0 | H30: =G24+M24+S24+Y24+AE24+AK24 -> 0 | K30: =G30*J31 -> 0 | M30: 5.06 | N30: =M30*($C24-$D24) -> 16.765467 | O30: =J31*N30 -> 16.765467 | P30: 0 | Q30: =P30*($C24-$D24) -> 0 | S30: =F30+M30+P30 -> 5.06 | T30: =G30+N30+Q30 -> 16.765467 | U30: =O30+K30 -> 16.765467 | V30: =T30-U30 -> 0
A31: Total | F31: =SUM(F28:F30) -> 17.89 | G31: =SUM(G28:G30) -> 26.998992 | H31: =SUM(H28:H30) -> 71.997311 | I31: =J24+AB24 -> 71.997311 | J31: =I31/H31 -> 1 | K31: =J31*G31 -> 26.998992 | M31: =SUM(M28:M30) -> 129.32 | N31: =SUM(N28:N30) -> 204.29452 | O31: =SUM(O28:O30) -> 204.29452 | P31: =SUM(P28:P30) -> 14.86 | Q31: =SUM(Q28:Q30) -> 22.426217 | S31: =SUM(S28:S30) -> 162.07 | T31: =SUM(T28:T30) -> 253.71973 | U31: =SUM(U28:U30) -> 231.29351 | V31: =SUM(V28:V30) -> 22.426217 | W31: =(V31-Q31)*0.1+(Q31*0.02) -> 0.44852433 | X31: =W31+V31 -> 22.874741
A33: * Shortage based on measured surface water diversions; no groundwater supplement
A34: ** Acreage is subject to shortage, but full supply assumed
A35: MONTHLY CIR COMPUTED USING THE SCS MODIFIED BLANEY-CRIDDLE METHOD
F36: Jan | G36: Feb | H36: Mar | I36: Apr | J36: May | K36: Jun | L36: Jul | M36: Aug | N36: Sep | O36: Oct | P36: Nov | Q36: Dec | R36: Total
A38: Weighted CIR - in | F38: 0 | G38: 0 | H38: 0 | I38: 1.16 | J38: 2.96 | K38: 4.56 | L38: 3.36 | M38: 3.63 | N38: 3.1 | O38: 1.65 | P38: 0.02 | Q38: 0 | R38: =SUM(F38:Q38) -> 20.44
A39: Ratio to Annual Total | F39: =F38/$R38 -> 0 | G39: =G38/$R38 -> 0 | H39: =H38/$R38 -> 0 | I39: =I38/$R38 -> 0.056751468 | J39: =J38/$R38 -> 0.14481409 | K39: =K38/$R38 -> 0.22309198 | L39: =L38/$R38 -> 0.16438356 | M39: =M38/$R38 -> 0.17759295 | ... Q39: =Q38/$R38 -> 0 | R39: =SUM(F39:Q39) -> 1
A41: ORIGINAL BLANEY-CRIDDLE ANNUAL WCIR | F41: 18.11 | G41: inches DISTRIBUTED USING MODIFIED BLANEY-CRIDDLE MONTHLY DISTRIBUTION RATIOS
F42: Jan | G42: Feb | H42: Mar | I42: Apr | J42: May | K42: Jun | L42: Jul | M42: Aug | N42: Sep | O42: Oct | P42: Nov | Q42: Dec | R42: Total
A44: CIR (in) | F44: =F39*$F41 -> 0 | G44: =G39*$F41 -> 0 | H44: =H39*$F41 -> 0 | I44: =I39*$F41 -> 1.0277691 | J44: =J39*$F41 -> 2.6225832 | K44: =K39*$F41 -> 4.0401957 | L44: =L39*$F41 -> 2.9769863 | M44: =M39*$F41 -> 3.2162084 | ... R44: =R39*$F41 -> 18.11
A45: CIR (ft) | F45: =F44/12 -> 0 | G45: =G44/12 -> 0 | H45: =H44/12 -> 0 | I45: =I44/12 -> 0.085647423 | J45: =J44/12 -> 0.2185486 | K45: =K44/12 -> 0.33668297 | L45: =L44/12 -> 0.24808219 | M45: =M44/12 -> 0.26801737 | ... Q45: =Q44/12 -> 0 | R45: =SUM(F45:Q45) -> 1.5091667
...

Sheet reserve
A1: RESERVE | B1: Crop acres diversion required for CU = crop acres * CIR / e; Reservoir acres diversion required for CU = reservoir acres * ( (monthly pan evap * 0.8) - precip) / e
A3: "e" = efficiency diversion to consumptive use = | D3: 0.375 | E3: Farm efficiency (50%)a multiplied by canal efficiency (75%)b = 37.5%
A4: a Gila River Hydrographic Survey Report Volume 5; b 1970 Arizona v. California Report backup computations
A5: Metered Diversions -- Crop Acres and Reservoir Acres
E6: Kiehne Ditch | K6: Parsons Ditch | Q6: Middle Frisco Ditch | W6: San Francisco Ditch | AC6: Hightower Ditch | AI6: Lewis Ditch | AO6: Cienega Ditch
F7: 0 | G7: reservoir acres | L7: 0 | M7: reservoir acres | R7: 0 | S7: reservoir acres | X7: 0.16 | Y7: reservoir acres | AD7: 0 | AE7: reservoir acres | AJ7: 1.15 | AK7: reservoir acres | AP7: 3 | AQ7: reservoir acres
F8: 0 | G8: pre-plant acres | L8: 0 | M8: pre-plant acres | R8: 0 | S8: pre-plant acres | X8: 0 | Y8: pre-plant acres | AD8: 0 | AE8: pre-plant acres | AJ8: 0 | AK8: pre-plant acres | AP8: 0 | AQ8: pre-plant acres
F9: 84.31 | G9: crop acres | L9: 20.22 | M9: crop acres | R9: 95.85 | S9: crop acres | X9: 19.02 | Y9: crop acres | AD9: 7.63 | AE9: crop acres | AJ9: 0 | AK9: crop acres | AP9: 1.71 | AQ9: crop acres
F10: =SUM(F7:F9) -> 84.31 | G10: total acres | L10: =SUM(L7:L9) -> 20.22 | M10: total acres | R10: =SUM(R7:R9) -> 95.85 | S10: total acres | X10: =SUM(X7:X9) -> 19.18 | Y10: total acres | AD10: =SUM(AD7:AD9) -> 7.63 | AE10: total acres | AJ10: =SUM(AJ7:AJ9) -> 1.15 | AK10: total acres | AP10: =SUM(AP7:AP9) -> 4.71 | AQ10: total acres
A11: MONTH | B11: CIR (ft)/e | C11: Average Area Monthly Pan *(0.8) Evaporation (ft) | D11: Precipitation (ft) | E11: Diverted | F11: Reservoir Evap. minus Precip. (ac-ft) | G11: Reservoir Acres Diversion required for CU | H11: Crop Acres Diversion required for CU | I11: Total Diversion required for CU | J11: Total Short to Required Diversion | K11: Diverted | L11: Reservoir Evap. minus Precip. (ac-ft) | M11: Reservoir Acres Diversion required for CU | N11: Crop Acres Diversion required for CU | O11: Total Diversion required for CU | P11: Total Short to Required Diversion | Q11: Diverted | R11: Reservoir Evap. minus Precip. (ac-ft) | S11: Reservoir Acres Diversion required for CU | T11: Crop Acres Diversion required for CU | U11: Total Diversion required for CU | V11: Total Short to Required Diversion | W11: Diverted | X11: Reservoir Evap. minus Precip. (ac-ft) | Y11: Reservoir Acres Diversion required for CU | Z11: Crop Acres Diversion required for CU | AA11: Total Diversion required for CU | AB11: Total Short to Required Diversion | AC11: Diverted | AD11: Reservoir Evap. minus Precip. (ac-ft) | AE11: Reservoir Acres Diversion required for CU | AF11: Crop Acres Diversion required for CU | AG11: Total Diversion required for CU | AH11: Total Short to Required Diversion | AI11: Diverted | AJ11: Reservoir Evap. minus Precip. (ac-ft) | AK11: Reservoir Acres Diversion required for CU | AL11: Crop Acres Diversion required for CU | AM11: Total Diversion required for CU | AN11: Total Short to Required Diversion | AO11: Diverted | AP11: Reservoir Evap. minus Precip. (ac-ft) | AQ11: Reservoir Acres Diversion required for CU | AR11: Crop Acres Diversion required for CU | AS11: Total Diversion required for CU | AT11: Total Short to Required Diversion
A12: January | B12: =F46/$D$3 -> 0 | C12: =1.74/12 -> 0.145 | D12: 0.11 | E12: 0 | F12: =$F$7*(IF($C12-$D12<0,0,ABS($C12-$D12))) -> 0 | G12: =F12/$D$3 -> 0 | H12: =F$9*$B12 -> 0 | I12: =G12+H12 -> 0 | J12: =IF(E12-I12>0,0,ABS(E12-I12)) -> 0 | K12: 0 | L12: =$L$7*(IF($C12-$D12<0,0,ABS($C12-$D12))) -> 0 | M12: =L12/$D$3 -> 0 | N12: =L$9*$B12 -> 0 | O12: =M12+N12 -> 0 | P12: =IF(K12-O12>0,0,ABS(K12-O12)) -> 0 | Q12: 0 | R12: =R$7*(IF($C12-$D12<0,0,ABS($C12-$D12))) -> 0 | S12: =R12/$D$3 -> 0 | T12: =R$9*$B12 -> 0 | U12: =S12+T12 -> 0 | V12: =IF(Q12-U12>0,0,ABS(Q12-U12)) -> 0 | W12: 0 | X12: =$X$7*(IF($C12-$D12<0,0,ABS($C12-$D12))) -> 0.0056 | Y12: =X12/$D$3 -> 0.014933333 | Z12: =X$9*$B12 -> 0 | AA12: =Y12+Z12 -> 0.014933333 | AB12: 0 | AC12: 0 | AD12: =$AD$7*(IF($C12-$D12<0,0,ABS($C12-$D12))) -> 0 | AE12: =AD12/$D$3 -> 0 | AF12: =AD$9*$B12 -> 0 | AG12: =AE12+AF12 -> 0 | AH12: =IF(AC12-AG12>0,0,ABS(AC12-AG12)) -> 0 | AI12: 0 | AJ12: =$AJ$7*(IF($C12-$D12<0,0,ABS($C12-$D12))) -> 0.04025 | AK12: =AJ12/$D$3 -> 0.10733333 | AL12: =AJ$9*$B12 -> 0 | AM12: =AK12+AL12 -> 0.10733333 | AN12: 0 | AO12: 0 | AP12: =$AP$7*(IF($C12-$D12<0,0,ABS($C12-$D12))) -> 0.105 | AQ12: =AP12/$D$3 -> 0.28 | AR12: =AP$9*$B12 -> 0 | AS12: =AQ12+AR12 -> 0.28 | AT12: =IF(AO12-AS12>0,0,ABS(AO12-AS12)) -> 0.28
A13: February | B13: =G46/$D$3 -> 0 | C13: =2.3/12 -> 0.19166667 | D13: 0.135 | E13: 0 | F13: =$F$7*(IF($C13-$D13<0,0,ABS($C13-$D13))) -> 0 | G13: =F13/$D$3 -> 0 | H13: =F$9*$B13 -> 0 | I13: =G13+H13 -> 0 | J13: =IF(E13-I13>0,0,ABS(E13-I13)) -> 0 | K13: 0 | L13: =$L$7*(IF($C13-$D13<0,0,ABS($C13-$D13))) -> 0 | M13: =L13/$D$3 -> 0 | N13: =L$9*$B13 -> 0 | O13: =M13+N13 -> 0 | P13: =IF(K13-O13>0,0,ABS(K13-O13)) -> 0 | Q13: 0 | R13: =R$7*(IF($C13-$D13<0,0,ABS($C13-$D13))) -> 0 | S13: =R13/$D$3 -> 0 | T13: =R$9*$B13 -> 0 | U13: =S13+T13 -> 0 | V13: =IF(Q13-U13>0,0,ABS(Q13-U13)) -> 0 | W13: 0 | X13: =$X$7*(IF($C13-$D13<0,0,ABS($C13-$D13))) -> 0.0090666667 | Y13: =X13/$D$3 -> 0.024177778 | Z13: =X$9*$B13 -> 0 | AA13: =Y13+Z13 -> 0.024177778 | AB13: 0 | AC13: 0 | AD13: =$AD$7*(IF($C13-$D13<0,0,ABS($C13-$D13))) -> 0 | AE13: =AD13/$D$3 -> 0 | AF13: =AD$9*$B13 -> 0 | AG13: =AE13+AF13 -> 0 | AH13: =IF(AC13-AG13>0,0,ABS(AC13-AG13)) -> 0 | AI13: 0 | AJ13: =$AJ$7*(IF($C13-$D13<0,0,ABS($C13-$D13))) -> 0.065166667 | AK13: =AJ13/$D$3 -> 0.17377778 | AL13: =AJ$9*$B13 -> 0 | AM13: =AK13+AL13 -> 0.17377778 | AN13: 0 | AO13: 0 | AP13: =$AP$7*(IF($C13-$D13<0,0,ABS($C13-$D13))) -> 0.17 | AQ13: =AP13/$D$3 -> 0.45333333 | AR13: =AP$9*$B13 -> 0 | AS13: =AQ13+AR13 -> 0.45333333 | AT13: =IF(AO13-AS13>0,0,ABS(AO13-AS13)) -> 0.45333333
A14: March | B14: =H46/$D$3 -> 0 | C14: =4.82/12 -> 0.40166667 | D14: 0.2175 | E14: 0 | F14: =$F$7*(IF($C14-$D14<0,0,ABS($C14-$D14))) -> 0 | G14: =F14/$D$3 -> 0 | H14: =F$9*$B14 -> 0 | I14: =G14+H14 -> 0 | J14: =IF(E14-I14>0,0,ABS(E14-I14)) -> 0 | K14: 0 | L14: =$L$7*(IF($C14-$D14<0,0,ABS($C14-$D14))) -> 0 | M14: =L14/$D$3 -> 0 | N14: =L$9*$B14 -> 0 | O14: =M14+N14 -> 0 | P14: =IF(K14-O14>0,0,ABS(K14-O14)) -> 0 | Q14: 0 | R14: =R$7*(IF($C14-$D14<0,0,ABS($C14-$D14))) -> 0 | S14: =R14/$D$3 -> 0 | T14: =R$9*$B14 -> 0 | U14: =S14+T14 -> 0 | V14: =IF(Q14-U14>0,0,ABS(Q14-U14)) -> 0 | W14: 0 | X14: =$X$7*(IF($C14-$D14<0,0,ABS($C14-$D14))) -> 0.029466667 | Y14: =X14/$D$3 -> 0.078577778 | Z14: =X$9*$B14 -> 0 | AA14: =Y14+Z14 -> 0.078577778 | AB14: =IF(W14-AA14>0,0,ABS(W14-AA14)) -> 0.078577778 | AC14: 0 | AD14: =$AD$7*(IF($C14-$D14<0,0,ABS($C14-$D14))) -> 0 | AE14: =AD14/$D$3 -> 0 | AF14: =AD$9*$B14 -> 0 | AG14: =AE14+AF14 -> 0 | AH14: =IF(AC14-AG14>0,0,ABS(AC14-AG14)) -> 0 | AI14: 570.54515 | AJ14: =$AJ$7*(IF($C14-$D14<0,0,ABS($C14-$D14))) -> 0.21179167 | AK14: =AJ14/$D$3 -> 0.56477778 | AL14: =AJ$9*$B14 -> 0 | AM14: =AK14+AL14 -> 0.56477778 | AN14: =IF(AI14-AM14>0,0,ABS(AI14-AM14)) -> 0 | AO14: 3.3857833 | AP14: =$AP$7*(IF($C14-$D14<0,0,ABS($C14-$D14))) -> 0.5525 | AQ14: =AP14/$D$3 -> 1.4733333 | AR14: =AP$9*$B14 -> 0 | AS14: =AQ14+AR14 -> 1.4733333 | AT14: =IF(AO14-AS14>0,0,ABS(AO14-AS14)) -> 0
A15: April | B15: =I46/$D$3 -> 0.33617969 | C15: =6.27/12 -> 0.5225 | D15: 0.02 | E15: 119.59795 | F15: =$F$7*(IF($C15-$D15<0,0,ABS($C15-$D15))) -> 0 | G15: =F15/$D$3 -> 0 | H15: =F$9*$B15 -> 28.34331 | I15: =G15+H15 -> 28.34331 | J15: =IF(E15-I15>0,0,ABS(E15-I15)) -> 0 | K15: 138.92224 | L15: =$L$7*(IF($C15-$D15<0,0,ABS($C15-$D15))) -> 0 | M15: =L15/$D$3 -> 0 | N15: =L$9*$B15 -> 6.7975533 | O15: =M15+N15 -> 6.7975533 | P15: =IF(K15-O15>0,0,ABS(K15-O15)) -> 0 | Q15: 50.698249 | R15: =R$7*(IF($C15-$D15<0,0,ABS($C15-$D15))) -> 0 | S15: =R15/$D$3 -> 0 | T15: =R$9*$B15 -> 32.222823 | U15: =S15+T15 -> 32.222823 | V15: =IF(Q15-U15>0,0,ABS(Q15-U15)) -> 0 | W15: 0 | X15: =$X$7*(IF($C15-$D15<0,0,ABS($C15-$D15))) -> 0.0804 | Y15: =X15/$D$3 -> 0.2144 | Z15: =X$9*$B15 -> 6.3941377 | AA15: =Y15+Z15 -> 6.6085377 | AB15: =IF(W15-AA15>0,0,ABS(W15-AA15)) -> 6.6085377 | AC15: 0 | AD15: =$AD$7*(IF($C15-$D15<0,0,ABS($C15-$D15))) -> 0 | AE15: =AD15/$D$3 -> 0 | AF15: =AD$9*$B15 -> 2.565051 | AG15: =AE15+AF15 -> 2.565051 | AH15: =IF(AC15-AG15>0,0,ABS(AC15-AG15)) -> 2.565051 | AI15: 908.80612 | AJ15: =$AJ$7*(IF($C15-$D15<0,0,ABS($C15-$D15))) -> 0.577875 | AK15: =AJ15/$D$3 -> 1.541 | AL15: =AJ$9*$B15 -> 0 | AM15: =AK15+AL15 -> 1.541 | AN15: =IF(AI15-AM15>0,0,ABS(AI15-AM15)) -> 0 | AO15: 2.7927258 | AP15: =$AP$7*(IF($C15-$D15<0,0,ABS($C15-$D15))) -> 1.5075 | AQ15: =AP15/$D$3 -> 4.02 | AR15: =AP$9*$B15 -> 0.57486727 | AS15: =AQ15+AR15 -> 4.5948673 | AT15: =IF(AO15-AS15>0,0,ABS(AO15-AS15)) -> 1.8021415
A16: May | B16: =J46/$D$3 -> 0.62514313 | C16: =7.22/12 -> 0.60166667 | D16: 0.0066666667 | E16: 144.41664 | F16: =$F$7*(IF($C16-$D16<0,0,ABS($C16-$D16))) -> 0 | G16: =F16/$D$3 -> 0 | H16: =F$9*$B16 -> 52.705817 | I16: =G16+H16 -> 52.705817 | J16: =IF(E16-I16>0,0,ABS(E16-I16)) -> 0 | K16: 149.85116 | L16: =$L$7*(IF($C16-$D16<0,0,ABS($C16-$D16))) -> 0 | M16: =L16/$D$3 -> 0 | N16: =L$9*$B16 -> 12.640394 | O16: =M16+N16 -> 12.640394 | P16: =IF(K16-O16>0,0,ABS(K16-O16)) -> 0 | Q16: 40.391265 | R16: =R$7*(IF($C16-$D16<0,0,ABS($C16-$D16))) -> 0 | S16: =R16/$D$3 -> 0 | T16: =R$9*$B16 -> 59.919969 | U16: =S16+T16 -> 59.919969 | V16: =IF(Q16-U16>0,0,ABS(Q16-U16)) -> 19.528704 | W16: 0 | X16: =$X$7*(IF($C16-$D16<0,0,ABS($C16-$D16))) -> 0.0952 | Y16: =X16/$D$3 -> 0.25386667 | Z16: =X$9*$B16 -> 11.890222 | AA16: =Y16+Z16 -> 12.144089 | AB16: =IF(W16-AA16>0,0,ABS(W16-AA16)) -> 12.144089 | AC16: 31.242648 | AD16: =$AD$7*(IF($C16-$D16<0,0,ABS($C16-$D16))) -> 0 | AE16: =AD16/$D$3 -> 0 | AF16: =AD$9*$B16 -> 4.7698421 | AG16: =AE16+AF16 -> 4.7698421 | AH16: =IF(AC16-AG16>0,0,ABS(AC16-AG16)) -> 0 | AI16: 275.26597 | AJ16: =$AJ$7*(IF($C16-$D16<0,0,ABS($C16-$D16))) -> 0.68425 | AK16: =AJ16/$D$3 -> 1.8246667 | AL16: =AJ$9*$B16 -> 0 | AM16: =AK16+AL16 -> 1.8246667 | AN16: =IF(AI16-AM16>0,0,ABS(AI16-AM16)) -> 0 | AO16: 4.4786753 | AP16: =$AP$7*(IF($C16-$D16<0,0,ABS($C16-$D16))) -> 1.785 | AQ16: =AP16/$D$3 -> 4.76 | AR16: =AP$9*$B16 -> 1.0689948 | AS16: =AQ16+AR16 -> 5.8289948 | AT16: =IF(AO16-AS16>0,0,ABS(AO16-AS16)) -> 1.3503195
A17: June | B17: =K46/$D$3 -> 0.95376822 | C17: =8.62/12 -> 0.71833333 | D17: 0.069166667 | E17: 23.17033 | F17: =$F$7*(IF($C17-$D17<0,0,ABS($C17-$D17))) -> 0 | G17: =F17/$D$3 -> 0 | H17: =F$9*$B17 -> 80.412199 | I17: =G17+H17 -> 80.412199 | J17: =IF(E17-I17>0,0,ABS(E17-I17)) -> 57.241869 | K17: 38.677665 | L17: =$L$7*(IF($C17-$D17<0,0,ABS($C17-$D17))) -> 0 | M17: =L17/$D$3 -> 0 | N17: =L$9*$B17 -> 19.285193 | O17: =M17+N17 -> 19.285193 | P17: =IF(K17-O17>0,0,ABS(K17-O17)) -> 0 | Q17: 14.076687 | R17: =R$7*(IF($C17-$D17<0,0,ABS($C17-$D17))) -> 0 | S17: =R17/$D$3 -> 0 | T17: =R$9*$B17 -> 91.418684 | U17: =S17+T17 -> 91.418684 | V17: =IF(Q17-U17>0,0,ABS(Q17-U17)) -> 77.341997 | W17: 0 | X17: =$X$7*(IF($C17-$D17<0,0,ABS($C17-$D17))) -> 0.10386667 | Y17: =X17/$D$3 -> 0.27697778 | Z17: =X$9*$B17 -> 18.140672 | AA17: =Y17+Z17 -> 18.417649 | AB17: =IF(W17-AA17>0,0,ABS(W17-AA17)) -> 18.417649 | AC17: 52.786087 | AD17: =$AD$7*(IF($C17-$D17<0,0,ABS($C17-$D17))) -> 0 | AE17: =AD17/$D$3 -> 0 | AF17: =AD$9*$B17 -> 7.2772515 | AG17: =AE17+AF17 -> 7.2772515 | AH17: =IF(AC17-AG17>0,0,ABS(AC17-AG17)) -> 0 | AI17: 121.22969 | AJ17: =$AJ$7*(IF($C17-$D17<0,0,ABS($C17-$D17))) -> 0.74654167 | AK17: =AJ17/$D$3 -> 1.9907778 | AL17: =AJ$9*$B17 -> 0 | AM17: =AK17+AL17 -> 1.9907778 | AN17: =IF(AI17-AM17>0,0,ABS(AI17-AM17)) -> 0 | AO17: 7.4975166 | AP17: =$AP$7*(IF($C17-$D17<0,0,ABS($C17-$D17))) -> 1.9475 | AQ17: =AP17/$D$3 -> 5.1933333 | AR17: =AP$9*$B17 -> 1.6309437 | AS17: =AQ17+AR17 -> 6.824277 | AT17: =IF(AO17-AS17>0,0,ABS(AO17-AS17)) -> 0
A18: July | B18: =L46/$D$3 -> 0.68557993 | C18: =6.61/12 -> 0.55083333 | D18: 0.2825 | E18: 28.167257 | F18: =$F$7*(IF($C18-$D18<0,0,ABS($C18-$D18))) -> 0 | G18: =F18/$D$3 -> 0 | H18: =F$9*$B18 -> 57.801244 | I18: =G18+H18 -> 57.801244 | J18: =IF(E18-I18>0,0,ABS(E18-I18)) -> 29.633986 | K18: 73.917866 | L18: =$L$7*(IF($C18-$D18<0,0,ABS($C18-$D18))) -> 0 | M18: =L18/$D$3 -> 0 | N18: =L$9*$B18 -> 13.862426 | O18: =M18+N18 -> 13.862426 | P18: =IF(K18-O18>0,0,ABS(K18-O18)) -> 0 | Q18: 114.67828 | R18: =R$7*(IF($C18-$D18<0,0,ABS($C18-$D18))) -> 0 | S18: =R18/$D$3 -> 0 | T18: =R$9*$B18 -> 65.712836 | U18: =S18+T18 -> 65.712836 | V18: =IF(Q18-U18>0,0,ABS(Q18-U18)) -> 0 | W18: 0 | X18: =$X$7*(IF($C18-$D18<0,0,ABS($C18-$D18))) -> 0.042933333 | Y18: =X18/$D$3 -> 0.11448889 | Z18: =X$9*$B18 -> 13.03973 | AA18: =Y18+Z18 -> 13.154219 | AB18: =IF(W18-AA18>0,0,ABS(W18-AA18)) -> 13.154219 | AC18: 108.44226 | AD18: =$AD$7*(IF($C18-$D18<0,0,ABS($C18-$D18))) -> 0 | AE18: =AD18/$D$3 -> 0 | AF18: =AD$9*$B18 -> 5.2309749 | AG18: =AE18+AF18 -> 5.2309749 | AH18: =IF(AC18-AG18>0,0,ABS(AC18-AG18)) -> 0 | AI18: 168.45611 | AJ18: =$AJ$7*(IF($C18-$D18<0,0,ABS($C18-$D18))) -> 0.30858333 | AK18: =AJ18/$D$3 -> 0.82288889 | AL18: =AJ$9*$B18 -> 0 | AM18: =AK18+AL18 -> 0.82288889 | AN18: =IF(AI18-AM18>0,0,ABS(AI18-AM18)) -> 0 | AO18: 5.4842946 | AP18: =$AP$7*(IF($C18-$D18<0,0,ABS($C18-$D18))) -> 0.805 | AQ18: =AP18/$D$3 -> 2.1466667 | AR18: =AP$9*$B18 -> 1.1723417 | AS18: =AQ18+AR18 -> 3.3190083 | AT18: =IF(AO18-AS18>0,0,ABS(AO18-AS18)) -> 0
A19: August | B19: =M46/$D$3 -> 0.85178112 | C19: =5.49/12 -> 0.4575 | D19: 0.1075 | E19: 6.0376827 | F19: =$F$7*(IF($C19-$D19<0,0,ABS($C19-$D19))) -> 0 | G19: =F19/$D$3 -> 0 | H19: =F$9*$B19 -> 71.813666 | I19: =G19+H19 -> 71.813666 | J19: =IF(E19-I19>0,0,ABS(E19-I19)) -> 65.775984 | K19: 0 | L19: =$L$7*(IF($C19-$D19<0,0,ABS($C19-$D19))) -> 0 | M19: =L19/$D$3 -> 0 | N19: =L$9*$B19 -> 17.223014 | O19: =M19+N19 -> 17.223014 | P19: =IF(K19-O19>0,0,ABS(K19-O19)) -> 17.223014 | Q19: 6.9619797 | R19: =R$7*(IF($C19-$D19<0,0,ABS($C19-$D19))) -> 0 | S19: =R19/$D$3 -> 0 | T19: =R$9*$B19 -> 81.643221 | U19: =S19+T19 -> 81.643221 | V19: =IF(Q19-U19>0,0,ABS(Q19-U19)) -> 74.681241 | W19: 0 | X19: =$X$7*(IF($C19-$D19<0,0,ABS($C19-$D19))) -> 0.056 | Y19: =X19/$D$3 -> 0.14933333 | Z19: =X$9*$B19 -> 16.200877 | AA19: =Y19+Z19 -> 16.35021 | AB19: =IF(W19-AA19>0,0,ABS(W19-AA19)) -> 16.35021 | AC19: 0 | AD19: =$AD$7*(IF($C19-$D19<0,0,ABS($C19-$D19))) -> 0 | AE19: =AD19/$D$3 -> 0 | AF19: =AD$9*$B19 -> 6.49909 | AG19: =AE19+AF19 -> 6.49909 | AH19: =IF(AC19-AG19>0,0,ABS(AC19-AG19)) -> 6.49909 | AI19: 143.88091 | AJ19: =$AJ$7*(IF($C19-$D19<0,0,ABS($C19-$D19))) -> 0.4025 | AK19: =AJ19/$D$3 -> 1.0733333 | AL19: =AJ$9*$B19 -> 0 | AM19: =AK19+AL19 -> 1.0733333 | AN19: =IF(AI19-AM19>0,0,ABS(AI19-AM19)) -> 0 | AO19: 0.018181808 | AP19: =$AP$7*(IF($C19-$D19<0,0,ABS($C19-$D19))) -> 1.05 | AQ19: =AP19/$D$3 -> 2.8 | AR19: =AP$9*$B19 -> 1.4565457 | AS19: =AQ19+AR19 -> 4.2565457 | AT19: =IF(AO19-AS19>0,0,ABS(AO19-AS19)) -> 4.2383639
A20: September | B20: =N46/$D$3 -> 0.57792688 | C20: =4.87/12 -> 0.40583333 | D20: 0.076666667 | E20: 0 | F20: =$F$7*(IF($C20-$D20<0,0,ABS($C20-$D20))) -> 0 | G20: =F20/$D$3 -> 0 | H20: =F$9*$B20 -> 48.725015 | I20: =G20+H20 -> 48.725015 | J20: =IF(E20-I20>0,0,ABS(E20-I20)) -> 48.725015 | K20: 0 | L20: =$L$7*(IF($C20-$D20<0,0,ABS($C20-$D20))) -> 0 | M20: =L20/$D$3 -> 0 | N20: =L$9*$B20 -> 11.685682 | O20: =M20+N20 -> 11.685682 | P20: =IF(K20-O20>0,0,ABS(K20-O20)) -> 11.685682 | Q20: 0 | R20: =R$7*(IF($C20-$D20<0,0,ABS($C20-$D20))) -> 0 | S20: =R20/$D$3 -> 0 | T20: =R$9*$B20 -> 55.394292 | U20: =S20+T20 -> 55.394292 | V20: =IF(Q20-U20>0,0,ABS(Q20-U20)) -> 55.394292 | W20: 0 | X20: =$X$7*(IF($C20-$D20<0,0,ABS($C20-$D20))) -> 0.052666667 | Y20: =X20/$D$3 -> 0.14044444 | Z20: =X$9*$B20 -> 10.992169 | AA20: =Y20+Z20 -> 11.132614 | AB20: =IF(W20-AA20>0,0,ABS(W20-AA20)) -> 11.132614 | AC20: 0 | AD20: =$AD$7*(IF($C20-$D20<0,0,ABS($C20-$D20))) -> 0 | AE20: =AD20/$D$3 -> 0 | AF20: =AD$9*$B20 -> 4.4095821 | AG20: =AE20+AF20 -> 4.4095821 | AH20: =IF(AC20-AG20>0,0,ABS(AC20-AG20)) -> 4.4095821 | AI20: 108.11895 | AJ20: =$AJ$7*(IF($C20-$D20<0,0,ABS($C20-$D20))) -> 0.37854167 | AK20: =AJ20/$D$3 -> 1.0094444 | AL20: =AJ$9*$B20 -> 0 | AM20: =AK20+AL20 -> 1.0094444 | AN20: =IF(AI20-AM20>0,0,ABS(AI20-AM20)) -> 0 | AO20: 0 | AP20: =$AP$7*(IF($C20-$D20<0,0,ABS($C20-$D20))) -> 0.9875 | AQ20: =AP20/$D$3 -> 2.6333333 | AR20: =AP$9*$B20 -> 0.98825497 | AS20: =AQ20+AR20 -> 3.6215883 | AT20: =IF(AO20-AS20>0,0,ABS(AO20-AS20)) -> 3.6215883
A21: October | B21: =O46/$D$3 -> 0.33995699 | C21: =4.09/12 -> 0.34083333 | D21: 0.058333333 | E21: 0 | F21: =$F$7*(IF($C21-$D21<0,0,ABS($C21-$D21))) -> 0 | G21: =F21/$D$3 -> 0 | H21: =F$9*$B21 -> 28.661774 | I21: =G21+H21 -> 28.661774 | J21: =IF(E21-I21>0,0,ABS(E21-I21)) -> 28.661774 | K21: 0 | L21: =$L$7*(IF($C21-$D21<0,0,ABS($C21-$D21))) -> 0 | M21: =L21/$D$3 -> 0 | N21: =L$9*$B21 -> 6.8739303 | O21: =M21+N21 -> 6.8739303 | P21: =IF(K21-O21>0,0,ABS(K21-O21)) -> 6.8739303 | Q21: 0 | R21: =R$7*(IF($C21-$D21<0,0,ABS($C21-$D21))) -> 0 | S21: =R21/$D$3 -> 0 | T21: =R$9*$B21 -> 32.584877 | U21: =S21+T21 -> 32.584877 | V21: =IF(Q21-U21>0,0,ABS(Q21-U21)) -> 32.584877 | W21: 0 | X21: =$X$7*(IF($C21-$D21<0,0,ABS($C21-$D21))) -> 0.0452 | Y21: =X21/$D$3 -> 0.12053333 | Z21: =X$9*$B21 -> 6.4659819 | AA21: =Y21+Z21 -> 6.5865153 | AB21: =IF(W21-AA21>0,0,ABS(W21-AA21)) -> 6.5865153 | AC21: 0 | AD21: =$AD$7*(IF($C21-$D21<0,0,ABS($C21-$D21))) -> 0 | AE21: =AD21/$D$3 -> 0 | AF21: =AD$9*$B21 -> 2.5938718 | AG21: =AE21+AF21 -> 2.5938718 | AH21: =IF(AC21-AG21>0,0,ABS(AC21-AG21)) -> 2.5938718 | AI21: 131.24621 | AJ21: =$AJ$7*(IF($C21-$D21<0,0,ABS($C21-$D21))) -> 0.324875 | AK21: =AJ21/$D$3 -> 0.86633333 | AL21: =AJ$9*$B21 -> 0 | AM21: =AK21+AL21 -> 0.86633333 | AN21: =IF(AI21-AM21>0,0,ABS(AI21-AM21)) -> 0 | AO21: 0 | AP21: =$AP$7*(IF($C21-$D21<0,0,ABS($C21-$D21))) -> 0.8475 | AQ21: =AP21/$D$3 -> 2.26 | AR21: =AP$9*$B21 -> 0.58132645 | AS21: =AQ21+AR21 -> 2.8413265 | AT21: =IF(AO21-AS21>0,0,ABS(AO21-AS21)) -> 2.8413265
A22: November | B22: =P46/$D$3 -> 0.020775149 | C22: =2.13/12 -> 0.1775 | D22: 0.058333333 | E22: 0 | F22: =$F$7*(IF($C22-$D22<0,0,ABS($C22-$D22))) -> 0 | G22: =F22/$D$3 -> 0 | H22: =F$9*$B22 -> 1.7515528 | I22: =G22+H22 -> 1.7515528 | J22: =IF(E22-I22>0,0,ABS(E22-I22)) -> 1.7515528 | K22: 0 | L22: =$L$7*(IF($C22-$D22<0,0,ABS($C22-$D22))) -> 0 | M22: =L22/$D$3 -> 0 | N22: =L$9*$B22 -> 0.42007352 | O22: =M22+N22 -> 0.42007352 | P22: =IF(K22-O22>0,0,ABS(K22-O22)) -> 0.42007352 | Q22: 0 | R22: =R$7*(IF($C22-$D22<0,0,ABS($C22-$D22))) -> 0 | S22: =R22/$D$3 -> 0 | T22: =R$9*$B22 -> 1.9912981 | U22: =S22+T22 -> 1.9912981 | V22: =IF(Q22-U22>0,0,ABS(Q22-U22)) -> 1.9912981 | W22: 0 | X22: =$X$7*(IF($C22-$D22<0,0,ABS($C22-$D22))) -> 0.019066667 | Y22: =X22/$D$3 -> 0.050844444 | Z22: =X$9*$B22 -> 0.39514334 | AA22: =Y22+Z22 -> 0.44598778 | AB22: =IF(W22-AA22>0,0,ABS(W22-AA22)) -> 0.44598778 | AC22: 0 | AD22: =$AD$7*(IF($C22-$D22<0,0,ABS($C22-$D22))) -> 0 | AE22: =AD22/$D$3 -> 0 | AF22: =AD$9*$B22 -> 0.15851439 | AG22: =AE22+AF22 -> 0.15851439 | AH22: =IF(AC22-AG22>0,0,ABS(AC22-AG22)) -> 0.15851439 | AI22: 189.63957 | AJ22: =$AJ$7*(IF($C22-$D22<0,0,ABS($C22-$D22))) -> 0.13704167 | AK22: =AJ22/$D$3 -> 0.36544444 | AL22: =AJ$9*$B22 -> 0 | AM22: =AK22+AL22 -> 0.36544444 | AN22: =IF(AI22-AM22>0,0,ABS(AI22-AM22)) -> 0 | AO22: 0 | AP22: =$AP$7*(IF($C22-$D22<0,0,ABS($C22-$D22))) -> 0.3575 | AQ22: =AP22/$D$3 -> 0.95333333 | AR22: =AP$9*$B22 -> 0.035525505 | AS22: =AQ22+AR22 -> 0.98885884 | AT22: =IF(AO22-AS22>0,0,ABS(AO22-AS22)) -> 0.98885884
A23: December | B23: =Q46/$D$3 -> 0 | C23: =1.74/12 -> 0.145 | D23: 0 | E23: 0 | F23: =$F$7*(IF($C23-$D23<0,0,ABS($C23-$D23))) -> 0 | G23: =F23/$D$3 -> 0 | H23: =F$9*$B23 -> 0 | I23: =G23+H23 -> 0 | J23: =IF(E23-I23>0,0,ABS(E23-I23)) -> 0 | K23: 0 | L23: =$L$7*(IF($C23-$D23<0,0,ABS($C23-$D23))) -> 0 | M23: =L23/$D$3 -> 0 | N23: =L$9*$B23 -> 0 | O23: =M23+N23 -> 0 | P23: =IF(K23-O23>0,0,ABS(K23-O23)) -> 0 | Q23: 0 | R23: =R$7*(IF($C23-$D23<0,0,ABS($C23-$D23))) -> 0 | S23: =R23/$D$3 -> 0 | T23: =R$9*$B23 -> 0 | U23: =S23+T23 -> 0 | V23: =IF(Q23-U23>0,0,ABS(Q23-U23)) -> 0 | W23: 0 | X23: =$X$7*(IF($C23-$D23<0,0,ABS($C23-$D23))) -> 0.0232 | Y23: =X23/$D$3 -> 0.061866667 | Z23: =X$9*$B23 -> 0 | AA23: =Y23+Z23 -> 0.061866667 | AB23: 0 | AC23: 0 | AD23: =$AD$7*(IF($C23-$D23<0,0,ABS($C23-$D23))) -> 0 | AE23: =AD23/$D$3 -> 0 | AF23: =AD$9*$B23 -> 0 | AG23: =AE23+AF23 -> 0 | AH23: =IF(AC23-AG23>0,0,ABS(AC23-AG23)) -> 0 | AI23: 5.7322283 | AJ23: =$AJ$7*(IF($C23-$D23<0,0,ABS($C23-$D23))) -> 0.16675 | AK23: =AJ23/$D$3 -> 0.44466667 | AL23: =AJ$9*$B23 -> 0 | AM23: =AK23+AL23 -> 0.44466667 | AN23: 0 | AO23: 0 | AP23: =$AP$7*(IF($C23-$D23<0,0,ABS($C23-$D23))) -> 0.435 | AQ23: =AP23/$D$3 -> 1.16 | AR23: =AP$9*$B23 -> 0 | AS23: =AQ23+AR23 -> 1.16 | AT23: =IF(AO23-AS23>0,0,ABS(AO23-AS23)) -> 1.16
A24: TOTALS | B24: =SUM(B12:B23) -> 4.3911111 | C24: =SUM(C12:C23) -> 4.6583333 | D24: =SUM(D12:D23) -> 1.1416667 | E24: =SUM(E12:E23) -> 321.38986 | F24: =SUM(F12:F23) -> 0 | G24: =SUM(G12:G23) -> 0 | H24: =SUM(H12:H23) -> 370.21458 | I24: =SUM(I12:I23) -> 370.21458 | ... AT24: =SUM(AT12:AT23) -> 16.735932
A25: Daily diversion records were used to assess whether a shortage condition truly existed in months for which only partial daily data were available, e.g. spring and fall at data logger startup/shutdown. | T25: Estimated from partial data.
A26: Reservoirs with small amounts of evaporation exceeding precipitation during winter were assumed to have no shortage in those months, despite the lack of diversion data for that period.
A27: Consumptive Use | F27: Metered | L27: Non-Metered | S27: Total
C28: CIR full season (ft) | D28: CIR Jul-Nov (ft) | F28: Acres Subject to Shortage | G28: CU Demand/Full Supply | H28: Diversion Required for CU * | I28: Diversion Shortage to CU * | J28: Fractional Shortage to Diversion Required | K28: Shortage to CU | M28: Acres Subject to Shortage | N28: CU Demand/Full Supply | O28: Shortage to CU | P28: Acres NOT Subject to Shortage** | Q28: CU Demand/Full Supply | S28: Total Acres | T28: Total CU Demand/Full Supply | U28: Total Shortage to CU Demand | V28: Tota Crop & Pond CU | W28: Incidental Losses | X28: Total Irrigated CU
A29: Full Season | C29: =B24*D3 -> 1.6466667 | F29: =($F9+$L9+$R9+$X9+$AD9+$AJ9+$AP9)-F30 -> 228.74 | G29: =F29*$C29 -> 376.65853 | H29: =H24+N24+T24+Z24+AF24+AL24 -> 996.91396 | K29: =G29*J32 -> 235.0714 | M29: 79.43 | N29: =M29*$C29 -> 130.79473 | O29: =J32*N29 -> 81.628579 | P29: 30.41 | Q29: =P29*$C29 -> 50.075133 | S29: =F29+M29+P29 -> 338.58 | T29: =G29+N29+Q29 -> 557.5284 | U29: =O29+K29 -> 316.69998 | V29: =T29-U29 -> 240.82842
A30: Pre-Plant | M30: 0 | P30: 0
