Workbook

Sheet GSAR_IA_2025
A1: OBJECTID | B1: Field_ID | C1: Basin | D1: Sub_Basin | E1: Inspector_1 | F1: Inspector_2 | G1: Water_Righted_Acreage | H1: Decree | I1: System | J1: SysCode | K1: Unit | L1: UCode | M1: Ditch | N1: Crop_Code | O1: Crop_Type | P1: Computed_Acreage | Q1: Irr_Code | R1: Irr_Method | S1: Remarks | T1: Season | U1: Mapsheet | V1: Sections | W1: File_nbr | X1: Tws | Y1: Rng | Z1: Sec | AA1: County | AB1: Owner | AC1: Priority | AD1: No_Adjudicated_Water_Right | AE1: Subfile | AF1: Inspection_date | AG1: Shape_Length | AH1: Shape_Area
A2: 1 | B2: GSAR 00001 | C2: GSF | D2: GSAR | E2: MM | G2: 0.21 | H2: Arizona v California | I2: San Francisco River | J2: SF | K2: Apache Creek, Aragon | L2: AA | N2: UN | O2: Unreported | P2: 0.21833546 | R2: <Null> | S2: PART 2 OF 3, permitted Locked gate | U2: 12 | W2: GSF-2922 | X2: T5S | Y2: R17W | Z2: 17 | AA2: CA | AB2: BROWN, BOGGS | AF2: 7/30/2025 | AG2: 177.95316 | AH2: 883.5758
A3: 2 | B3: GSAR 00002 | C3: GSF | D3: GSAR | E3: MM | G3: 0.79 | H3: Arizona v California | I3: San Francisco River | J3: SF | K3: Apache Creek, Aragon | L3: AA | N3: UN | O3: Unreported | P3: 0.79592205 | R3: <Null> | S3: PART 1 OF 3, permitted Locked Gate | U3: 12 | W3: GSF-2922 | X3: T5S | Y3: R17W | Z3: 17 | AA3: CA | AB3: BROWN, BOGGS | AF3: 7/30/2025 | AG3: 381.03452 | AH3: 3220.9952
A4: 3 | B4: GSAR 00003 | C4: GSF | D4: GSAR | E4: MM | G4: 1 | H4: Arizona v California | I4: San Francisco River | J4: SF | K4: Apache Creek, Aragon | L4: AA | N4: UN | O4: Unreported | P4: 0.99127358 | R4: <Null> | S4: PART 3 OF 3, permitted Locked Gate | U4: 12 | W4: GSF-2922 | X4: T5S | Y4: R17W | Z4: 17 | AA4: CA | AB4: BROWN, BOGGS | AF4: 7/30/2025 | AG4: 352.60067 | AH4: 4011.5579
A5: 4 | B5: GSAR 00004 | C5: GSF | D5: GSAR | E5: MM | G5: 0 | H5: Arizona v California | I5: San Francisco River | J5: SF | K5: Apache Creek, Aragon | L5: AA | N5: MON | O5: Misc. Outdoor Nursery Stock | P5: 0.023306898 | Q5: 2 | R5: Sprinkler irrigated | S5: permitted | U5: 2 | X5: T5S | Y5: R17W | Z5: 31 | AA5: CA | AF5: 7/24/2025 | AG5: 60.301845 | AH5: 94.320048
A6: 5 | B6: GSAR 00005 | C6: GSF | D6: GSAR | E6: MM | G6: 0 | H6: Arizona v California | I6: San Francisco River | J6: SF | K6: Apache Creek, Aragon | L6: AA | N6: MON | O6: Misc. Outdoor Nursery Stock | P6: 0.017085041 | Q6: 2 | R6: Sprinkler irrigated | S6: permitted | U6: 2 | X6: T5S | Y6: R17W | Z6: 31 | AA6: CA | AF6: 7/24/2025 | AG6: 54.559829 | AH6: 69.140983
A7: 6 | B7: GSAR 00006 | C7: GSF | D7: GSAR | E7: MM | G7: 0 | H7: Arizona v California | I7: San Francisco River | J7: SF | K7: Apache Creek, Aragon | L7: AA | N7: MON | O7: Misc. Outdoor Nursery Stock | P7: 0.040959164 | Q7: 2 | R7: Sprinkler irrigated | S7: permitted | U7: 2 | X7: T5S | Y7: R17W | Z7: 31 | AA7: CA | AF7: 7/24/2025 | AG7: 51.790404 | AH7: 165.75652
A8: 7 | B8: GSAR 00007 | C8: GSF | D8: GSAR | E8: MM | G8: 0 | H8: Arizona v California | I8: San Francisco River | J8: SF | K8: Apache Creek, Aragon | L8: AA | N8: MON | O8: Misc. Outdoor Nursery Stock | P8: 0.011027034 | Q8: 2 | R8: Sprinkler irrigated | S8: permitted | U8: 2 | X8: T5S | Y8: R17W | Z8: 31 | AA8: CA | AF8: 7/24/2025 | AG8: 33.608519 | AH8: 44.625002
A9: 8 | B9: GSAR 00008 | C9: GSF | D9: GSAR | E9: MM | G9: 0 | H9: Arizona v California | I9: San Francisco River | J9: SF | K9: Apache Creek, Aragon | L9: AA | N9: FA | O9: Fallow, idle or otherwise not irrigated | P9: 0.14447488 | Q9: 4 | R9: Not irrigated | S9: WR MOVED FROM RESERVE TO ARAGON AREA | U9: 3 | X9: T5S | Y9: R17W | Z9: 31 | AA9: CA | AF9: 7/23/2025 | AG9: 109.47847 | AH9: 584.67144
A10: 9 | B10: GSAR 00009 | C10: GSF | D10: GSAR | E10: MM | G10: 0 | H10: Arizona v California | I10: San Francisco River | J10: SF | K10: Apache Creek, Aragon | L10: AA | N10: FA | O10: Fallow, idle or otherwise not irrigated | P10: 0.03373416 | Q10: 4 | R10: Not irrigated | S10: permitted | U10: 3 | X10: T5S | Y10: R17W | Z10: 31 | AA10: CA | AF10: 7/23/2025 | AG10: 47.617706 | AH10: 136.51785
A11: 10 | B11: GSAR 00010 | C11: GSF | D11: GSAR | E11: MM | G11: 0 | H11: Arizona v California | I11: San Francisco River | J11: SF | K11: Apache Creek, Aragon | L11: AA | N11: MON | O11: Misc. Outdoor Nursery Stock | P11: 0.35424386 | Q11: 2 | R11: Sprinkler irrigated | S11: permitted | U11: 1 | X11: T6S | Y11: R18W | Z11: 11 | AA11: CA | AF11: 7/24/2025 | AG11: 269.03804 | AH11: 1433.5798
A12: 11 | B12: GSAR 00011 | C12: GSF | D12: GSAR | E12: MM | G12: 0 | H12: Arizona v California | I12: San Francisco River | J12: SF | K12: Apache Creek, Aragon | L12: AA | N12: FA | O12: Fallow, idle or otherwise not irrigated | P12: 0.23828319 | Q12: 4 | R12: Not irrigated | S12: permitted | U12: 1 | X12: T6S | Y12: R18W | Z12: 11 | AA12: CA | AF12: 7/24/2025 | AG12: 145.32403 | AH12: 964.3017
A13: 12 | B13: GSAR 00012 | C13: GSF | D13: GSAR | E13: MM | G13: 0 | H13: Arizona v California | I13: San Francisco River | J13: SF | K13: Apache Creek, Aragon | L13: AA | N13: OUT | O13: Out Areas | P13: 5.5242751 | R13: <Null> | S13: No Right | U13: 17 | X13: T4S | Y13: R18W | Z13: 25 | AA13: CA | AD13: 7.3 | AE13: 539 | AF13: 7/30/2025 | AG13: 847.83474 | AH13: 22356.037
A14: 13 | B14: GSAR 00013 | C14: GSF | D14: GSAR | E14: MM | G14: 0 | H14: Arizona v California | I14: San Francisco River | J14: SF | K14: Apache Creek, Aragon | L14: AA | N14: OUT | O14: Out Areas | P14: 0.27886332 | R14: <Null> | S14: No Right, Reservoir | U14: 17 | X14: T4S | Y14: R18W | Z14: 25 | AA14: CA | AD14: 0.5 | AE14: 539 | AF14: 7/30/2025 | AG14: 127.95895 | AH14: 1128.5243
A15: 14 | B15: GSAR 00014 | C15: GSF | D15: GSAR | E15: MM | G15: 0.8 | H15: Arizona v California | I15: San Francisco River | J15: SF | K15: Apache Creek, Aragon | L15: AA | N15: FA | O15: Fallow, idle or otherwise not irrigated | P15: 0.58761801 | Q15: 4 | R15: Not irrigated | S15: rights in ponds? | U15: 17 | X15: T4S | Y15: R18W | Z15: 25 | AA15: CA | AC15: 1907 | AE15: 538 | AF15: 7/30/2025 | AG15: 250.19931 | AH15: 2378.0152
A16: 15 | B16: GSAR 00015 | C16: GSF | D16: GSAR | E16: MM | G16: 2.6 | H16: Arizona v California | I16: San Francisco River | J16: SF | K16: Apache Creek, Aragon | L16: AA | O16: Reservoir Retaining water (note volume in remarks) | P16: 2.0488135 | S16: rights in ponds? 85% Full | U16: 17 | AC16: 1907 | AE16: 538 | AF16: 7/30/2025 | AG16: 186.87922 | AH16: 2104.2653
A17: 16 | B17: GSAR 00016 | C17: GSF | D17: GSAR | E17: MM | H17: Arizona v California | I17: San Francisco River | J17: SF | K17: Apache Creek, Aragon | L17: AA | N17: OUT | O17: Out Areas | P17: 3.2222411 | R17: <Null> | S17: No Right | U17: 16 | X17: T4S | Y17: R17W | Z17: 31 | AA17: CA | AD17: 3.0 | AE17: 562 | AF17: 7/30/2025 | AG17: 606.72744 | AH17: 13039.999
A18: 17 | B18: GSAR 00017 | C18: GSF | D18: GSAR | E18: MM | G18: 3 | H18: Arizona v California | I18: San Francisco River | J18: SF | K18: Apache Creek, Aragon | L18: AA | N18: OUT | O18: Out Areas | P18: 3.2136736 | R18: <Null> | S18: No Right (domestic well only) | U18: 16 | X18: T4S | Y18: R17W | Z18: 31 | AA18: CA | AE18: 562 | AF18: 7/30/2025 | AG18: 678.97332 | AH18: 12592.969
A19: 18 | B19: GSAR 00018 | C19: GSF | D19: GSAR | E19: MM | G19: 5.7 | H19: Arizona v California | I19: San Francisco River | J19: SF | K19: Apache Creek, Aragon | L19: AA | N19: FA | O19: Fallow, idle or otherwise not irrigated | P19: 3.1141259 | Q19: 4 | R19: Not irrigated | U19: 15 | W19: GSF-27 | X19: T5S | Y19: R17W | Z19: 6 | AA19: CA | AC19: 1937 | AE19: 524 | AF19: 7/30/2025 | AG19: 507.99637 | AH19: 12602.471
A20: 19 | B20: GSAR 00019 | C20: GSF | D20: GSAR | E20: MM | G20: 3 | H20: Arizona v California | I20: San Francisco River | J20: SF | K20: Apache Creek, Aragon | L20: AA | N20: OUT | O20: Out Areas | P20: 3.1905987 | R20: <Null> | S20: Right move off | U20: 15 | W20: GSF-27 | X20: T5S | Y20: R17W | Z20: 6 | AA20: CA | AC20: 1937 | AE20: 524 | AF20: 7/30/2025 | AG20: 450.8051 | AH20: 12911.946
A21: 20 | B21: GSAR 00026 | C21: GSF | D21: GSAR | E21: MM | G21: 0.5 | H21: Arizona v California | I21: San Francisco River | J21: SF | K21: Apache Creek, Aragon | L21: AA | N21: OUT | O21: Out Areas | P21: 0.48953487 | R21: <Null> | S21: Right move off | U21: 9 | W21: SD-7877-11 | X21: T5S | Y21: R16W | Z21: 8 | AA21: CA | AB21: MATA FAMILY | AC21: 1878 | AE21: 518 | AF21: 7/30/2025 | AG21: 200.05118 | AH21: 1981.0852
A22: 21 | B22: GSAR 00028 | C22: GSF | D22: GSAR | E22: MM | G22: 0.5 | H22: Arizona v California | I22: San Francisco River | J22: SF | K22: Apache Creek, Aragon | L22: AA | N22: PN | O22: Pasture (Native) | P22: 0.51395658 | Q22: 1 | R22: Flood irrigated | U22: 9 | W22: SD-7877-12 | X22: T5S | Y22: R16W | Z22: 8 | AA22: CA | AB22: MATA FAMILY | AC22: 1878 | AE22: 518 | AF22: 7/30/2025 | AG22: 206.91176 | AH22: 2079.9168
A23: 22 | B23: GSAR 00029 | C23: GSF | D23: GSAR | E23: MM | G23: 0.7 | H23: Arizona v California | I23: San Francisco River | J23: SF | K23: Apache Creek, Aragon | L23: AA | N23: FA | O23: Fallow, idle or otherwise not irrigated | P23: 0.71693312 | Q23: 4 | R23: Not irrigated | S23: Dying Orchard | U23: 9 | W23: SD-7877-6 | X23: T5S | Y23: R16W | Z23: 8 | AA23: CA | AE23: 470 | AF23: 7/30/2025 | AG23: 231.78759 | AH23: 2901.337
A24: 23 | B24: GSAR 00030 | C24: GSF | D24: GSAR | E24: MM | G24: 0.4 | H24: Arizona v California | I24: San Francisco River | J24: SF | K24: Apache Creek, Aragon | L24: AA | N24: PN | O24: Pasture (Native) | P24: 0.45289779 | Q24: 1 | R24: Flood irrigated | U24: 9 | W24: SD-7877-6 | X24: T5S | Y24: R16W | Z24: 8 | AA24: CA | AC24: 12/31/1878 | AE24: 470 | AF24: 7/30/2025 | AG24: 204.75902 | AH24: 1832.8197
A25: 24 | B25: GSAR 00031 | C25: GSF | D25: GSAR | E25: MM | G25: 0.7 | H25: Arizona v California | I25: San Francisco River | J25: SF | K25: Apache Creek, Aragon | L25: AA | N25: FA | O25: Fallow, idle or otherwise not irrigated | P25: 0.66300725 | Q25: 4 | R25: Not irrigated | U25: 9 | W25: SD-7877-6 | X25: T5S | Y25: R16W | Z25: 8 | AA25: CA | AC25: 12/31/1878 | AE25: 470 | AF25: 7/30/2025 | AG25: 228.14344 | AH25: 2683.1059
A26: 25 | B26: GSAR 00033 | C26: GSF | D26: GSAR | E26: MM | G26: 1.3 | H26: Arizona v California | I26: San Francisco River | J26: SF | K26: Apache Creek, Aragon | L26: AA | N26: PN | O26: Pasture (Native) | P26: 1.3020783 | Q26: 1 | R26: Flood irrigated | U26: 9 | W26: SD-7877-6 | X26: T5S | Y26: R16W | Z26: 8 | AA26: CA | AC26: 12/31/1878 | AE26: 470 | AF26: 7/30/2025 | AG26: 338.86269 | AH26: 5269.345
A27: 26 | B27: GSAR 00034 | C27: GSF | D27: GSAR | E27: MM | G27: 0.3 | H27: Arizona v California | I27: San Francisco River | J27: SF | K27: Apache Creek, Aragon | L27: AA | N27: PN | O27: Pasture (Native) | P27: 0.31838101 | Q27: 1 | R27: Flood irrigated | U27: 9 | W27: SD-7877-6 | X27: T5S | Y27: R16W | Z27: 8 | AA27: CA | AC27: 12/31/1878 | AE27: 470 | AF27: 7/30/2025 | AG27: 178.23153 | AH27: 1288.4474
A28: 27 | B28: GSAR 00035 | C28: GSF | D28: GSAR | E28: MM | G28: 1.5 | H28: Arizona v California | I28: San Francisco River | J28: SF | K28: Apache Creek, Aragon | L28: AA | N28: PN | O28: Pasture (Native) | P28: 1.5686711 | Q28: 1 | R28: Flood irrigated | U28: 9 | W28: SD-7877-6 | X28: T5S | Y28: R16W | Z28: 8 | AA28: CA | AC28: 12/31/1878 | AE28: 470 | AF28: 7/30/2025 | AG28: 353.18666 | AH28: 6348.212
A29: 28 | B29: GSAR 00036 | C29: GSF | D29: GSAR | E29: MM | G29: 3.2 | H29: Arizona v California | I29: San Francisco River | J29: SF | K29: Apache Creek, Aragon | L29: AA | N29: PN | O29: Pasture (Native) | P29: 3.3557468 | Q29: 1 | R29: Flood irrigated | U29: 9 | W29: SD-7877-6 | X29: T5S | Y29: R16W | Z29: 8 | AA29: CA | AC29: 12/31/1878 | AE29: 470 | AF29: 7/30/2025 | AG29: 469.264 | AH29: 13580.28
A30: 29 | B30: GSAR 00038 | C30: GSF | D30: GSAR | E30: MM | G30: 1.7 | H30: Arizona v California | I30: San Francisco River | J30: SF | K30: Apache Creek, Aragon | L30: AA | N30: PN | O30: Pasture (Native) | P30: 1.8582942 | Q30: 1 | R30: Flood irrigated | U30: 9 | W30: SD-7877-6 | X30: T5S | Y30: R16W | Z30: 8 | AA30: CA | AC30: 12/31/1878 | AE30: 470 | AF30: 7/30/2025 | AG30: 340.50119 | AH30: 7520.2798
A31: 30 | B31: GSAR 00039 | C31: GSF | D31: GSAR | E31: MM | G31: 10.8 | H31: Arizona v California | I31: San Francisco River | J31: SF | K31: Apache Creek, Aragon | L31: AA | N31: PN | O31: Pasture (Native) | P31: 11.432008 | Q31: 1 | R31: Flood irrigated | U31: 9 | W31: SD-7877-3 | X31: T5S | Y31: R16W | Z31: 8 | AA31: CA | AC31: 12/31/1878 | AE31: 464 | AF31: 7/30/2025 | AG31: 954.01221 | AH31: 46263.882
A32: 31 | B32: GSAR 00040 | C32: GSF | D32: GSAR | E32: MM | G32: 0.9 | H32: Arizona v California | I32: San Francisco River | J32: SF | K32: Apache Creek, Aragon | L32: AA | N32: FA | O32: Fallow, idle or otherwise not irrigated | P32: 0.97906798 | Q32: 4 | R32: Not irrigated | U32: 9 | W32: SD-7877-6 | X32: T5S | Y32: R16W | Z32: 8 | AA32: CA | AC32: 12/31/1878 | AE32: 470 | AF32: 7/30/2025 | AG32: 252.19109 | AH32: 3962.1634
A33: 32 | B33: GSAR 00041 | C33: GSF | D33: GSAR | E33: MM | G33: 5.3 | H33: Arizona v California | I33: San Francisco River | J33: SF | K33: Apache Creek, Aragon | L33: AA | N33: PN | O33: Pasture (Native) | P33: 5.6182382 | Q33: 1 | R33: Flood irrigated | U33: 9 | W33: SD-7877-6 | X33: T5S | Y33: R16W | Z33: 8 | AA33: CA | AC33: 12/31/1878 | AE33: 470 | AF33: 7/30/2025 | AG33: 666.83356 | AH33: 22736.294
A34: 33 | B34: GSAR 00042 | C34: GSF | D34: GSAR | E34: MM | G34: 1.9 | H34: Arizona v California | I34: San Francisco River | J34: SF | K34: Apache Creek, Aragon | L34: AA | N34: PN | O34: Pasture (Native) | P34: 1.9187461 | Q34: 1 | R34: Flood irrigated | U34: 9 | W34: SD-7877-6 | X34: T5S | Y34: R16W | Z34: 8 | AA34: CA | AC34: 12/31/1878 | AE34: 470 | AF34: 7/30/2025 | AG34: 504.99093 | AH34: 7764.9209
A35: 34 | B35: GSAR 00043 | C35: GSF | D35: GSAR | E35: MM | G35: 1.1 | H35: Arizona v California | I35: San Francisco River | J35: SF | K35: Apache Creek, Aragon | L35: AA | N35: PN | O35: Pasture (Native) | P35: 1.2275965 | Q35: 1 | R35: Flood irrigated | U35: 9 | W35: SD-7877-6 | X35: T5S | Y35: R16W | Z35: 8 | AA35: CA | AC35: 12/31/1878 | AE35: 470 | AF35: 7/30/2025 | AG35: 345.49092 | AH35: 4967.9267
... A37: 36 | B37: GSAR 00045 | C37: GSF | D37: GSAR | E37: MM | G37: 0.3 | H37: Arizona v California | I37: San Francisco River | J37: SF | K37: Apache Creek, Aragon | L37: AA | N37: <Null> | O37: Orchard (ground cover) | P37: 0.22330378 | Q37: 1 | R37: Flood irrigated | U37: 9 | W37: SD-7877-14 | X37: T5S | Y37: R16W | Z37: 8 | AA37: CA | AC37: 12/31/1878 | AE37: 541 | AF37: 7/30/2025 | AG37: 314.52425 | AH37: 903.68196
A38: 37 | B38: GSAR 00046 | C38: GSF | D38: GSAR | E38: MM | G38: 5 | H38: Arizona v California | I38: San Francisco River | J38: SF | K38: Apache Creek, Aragon | L38: AA | N38: PN | O38: Pasture (Native) | P38: 5.3074515 | Q38: 1 | R38: Flood irrigated | U38: 9 | W38: SD-7877-15 | AC38: 12/31/1878 | AE38: 545 | AF38: 7/30/2025 | AG38: 639.27375 | AH38: 12834.774
A39: 38 | B39: GSAR 00047 | C39: GSF | D39: GSAR | E39: MM | G39: 1 | H39: Arizona v California | I39: San Francisco River | J39: SF | K39: Apache Creek, Aragon | L39: AA | N39: PN | O39: Pasture (Native) | P39: 1.0060538 | Q39: 1 | R39: Flood irrigated | U39: 9 | W39: SD-7877-10 | X39: T5S | Y39: R16W | Z39: 8 | AA39: CA | AC39: 12/31/1878 | AE39: 511 | AF39: 7/30/2025 | AG39: 287.75257 | AH39: 4071.3716
A40: 39 | B40: GSAR 00048 | C40: GSF | D40: GSAR | E40: MM | G40: 1 | H40: Arizona v California | I40: San Francisco River | J40: SF | K40: Apache Creek, Aragon | L40: AA | N40: FA | O40: Fallow, idle or otherwise not irrigated | P40: 1.0294206 | Q40: 4 | R40: Not irrigated | U40: 9 | W40: SD-7877-2 | X40: T5S | Y40: R16W | Z40: 8 | AA40: CA | AC40: 12/31/1878 | AE40: 462 | AF40: 7/30/2025 | AG40: 280.64796 | AH40: 4165.934
A41: 40 | B41: GSAR 00049 | C41: GSF | D41: GSAR | E41: MM | G41: 0.8 | H41: Arizona v California | I41: San Francisco River | J41: SF | K41: Apache Creek, Aragon | L41: AA | N41: FA | O41: Fallow, idle or otherwise not irrigated | P41: 0.8879661 | Q41: 4 | R41: Not irrigated | U41: 9 | W41: SD-7878-5 | X41: T5S | Y41: R16W | Z41: 8 | AA41: CA | AC41: 12/31/1878 | AE41: 470 | AF41: 7/30/2025 | AG41: 286.5727 | AH41: 3593.4857
...

Sheet GSCG_IA_2025
A1: OBJECTID | B1: Field_ID | C1: Basin | D1: Sub_Basin | E1: Inspector_1 | F1: Inspector_2 | G1: Inspection_Date | H1: Water_Righted_Acreage | I1: Decree | J1: System | K1: SysCode | L1: Unit | M1: UCode | N1: Ditch | O1: Crop_Code | P1: Crop_Type | Q1: Computed_Acreage | R1: Irr_Code | S1: Irr_Method | T1: Remarks | U1: Season | V1: Mapsheet | W1: Sections | X1: File_nbr | Y1: Tws | Z1: Rng | AA1: Sec | AB1: County | AC1: Owner | AD1: Priority | AE1: No_Adjudicated_Water_Right | AF1: Subfile | AG1: PLSS QQQ | AH1: Pla_rec_nbr | AI1: # | AJ1: Shape_Length | AK1: Shape_Area
A2: 1 | B2: GSCG-00001 | C2: GSF | D2: GSCG | E2: MM | F2: <Null> | G2: 45869 | H2: 0.05 | I2: Arizona v California | J2: Gila River | K2: GR | L2: Cliff Gila, Buckhorn-Duck Creek | M2: CG | O2: MON | P2: Misc. Outdoor Nursery Stock | Q2: 0.05208365 | R2: 2 | S2: Sprinkler irrigated | T2: Permitted, GSF-1146-M into GSF-4380, 2,245.59 sqft | V2: 20 | X2: GSF-4380 | Y2: T15S | Z2: R18W | AA2: 24 | AB2: GR | AD2: 06/09/1961 | AF2: C&L: GSF-1146 | AJ2: 103.26522 | AK2: 210.7759
A3: 2 | B3: GSCG-00002 | C3: GSF | D3: GSCG | E3: MM | F3: <Null> | G3: 45869 | H3: 0.001 | I3: Arizona v California | J3: Gila River | K3: GR | L3: Cliff Gila, Buckhorn-Duck Creek | M3: CG | O3: MON | P3: Misc. Outdoor Nursery Stock | Q3: 0.0039164252 | R3: 2 | S3: Sprinkler irrigated | T3: Permitted, GSF-1146-M into GSF-4380, 171.15 sqft | V3: 20 | X3: GSF-4380 | Y3: T15S | Z3: R18W | AA3: 24 | AB3: GR | AD3: 06/09/1961 | AF3: C&L: GSF-1146 | AJ3: 23.934879 | AK3: 15.849274
A4: 3 | B4: GSCG-00003 | C4: GSF | D4: GSCG | E4: MM | F4: <Null> | G4: 45869 | H4: 0.001 | I4: Arizona v California | J4: Gila River | K4: GR | L4: Cliff Gila, Buckhorn-Duck Creek | M4: CG | O4: MON | P4: Misc. Outdoor Nursery Stock | Q4: 0.0014710926 | R4: 2 | S4: Sprinkler irrigated | T4: Permitted, GSF-1146-M into GSF-4380, 51.5 sqft | V4: 20 | X4: GSF-4380 | Y4: T15S | Z4: R18W | AA4: 24 | AB4: GR | AD4: 06/09/1961 | AF4: C&L: GSF-1146 | AJ4: 14.02029 | AK4: 5.9533245
A5: 4 | B5: GSCG-00004 | C5: GSF | D5: GSCG | E5: MM | F5: <Null> | G5: 45869 | H5: 0.001 | I5: Arizona v California | J5: Gila River | K5: GR | L5: Cliff Gila, Buckhorn-Duck Creek | M5: CG | O5: MON | P5: Misc. Outdoor Nursery Stock | Q5: 0.0030456764 | R5: 2 | S5: Sprinkler irrigated | T5: Permitted, GSF-1146-M into GSF-4380, 94.70 sqft | V5: 20 | X5: GSF-4380 | Y5: T15S | Z5: R18W | AA5: 24 | AB5: GR | AD5: 06/09/1961 | AF5: C&L: GSF-1146 | AJ5: 16.244796 | AK5: 12.325465
A6: 5 | B6: GSCG-00005 | C6: GSF | D6: GSCG | E6: MM | F6: <Null> | G6: 45869 | H6: 0.03 | I6: Arizona v California | J6: Gila River | K6: GR | L6: Cliff Gila, Buckhorn-Duck Creek | M6: CG | O6: MON | P6: Misc. Outdoor Nursery Stock | Q6: 0.029975985 | R6: 2 | S6: Sprinkler irrigated | T6: Permitted, GSF-1146-M into GSF-4380, 1,305.73 sqft | V6: 20 | X6: GSF-4380 | Y6: T15S | Z6: R18W | AA6: 24 | AB6: GR | AD6: 06/09/1961 | AF6: C&L: GSF-1146 | AJ6: 69.193154 | AK6: 121.30899
A7: 6 | B7: GSCG-00006 | C7: GSF | D7: GSCG | E7: MM | F7: <Null> | G7: 45869 | H7: 0.001 | I7: Arizona v California | J7: Gila River | K7: GR | L7: Cliff Gila, Buckhorn-Duck Creek | M7: CG | O7: MON | P7: Misc. Outdoor Nursery Stock | Q7: 0.0035711166 | R7: 2 | S7: Sprinkler irrigated | T7: Permitted, GSF-1146-M into GSF-4380. 155.23 sqft | V7: 20 | X7: GSF-4380 | Y7: T15S | Z7: R18W | AA7: 24 | AB7: GR | AD7: 06/09/1961 | AF7: C&L: GSF-1146 | AJ7: 15.327355 | AK7: 14.451854
A8: 7 | B8: GSCG-00007 | C8: GSF | D8: GSCG | E8: MM | F8: <Null> | G8: 45846 | H8: 0.4 | I8: Arizona v California | J8: Gila River | K8: GR | L8: Cliff Gila, Buckhorn-Duck Creek | M8: CG | N8: <Null> | O8: FA | P8: Fallow, idle or otherwise not irrigated | Q8: 0.036017974 | R8: 4 | S8: Not irrigated | T8: Permitted | U8: <Null> | V8: 12 | W8: <Null> | X8: GSF-3207 | Y8: T15S | Z8: R17W | AA8: 26 | AB8: GR | AC8: <Null> | AD8: 01/01/1897 | AF8: 276 | AJ8: 56.503796 | AK8: 145.76015
A9: 8 | B9: GSCG-00008 | C9: GSF | D9: GSCG | E9: MM | F9: <Null> | G9: 45846 | H9: 0.2 | I9: Arizona v California | J9: Gila River | K9: GR | L9: Cliff Gila, Buckhorn-Duck Creek | M9: CG | N9: <Null> | O9: FA | P9: Fallow, idle or otherwise not irrigated | Q9: 0.024374805 | R9: 4 | S9: Not irrigated | T9: Permitted | U9: <Null> | V9: 12 | W9: <Null> | X9: GSF-3207 | Y9: T15S | Z9: R17W | AA9: 26 | AB9: GR | AC9: <Null> | AD9: 01/01/1897 | AF9: 276 | AJ9: 42.003004 | AK9: 98.641732
A10: 9 | B10: GSCG-00009 | C10: GSF | D10: GSCG | E10: MM | F10: <Null> | G10: 45846 | H10: 0.11 | I10: Arizona v California | J10: Gila River | K10: GR | L10: Cliff Gila, Buckhorn-Duck Creek | M10: CG | N10: <Null> | O10: FA | P10: Fallow, idle or otherwise not irrigated | Q10: 0.27958647 | R10: 4 | S10: Not irrigated | T10: Permitted | U10: <Null> | V10: 12 | W10: <Null> | X10: GSF-3207 | Y10: T15S | Z10: R17W | AA10: 26 | AB10: GR | AC10: <Null> | AD10: 01/01/1897 | AF10: 276 | AJ10: 163.62628 | AK10: 1131.4508
A11: 10 | B11: GSCG-00012 | C11: GSF | D11: GSCG | E11: MM | F11: <Null> | G11: 45846 | H11: 2.4 | I11: Arizona v California | J11: Gila River | K11: GR | L11: Cliff Gila, Buckhorn-Duck Creek | M11: CG | O11: FA | P11: Fallow, idle or otherwise not irrigated | Q11: 3.0427458 | R11: 4 | S11: Not irrigated | T11: OSE File No. 0228, Watson-Howard Ditch "Walked in 6/23/2023" | V11: 18 | X11: 0228 | Y11: T14S | Z11: R16W | AA11: 30 | AB11: GR | AD11: 01/01/1897 | AF11: 300 | AJ11: 548.68157 | AK11: 12313.605
A12: 11 | B12: GSCG-00014 | C12: GSF | D12: GSCG | E12: MM | F12: <Null> | G12: 45846 | H12: 19.2 | I12: Arizona v California | J12: Gila River | K12: GR | L12: Cliff Gila, Buckhorn-Duck Creek | M12: CG | O12: FA | P12: Fallow, idle or otherwise not irrigated | Q12: 25.536133 | R12: 4 | S12: Not irrigated | T12: OSE File No. 0228, Watson-Howard Ditch "Walked in 6/23/2023" | V12: 18 | X12: 0228 | Y12: T14S | Z12: R17W | AA12: 25 | AB12: GR | AD12: 01/01/1897 | AF12: 294 | AJ12: 1652.4063 | AK12: 103341.48
A13: 12 | B13: GSCG-00015 | C13: GSF | D13: GSCG | E13: MM | F13: <Null> | G13: 45846 | H13: 0.5 | I13: Arizona v California | J13: Gila River | K13: GR | L13: Cliff Gila, Buckhorn-Duck Creek | M13: CG | O13: FA | P13: Fallow, idle or otherwise not irrigated | Q13: 0.65714797 | R13: 4 | S13: Not irrigated | T13: OSE File No. 0228, Howard Ditch "Walked in 6/23/2023" | V13: 18 | X13: 0228 | Y13: T14S | Z13: R16W | AA13: 30 | AB13: GR | AD13: 01/01/1897 | AF13: 300 | AJ13: 344.69372 | AK13: 2659.3941
A14: 13 | B14: GSCG-00016 | C14: GSF | D14: GSCG | E14: MM | F14: <Null> | G14: 45846 | H14: 4.2 | I14: Arizona v California | J14: Gila River | K14: GR | L14: Cliff Gila, Buckhorn-Duck Creek | M14: CG | O14: FA | P14: Fallow, idle or otherwise not irrigated | Q14: 5.4266853 | R14: 4 | S14: Not irrigated | T14: OSE File No. 0228, Howard Ditch "Walked in 6/23/2023" | V14: 18 | X14: 0228 | Y14: T14S | Z14: R16W | AA14: 30 | AB14: GR | AD14: 01/01/1897 | AF14: 300 | AJ14: 828.00786 | AK14: 21961.104
A15: 14 | B15: GSCG-00017 | C15: GSF | D15: GSCG | E15: MM | F15: <Null> | G15: 45846 | H15: 4 | I15: Arizona v California | J15: Gila River | K15: GR | L15: Cliff Gila, Buckhorn-Duck Creek | M15: CG | O15: FA | P15: Fallow, idle or otherwise not irrigated | Q15: 5.1356692 | R15: 4 | S15: Not irrigated | T15: OSE File No. 0228, Howard Ditch "Walked in 6/23/2023" | V15: 18 | X15: 0228 | Y15: T14S | Z15: R16W | AA15: 30 | AB15: GR | AD15: 01/01/1897 | AF15: 300 | AJ15: 1390.254 | AK15: 20783.399
A16: 15 | B16: GSCG-00018 | C16: GSF | D16: GSCG | E16: MM | F16: <Null> | G16: 45846 | H16: 2.5 | I16: Arizona v California | J16: Gila River | K16: GR | L16: Cliff Gila, Buckhorn-Duck Creek | M16: CG | O16: FA | P16: Fallow, idle or otherwise not irrigated | Q16: 3.304913 | R16: 4 | S16: Not irrigated | T16: OSE File No. 0228, Howard Ditch "Walked in 6/23/2023" | V16: 18 | X16: 0228 | Y16: T14S | Z16: R16W | AA16: 30 | AB16: GR | AD16: 01/01/1897 | AF16: 300 | AJ16: 1370.2881 | AK16: 13374.562
A17: 16 | B17: GSCG-00021 | C17: GSF | D17: GSCG | E17: MM | F17: <Null> | G17: 45846 | H17: 0.3 | I17: Arizona v California | J17: Gila River | K17: GR | L17: Cliff Gila, Buckhorn-Duck Creek | M17: CG | O17: FA | P17: Fallow, idle or otherwise not irrigated | Q17: 0.32083057 | R17: 4 | S17: Not irrigated | T17: OSE File No. 01523-A and 01523-B, Mogollon Creek Ditch "Walked in 6/23/2023" | V17: 18 | X17: 01523-A & 01523-B | Y17: T14S | Z17: R16W | AA17: 30 | AB17: GR | AD17: 1900 | AF17: 338 - 339 | AJ17: 203.50338 | AK17: 1298.3605
A18: 17 | B18: GSCG-00022 | C18: GSF | D18: GSCG | E18: MM | F18: <Null> | G18: 45846 | H18: 7.5 | I18: Arizona v California | J18: Gila River | K18: GR | L18: Cliff Gila, Buckhorn-Duck Creek | M18: CG | O18: FA | P18: Fallow, idle or otherwise not irrigated | Q18: 9.7692074 | R18: 4 | S18: Not irrigated | T18: OSE File No. 01523-A and 01523-B, Mogollon Creek Ditch "Walked in 6/23/2023" | V18: 18 | X18: 01523-A & 01523-B | Y18: T14S | Z18: R16W | AA18: 31 | AB18: GR | AD18: 1900 | AF18: 338 - 339 | AJ18: 1295.0319 | AK18: 39534.738
A19: 18 | B19: GSCG-00024 | C19: GSF | D19: GSCG | E19: MM | F19: <Null> | G19: 45847 | I19: Arizona v California | J19: Gila River | K19: GR | L19: Cliff Gila, Buckhorn-Duck Creek | M19: CG | O19: FA | P19: Fallow, idle or otherwise not irrigated | Q19: 0.86766204 | R19: 4 | S19: Not irrigated | T19: Stock Tank | V19: 24 | X19: Stock Tank | Y19: T14S | Z19: R18W | AA19: 28 | AB19: GR | AJ19: 293.37657 | AK19: 3511.3178
A20: 19 | B20: GSCG-00025 | C20: GSF | D20: GSCG | E20: MM | F20: <Null> | G20: 45846 | H20: 3.9 | I20: Arizona v California | J20: Gila River | K20: GR | L20: Cliff Gila, Buckhorn-Duck Creek | M20: CG | O20: FA | P20: Fallow, idle or otherwise not irrigated | Q20: 5.0530011 | R20: 4 | S20: Not irrigated | T20: OSE File No. 01523-A and 01523-B, Mogollon Creek Ditch "Walked in 6/23/2023" | V20: 18 | X20: 01523-A & 01523-B | Y20: T14S | Z20: R16W | AA20: 31 | AB20: GR | AD20: 1900 | AF20: 338 - 339 | AJ20: 694.24752 | AK20: 20448.852
A21: 20 | B21: GSCG-00026 | C21: GSF | D21: GSCG | E21: MM | F21: <Null> | G21: 45847 | H21: 0.6 | I21: Arizona v California | J21: Gila River | K21: GR | L21: Cliff Gila, Buckhorn-Duck Creek | M21: CG | O21: FA | P21: Fallow, idle or otherwise not irrigated | Q21: 0.52581166 | R21: 4 | S21: Not irrigated | T21: OSE File No. GSF-188 | V21: 24 | X21: GSF-188 | Y21: T14S | Z21: R18W | AA21: 33 | AB21: GR | AJ21: 217.9683 | AK21: 2127.8928
A22: 21 | B22: GSCG-00028 | C22: GSF | D22: GSCG | E22: MM | F22: <Null> | G22: 45847 | H22: 39.55 | I22: Arizona v California | J22: Gila River | K22: GR | L22: Cliff Gila, Buckhorn-Duck Creek | M22: CG | O22: FA | P22: Fallow, idle or otherwise not irrigated | Q22: 35.494901 | R22: 4 | S22: Not irrigated | T22: OSE File No. GSF-47 | V22: 24 | X22: GSF-47 | Y22: T14S | Z22: R18W | AA22: 33 | AB22: GR | AD22: 1941 | AF22: 186 | AJ22: 3091.89 | AK22: 143643.34
A23: 22 | B23: GSCG-00031 | C23: GSF | D23: GSCG | E23: MM | F23: <Null> | G23: 45847 | H23: 1.9 | I23: Arizona v California | J23: Gila River | K23: GR | L23: Cliff Gila, Buckhorn-Duck Creek | M23: CG | O23: FA | P23: Fallow, idle or otherwise not irrigated | Q23: 1.7837423 | R23: 4 | S23: Not irrigated | T23: OSE File No. GSF-47 | V23: 24 | X23: GSF-47 | Y23: T14S | Z23: R18W | AA23: 33 | AB23: GR | AD23: 1941 | AF23: 186 | AJ23: 348.12366 | AK23: 7218.5777
A24: 23 | B24: GSCG-00032 | C24: GSF | D24: GSCG | E24: MM | F24: <Null> | G24: 45847 | H24: 1.6 | I24: Arizona v California | J24: Gila River | K24: GR | L24: Cliff Gila, Buckhorn-Duck Creek | M24: CG | O24: PIC | P24: Pasture (Improved/Planted, Cool Grass) | Q24: 5.1244467 | R24: 1 | S24: Flood irrigated | T24: OSE File No. GSF-59 | V24: 24 | X24: GSF-59 | Y24: T14S | Z24: R18W | AA24: 33 | AB24: GR | AD24: 1951 | AF24: 99 | AJ24: 575.01713 | AK24: 20737.983
A25: 24 | B25: GSCG-00033 | C25: GSF | D25: GSCG | E25: MM | F25: <Null> | G25: 45847 | H25: 0.2 | I25: Arizona v California | J25: Gila River | K25: GR | L25: Cliff Gila, Buckhorn-Duck Creek | M25: CG | O25: RD | P25: Reservoir Dry | Q25: 0.17020365 | S25: <Null> | V25: 24 | X25: GSF-59 | Y25: T14S | Z25: R18W | AA25: 33 | AB25: GR | AD25: 1951 | AF25: 99 | AJ25: 96.278201 | AK25: 688.79251
A26: 25 | B26: GSCG-00037 | C26: GSF | D26: GSCG | E26: MM | F26: <Null> | G26: 45847 | H26: 0.1 | I26: Arizona v California | J26: Gila River | K26: GR | L26: Cliff Gila, Buckhorn-Duck Creek | M26: CG | O26: RD | P26: Reservoir Dry | Q26: 0.14001578 | S26: <Null> | T26: Reservoir | V26: 24 | X26: GSF-47 | Y26: T14S | Z26: R18W | AA26: 33 | AB26: GR | AD26: 1941 | AF26: 186 | AJ26: 93.654056 | AK26: 566.62603
A27: 26 | B27: GSCG-00043 | C27: GSF | D27: GSCG | E27: MM | F27: <Null> | G27: 45847 | H27: 0.4 | I27: Arizona v California | J27: Gila River | K27: GR | L27: Cliff Gila, Buckhorn-Duck Creek | M27: CG | O27: MON | P27: Misc. Outdoor Nursery Stock | Q27: 0.24576532 | R27: 3 | S27: Drip irrigated | T27: OSE File No. GSF-335 | V27: 24 | X27: GSF-335 | Y27: T14S | Z27: R18W | AA27: 33 | AB27: GR | AJ27: 183.81459 | AK27: 994.58094
A28: 27 | B28: GSCG-00050 | C28: GSF | D28: GSCG | E28: MM | F28: <Null> | G28: 45846 | H28: 6.4 | I28: Arizona v California | J28: Gila River | K28: GR | L28: Cliff Gila, Buckhorn-Duck Creek | M28: CG | O28: FA | P28: Fallow, idle or otherwise not irrigated | Q28: 8.2153601 | R28: 4 | S28: Not irrigated | T28: OSE File No. 0229 and 0230, Powell Ditch, 1/2 Duty | V28: 17 | X28: 0229 & 0230 | Y28: T14S | Z28: R16W | AA28: 31 | AB28: GR | AD28: 01/01/1897 | AF28: 257 | AJ28: 765.82106 | AK28: 33246.516
A29: 28 | B29: GSCG-00053 | C29: GSF | D29: GSCG | E29: MM | F29: <Null> | G29: 45847 | I29: Arizona v California | J29: Gila River | K29: GR | L29: Cliff Gila, Buckhorn-Duck Creek | M29: CG | O29: FA | P29: Fallow, idle or otherwise not irrigated | Q29: 5.6398311 | R29: 4 | S29: Not irrigated | V29: 24 | Y29: T14S | Z29: R18W | AA29: 33 | AB29: GR | AJ29: 766.16153 | AK29: 22823.678
A30: 29 | B30: GSCG-00056 | C30: GSF | D30: GSCG | E30: MM | F30: <Null> | G30: 45847 | H30: 1 | I30: Arizona v California | J30: Gila River | K30: GR | L30: Cliff Gila, Buckhorn-Duck Creek | M30: CG | O30: FA | P30: Fallow, idle or otherwise not irrigated | Q30: 0.94358213 | R30: 4 | S30: Not irrigated | T30: OSE File No. GSF-214 | V30: 24 | X30: GSF-214 | Y30: T14S | Z30: R18W | AA30: 33 | AB30: GR | AJ30: 257.46338 | AK30: 3818.5567
A31: 30 | B31: GSCG-00057 | C31: GSF | D31: GSCG | E31: MM | F31: <Null> | G31: 45846 | H31: 5.1 | I31: Arizona v California | J31: Gila River | K31: GR | L31: Cliff Gila, Buckhorn-Duck Creek | M31: CG | O31: FA | P31: Fallow, idle or otherwise not irrigated | Q31: 6.6186053 | R31: 4 | S31: Not irrigated | T31: OSE File No. 0229 and 0230, Powell Ditch, 1/2 Duty | V31: 17 | X31: 0229 & 0230 | Y31: T15S | Z31: R16W | AA31: 6 | AB31: GR | AD31: 01/01/1897 | AF31: 257 | AJ31: 665.53814 | AK31: 26784.653
A32: 31 | B32: GSCG-00059 | C32: GSF | D32: GSCG | E32: MM | F32: <Null> | G32: 45847 | I32: Arizona v California | J32: Gila River | K32: GR | L32: Cliff Gila, Buckhorn-Duck Creek | M32: CG | O32: OUT | P32: Out Areas | Q32: 0.68329814 | S32: <Null> | T32: Out Area | V32: 24 | X32: Out Area | Y32: T14S | Z32: R18W | AA32: 33 | AB32: GR | AJ32: 218.32425 | AK32: 2765.2205
A33: 32 | B33: GSCG-00060 | C33: GSF | D33: GSCG | E33: MM | F33: <Null> | G33: 45846 | H33: 3.7 | I33: Arizona v California | J33: Gila River | K33: GR | L33: Cliff Gila, Buckhorn-Duck Creek | M33: CG | O33: FA | P33: Fallow, idle or otherwise not irrigated | Q33: 4.7653082 | R33: 4 | S33: Not irrigated | T33: OSE File No. 0229 and 0230, Powell Ditch, 1/2 Duty | V33: 17 | X33: 0229 & 0230 | Y33: T15S | Z33: R16W | AA33: 6 | AB33: GR | AD33: 01/01/1897 | AF33: 257 | AJ33: 592.0796 | AK33: 19284.595
A34: 33 | B34: GSCG-00061 | C34: GSF | D34: GSCG | E34: MM | F34: <Null> | G34: 45847 | H34: 0.1 | I34: Arizona v California | J34: Gila River | K34: GR | L34: Cliff Gila, Buckhorn-Duck Creek | M34: CG | O34: FA | P34: Fallow, idle or otherwise not irrigated | Q34: 0.050352509 | R34: 4 | S34: Not irrigated | T34: OSE File No. GSF-125 | V34: 24 | X34: GSF-125 | Y34: T14S | Z34: R18W | AA34: 33 | AB34: GR | AJ34: 55.624825 | AK34: 203.77019
A35: 34 | B35: GSCG-00062 | C35: GSF | D35: GSCG | E35: MM | F35: <Null> | G35: 45846 | H35: 3.3 | I35: Arizona v California | J35: Gila River | K35: GR | L35: Cliff Gila, Buckhorn-Duck Creek | M35: CG | O35: FA | P35: Fallow, idle or otherwise not irrigated | Q35: 4.1797468 | R35: 4 | S35: Not irrigated | T35: OSE File No. 0229 and 0230, Powell Ditch, 1/2 Duty | V35: 17 | X35: 0229 & 0230 | Y35: T15S | Z35: R16W | AA35: 6 | AB35: GR | AD35: 01/01/1897 | AF35: 257 | AJ35: 718.45036 | AK35: 16914.903
A36: 36 | B36: GSCG-00070 | C36: GSF | D36: GSCG | E36: MM | F36: <Null> | G36: 45847 | H36: 1.4 | I36: Arizona v California | J36: Gila River | K36: GR | L36: Cliff Gila, Buckhorn-Duck Creek | M36: CG | O36: FA | P36: Fallow, idle or otherwise not irrigated | Q36: 1.3326672 | R36: 4 | S36: Not irrigated | T36: OSE File No. GSF-161 | V36: 23 | X36: GSF-161 | Y36: T15S | Z36: R18W | AA36: 4 | AB36: GR | AD36: 1957 | AF36: 345 | AJ36: 335.02385 | AK36: 5393.1344
A37: 37 | B37: GSCG-00071 | C37: GSF | D37: GSCG | E37: MM | F37: <Null> | G37: 45847 | H37: 3.5 | I37: Arizona v California | J37: Gila River | K37: GR | L37: Cliff Gila, Buckhorn-Duck Creek | M37: CG | O37: FA | P37: Fallow, idle or otherwise not irrigated | Q37: 2.5899614 | R37: 4 | S37: Not irrigated | T37: OSE File No. GSF-161-A | V37: 23 | X37: GSF-161-A | Y37: T15S | Z37: R18W | AA37: 4 | AB37: GR | AJ37: 550.47416 | AK37: 10481.244
A38: 38 | B38: GSCG-00076 | C38: GSF | D38: GSCG | E38: MM | F38: <Null> | G38: 45869 | H38: 3.8 | I38: Arizona v California | J38: Gila River | K38: GR | L38: Cliff Gila, Buckhorn-Duck Creek | M38: CG | O38: OUT | P38: Out Areas | Q38: 2.500413 | S38: <Null> | T38: No Right | V38: 23 | X38: GSF-51 & GSF-52 | Y38: T15S | Z38: R18W | AA38: 3 | AB38: GR | AF38: 257 | AJ38: 443.39077 | AK38: 10118.853
A39: 39 | B39: GSCG-00077 | C39: GSF | D39: GSCG | E39: MM | F39: <Null> | G39: 45846 | H39: 0.5 | I39: Arizona v California | J39: Gila River | K39: GR | L39: Cliff Gila, Buckhorn-Duck Creek | M39: CG | O39: ONG | P39: Orchard (no ground cover) | Q39: 0.69188661 | R39: 3 | S39: Drip irrigated | T39: Watered form domestic well | V39: 17 | X39: GSF-1930 | Y39: T15S | Z39: R16W | AA39: 6 | AB39: GR | AD39: 1907 | AJ39: 215.18765 | AK39: 2799.977
A40: 40 | B40: GSCG-00078 | C40: GSF | D40: GSCG | E40: MM | F40: <Null> | G40: 45847 | H40: 0.5 | I40: Arizona v California | J40: Gila River | K40: GR | L40: Cliff Gila, Buckhorn-Duck Creek | M40: CG | O40: FA | P40: Fallow, idle or otherwise not irrigated | Q40: 0.40488685 | R40: 4 | S40: Not irrigated | T40: OSE File No. GSF-81 | V40: 23 | X40: GSF-81 | Y40: T15S | Z40: R18W | AA40: 4 | AB40: GR | AJ40: 187.86668 | AK40: 1638.5255
...

Sheet GSGW_IA_2025
A1: OBJECTID | B1: Field_ID | C1: Basin | D1: Sub_Basin | E1: Inspector_1 | F1: Inspector_2 | G1: Inspection_Date | H1: Water_Righted_Acreage | I1: Decree | J1: System | K1: SysCode | L1: Unit | M1: UCode | N1: Ditch | O1: Crop_Code | P1: Crop_Type | Q1: Computed_Acreage | R1: Irr_Code | S1: Irr_Method | T1: Remarks | U1: Season | V1: Mapsheet | W1: Sections | X1: File_nbr | Y1: Tws | Z1: Rng | AA1: Sec | AB1: County | AC1: Owner | AD1: Priority | AE1: Subfile | AF1: No_Adjudicated_Water_Right | AG1: PLSS QQQ | AH1: Pla_rec_nbr | AI1: Shape_Length | AJ1: Shape_Area
A2: 1 | B2: GCGW-00001 | C2: GSF | D2: GSGW | E2: MM | G2: 45854 | H2: 1 | I2: Arizona v California | J2: San Francisco River | K2: SF | L2: Glenwood-Mule Creek | M2: GL | O2: FA | P2: Fallow, idle or otherwise not irrigated | Q2: 1.0783296 | R2: 4 | S2: Not irrigated | T2: OSE File No. GSF-3579 | V2: 13 | X2: GSF-3579 | Y2: 11S | Z2: 19W | AA2: 6 | AB2: CA | AD2: 05/10/1898 | AE2: 90 | AI2: 265.50779 | AJ2: 4363.8626
A3: 2 | B3: GCGW-00002 | C3: GSF | D3: GSGW | E3: MM | G3: 45854 | H3: 0.5 | I3: Arizona v California | J3: San Francisco River | K3: SF | L3: Glenwood-Mule Creek | M3: GL | O3: OUT | P3: Out Areas | Q3: 0.54497112 | S3: <Null> | T3: OSE File No. 01446, Spurgeon Ditch #1, Locked Gate, Not Observed | V3: 10 | X3: 01446 | Y3: 10S | Z3: 20W | AA3: 9 | AB3: CA | AD3: 1890 | AE3: 45 | AI3: 198.00928 | AJ3: 2205.4287
A4: 3 | B4: GCGW-00003 | C4: GSF | D4: GSGW | E4: MM | G4: 45854 | H4: 1.5 | I4: Arizona v California | J4: San Francisco River | K4: SF | L4: Glenwood-Mule Creek | M4: GL | O4: OUT | P4: Out Areas | Q4: 1.508777 | S4: <Null> | T4: OSE File No. 01446, Spurgeon Ditch #1, Locked Gate, Not Observed | V4: 10 | X4: 01446 | Y4: 10S | Z4: 20W | AA4: 9 | AB4: CA | AD4: 1890 | AE4: 45 | AI4: 367.6385 | AJ4: 6105.8284
A5: 4 | B5: GCGW-00004 | C5: GSF | D5: GSGW | E5: MM | G5: 45854 | H5: 4 | I5: Arizona v California | J5: San Francisco River | K5: SF | L5: Glenwood-Mule Creek | M5: GL | O5: OUT | P5: Out Areas | Q5: 4.0858073 | S5: <Null> | T5: OSE File No. 01446, Spurgeon Ditch #1, Locked Gate, Not Observed | V5: 10 | X5: 01446 | Y5: 10S | Z5: 20W | AA5: 9 | AB5: CA | AD5: 1890 | AE5: 45 | AI5: 617.89746 | AJ5: 16534.742
A6: 5 | B6: GCGW-00005 | C6: GSF | D6: GSGW | E6: MM | G6: 45854 | H6: 1 | I6: Arizona v California | J6: San Francisco River | K6: SF | L6: Glenwood-Mule Creek | M6: GL | O6: OUT | P6: Out Areas | Q6: 1.0835185 | S6: <Null> | T6: OSE File No. 01446, Spurgeon Ditch #1, Locked Gate, Not Observed | V6: 10 | X6: 01446 | Y6: 10S | Z6: 20W | AA6: 8 | AB6: CA | AD6: 1890 | AE6: 45 | AI6: 296.76019 | AJ6: 4384.8612
A7: 6 | B7: GCGW-00006 | C7: GSF | D7: GSGW | E7: MM | G7: 45854 | H7: 0.5 | I7: Arizona v California | J7: San Francisco River | K7: SF | L7: Glenwood-Mule Creek | M7: GL | N7: Spurgeon No. 2 Ditch | O7: FA | P7: Fallow, idle or otherwise not irrigated | Q7: 0.53727772 | R7: 4 | S7: Not irrigated | T7: OSE File No. 01446, Spurgeon Ditch #2 | V7: 9 | X7: 01446 | Y7: 10S | Z7: 20W | AA7: 17 | AB7: CA | AD7: 1890 | AE7: 45 | AI7: 190.584 | AJ7: 2174.2945
A8: 7 | B8: GCGW-00007 | C8: GSF | D8: GSGW | E8: MM | G8: 45854 | H8: 0.2 | I8: Arizona v California | J8: San Francisco River | K8: SF | L8: Glenwood-Mule Creek | M8: GL | N8: Spurgeon No. 2 Ditch | O8: FA | P8: Fallow, idle or otherwise not irrigated | Q8: 0.19506563 | R8: 4 | S8: Not irrigated | T8: OSE File No. 01446, Spurgeon Ditch #2 | V8: 9 | X8: 01446 | Y8: 10S | Z8: 20W | AA8: 17 | AB8: CA | AD8: 1890 | AE8: 45 | AI8: 112.41178 | AJ8: 789.40577
A9: 8 | B9: GCGW-00009 | C9: GSF | D9: GSGW | E9: MM | G9: 45854 | H9: 3.8 | I9: Arizona v California | J9: San Francisco River | K9: SF | L9: Glenwood-Mule Creek | M9: GL | O9: WSG | P9: Winter Small Grains | Q9: 1.9538681 | R9: 1 | S9: Flood irrigated | T9: Early Spring Crop - OSE File No. 01454, Spurgeon Ditch #2 | V9: 9 | X9: 01454 | Y9: 10S | Z9: 20W | AA9: 17 | AD9: 1885 | AE9: 132 | AI9: 702.01522 | AJ9: 7907.0552
A10: 9 | B10: GCGW-00011 | C10: GSF | D10: GSGW | E10: MM | G10: 45854 | H10: 3.6 | I10: Arizona v California | J10: San Francisco River | K10: SF | L10: Glenwood-Mule Creek | M10: GL | O10: FA | P10: Fallow, idle or otherwise not irrigated | Q10: 3.6299167 | R10: 4 | S10: Not irrigated | T10: OSE File No. 01454, Spurgeon Ditch #3 | V10: 9 | X10: 01454 | Y10: 10S | Z10: 20W | AA10: 17 | AB10: CA | AD10: 1885 | AE10: 132 | AI10: 591.17159 | AJ10: 14689.811
A11: 10 | B11: GCGW-00012 | C11: GSF | D11: GSGW | E11: MM | G11: 45854 | H11: 0.2 | I11: Arizona v California | J11: San Francisco River | K11: SF | L11: Glenwood-Mule Creek | M11: GL | N11: Spurgeon No. 2 Ditch | P11: Pasture (improved/Planted, Warm Grass) | Q11: 0.24193177 | R11: 1 | S11: Flood irrigated | T11: OSE File No. 01454, Spurgeon Ditch #2 | V11: 9 | X11: 01454 | Y11: 10S | Z11: 20W | AA11: 17 | AB11: CA | AD11: 1885 | AE11: 132 | AI11: 149.55342 | AJ11: 979.06705
A12: 11 | B12: GCGW-00013 | C12: GSF | D12: GSGW | E12: MM | G12: 45854 | H12: 0.3 | I12: Arizona v California | J12: San Francisco River | K12: SF | L12: Glenwood-Mule Creek | M12: GL | N12: Spurgeon No. 2 Ditch | P12: Pasture (improved/Planted, Warm Grass) | Q12: 0.25141703 | R12: 1 | S12: Flood irrigated | T12: OSE File No. 01454, Spurgeon Ditch #2 | V12: 9 | X12: 01454 | Y12: 10S | Z12: 20W | AB12: CA | AD12: 1885 | AE12: 132 | AI12: 150.83296 | AJ12: 1017.4527
A13: 12 | B13: GCGW-00014 | C13: GSF | D13: GSGW | E13: MM | G13: 45854 | H13: 0.5 | I13: Arizona v California | J13: San Francisco River | K13: SF | L13: Glenwood-Mule Creek | M13: GL | N13: Spurgeon No. 2 Ditch | P13: Pasture (improved/Planted, Warm Grass) | Q13: 0.49526102 | R13: 1 | S13: Flood irrigated | T13: OSE File No. 01454, Spurgeon Ditch #2 | V13: 9 | X13: 01454 | Y13: 10S | Z13: 20W | AB13: CA | AD13: 1885 | AE13: 132 | AI13: 176.1997 | AJ13: 2004.2583
A14: 13 | B14: GCGW-00016 | C14: GSF | D14: GSGW | E14: MM | G14: 45854 | H14: 16.9 | I14: Arizona v California | J14: San Francisco River | K14: SF | L14: Glenwood-Mule Creek | M14: GL | N14: Spurgeon No. 2 Ditch | O14: PN | P14: Pasture (Native) | Q14: 22.087763 | R14: 1 | S14: Flood irrigated | T14: OSE File No. 01454, Spurgeon Ditch #2 | V14: 8 | X14: 01454 | Y14: 10S | Z14: 20W | AA14: 17 | AB14: CA | AD14: 1885 | AE14: 133 | AI14: 1260.2077 | AJ14: 89386.365
A15: 14 | B15: GCGW-00018 | C15: GSF | D15: GSGW | E15: MM | G15: 45854 | H15: 2.8 | I15: Arizona v California | J15: San Francisco River | K15: SF | L15: Glenwood-Mule Creek | M15: GL | N15: Spurgeon No. 2 Ditch | O15: PN | P15: Pasture (Native) | Q15: 2.8965115 | R15: 1 | S15: Flood irrigated | T15: OSE File No. 01454, Spurgeon Ditch #2 | V15: 8 | X15: 01454 | Y15: 10S | Z15: 20W | AA15: 17 | AB15: CA | AD15: 1885 | AE15: 133 | AI15: 458.87305 | AJ15: 11721.813
A16: 15 | B16: GCGW-00019 | C16: GSF | D16: GSGW | E16: MM | G16: 45854 | H16: 0.3 | I16: Arizona v California | J16: San Francisco River | K16: SF | L16: Glenwood-Mule Creek | M16: GL | N16: Spurgeon No. 2 Ditch | O16: PN | P16: Pasture (Native) | Q16: 0.25943572 | R16: 1 | S16: Flood irrigated | T16: OSE File No. 01454, Spurgeon Ditch #2 | V16: 8 | X16: 01454 | Y16: 10S | Z16: 20W | AA16: 17 | AB16: CA | AD16: 1885 | AE16: 133 | AI16: 159.81613 | AJ16: 1049.9033
A17: 16 | B17: GCGW-00020 | C17: GSF | D17: GSGW | E17: MM | G17: 45854 | H17: 0.1 | I17: Arizona v California | J17: San Francisco River | K17: SF | L17: Glenwood-Mule Creek | M17: GL | N17: Spurgeon No. 2 Ditch | O17: PN | P17: Pasture (Native) | Q17: 0.16993581 | R17: 1 | S17: Flood irrigated | T17: OSE File No. 01454, Spurgeon Ditch #2 | V17: 8 | X17: 01454 | Y17: 10S | Z17: 20W | AA17: 17 | AB17: CA | AD17: 1885 | AE17: 133 | AI17: 111.26594 | AJ17: 687.70858
A18: 17 | B18: GCGW-00021 | C18: GSF | D18: GSGW | E18: MM | G18: 45854 | H18: 1.7 | I18: Arizona v California | J18: San Francisco River | K18: SF | L18: Glenwood-Mule Creek | M18: GL | N18: Spurgeon No. 2 Ditch | O18: PN | P18: Pasture (Native) | Q18: 1.4303908 | R18: 1 | S18: Flood irrigated | T18: OSE File No. 01454, Spurgeon Ditch #2 | V18: 8 | X18: 01454 | Y18: 10S | Z18: 20W | AA18: 20 | AB18: CA | AD18: 1885 | AE18: 133 | AI18: 458.77296 | AJ18: 5788.6092
A19: 18 | B19: GCGW-00022 | C19: GSF | D19: GSGW | E19: MM | G19: 45854 | H19: 0.4 | I19: Arizona v California | J19: San Francisco River | K19: SF | L19: Glenwood-Mule Creek | M19: GL | N19: Spurgeon No. 2 Ditch | O19: PN | P19: Pasture (Native) | Q19: 1.4305235 | R19: 1 | S19: Flood irrigated | T19: OSE File No. 01454, Spurgeon Ditch #2 | V19: 8 | X19: 01454 | Y19: 10S | Z19: 20W | AA19: 20 | AB19: CA | AD19: 1885 | AE19: 133 | AI19: 419.37493 | AJ19: 5789.1463
A20: 19 | B20: GCGW-00023 | C20: GSF | D20: GSGW | E20: MM | G20: 45854 | H20: 2.9 | I20: Arizona v California | J20: San Francisco River | K20: SF | L20: Glenwood-Mule Creek | M20: GL | N20: Spurgeon No. 2 Ditch | O20: OUT | P20: Out Areas | Q20: 2.7245383 | S20: <Null> | T20: OSE File No. 01454, Spurgeon Ditch #2 | V20: 8 | X20: 01454 | Y20: 10S | Z20: 20W | AA20: 20 | AB20: CA | AD20: 1885 | AE20: 45 | AI20: 475.78079 | AJ20: 11025.859
A21: 20 | B21: GCGW-00024 | C21: GSF | D21: GSGW | E21: MM | G21: 45854 | H21: 2.1 | I21: Arizona v California | J21: San Francisco River | K21: SF | L21: Glenwood-Mule Creek | M21: GL | N21: Thomason Flat Ditch | O21: PN | P21: Pasture (Native) | Q21: 2.1813364 | R21: 1 | S21: Flood irrigated | T21: OSE File No. 01446, Thomason Flat Ditch | V21: 8 | X21: 01446 | Y21: 10S | Z21: 20W | AA21: 20 | AB21: CA | AD21: 1890 | AE21: 45 | AI21: 386.70968 | AJ21: 8827.5903
A22: 21 | B22: GCGW-00025 | C22: GSF | D22: GSGW | E22: MM | G22: 45854 | H22: 0.4 | I22: Arizona v California | J22: San Francisco River | K22: SF | L22: Glenwood-Mule Creek | M22: GL | N22: Thomason Flat Ditch | O22: PN | P22: Pasture (Native) | Q22: 0.33745601 | R22: 1 | S22: Flood irrigated | T22: OSE File No. 01446, Thomason Flat Ditch | V22: 8 | X22: 01446 | Y22: 10S | Z22: 20W | AA22: 20 | AB22: CA | AD22: 1890 | AE22: 45 | AI22: 217.43879 | AJ22: 1365.6415
A23: 22 | B23: GCGW-00026 | C23: GSF | D23: GSGW | E23: MM | G23: 45854 | H23: 1 | I23: Arizona v California | J23: San Francisco River | K23: SF | L23: Glenwood-Mule Creek | M23: GL | N23: Thomason Flat Ditch | O23: PN | P23: Pasture (Native) | Q23: 1.050243 | R23: 1 | S23: Flood irrigated | T23: OSE File No. 01446, Thomason Flat Ditch | V23: 8 | X23: 01446 | Y23: 10S | Z23: 20W | AA23: 19 | AB23: CA | AD23: 1890 | AE23: 45 | AI23: 287.48955 | AJ23: 4250.1996
A24: 23 | B24: GCGW-00027 | C24: GSF | D24: GSGW | E24: MM | G24: 45854 | H24: 17.8 | I24: Arizona v California | J24: San Francisco River | K24: SF | L24: Glenwood-Mule Creek | M24: GL | N24: Thomason Flat Ditch | O24: PN | P24: Pasture (Native) | Q24: 18.093655 | R24: 1 | S24: Flood irrigated | T24: OSE File No. 01446, Thomason Flat Ditch | V24: 8 | X24: 01446 | Y24: 10S | Z24: 20W | AA24: 20 | AB24: CA | AD24: 1890 | AE24: 45 | AI24: 1400.0981 | AJ24: 73222.715
A25: 24 | B25: GCGW-00028 | C25: GSF | D25: GSGW | E25: MM | G25: 45854 | H25: 0.1 | I25: Arizona v California | J25: San Francisco River | K25: SF | L25: Glenwood-Mule Creek | M25: GL | N25: Thomason Flat Ditch | O25: PN | P25: Pasture (Native) | Q25: 0.12266612 | R25: 1 | S25: Flood irrigated | T25: OSE File No. 01446, Thomason Flat Ditch | V25: 8 | X25: 01446 | Y25: 10S | Z25: 20W | AA25: 20 | AB25: CA | AD25: 1890 | AE25: 45 | AI25: 114.93407 | AJ25: 496.41417
A26: 25 | B26: GCGW-00029 | C26: GSF | D26: GSGW | E26: MM | G26: 45854 | H26: 0.9 | I26: Arizona v California | J26: San Francisco River | K26: SF | L26: Glenwood-Mule Creek | M26: GL | N26: Thomason Flat Ditch | O26: PN | P26: Pasture (Native) | Q26: 0.86514301 | R26: 1 | S26: Flood irrigated | T26: OSE File No. 01446, Thomason Flat Ditch | V26: 8 | X26: 01446 | Y26: 10S | Z26: 20W | AA26: 19 | AB26: CA | AD26: 1890 | AE26: 45 | AI26: 243.05507 | AJ26: 3501.1236
A27: 26 | B27: GCGW-00030 | C27: GSF | D27: GSGW | E27: MM | G27: 45854 | H27: 5.3 | I27: Arizona v California | J27: San Francisco River | K27: SF | L27: Glenwood-Mule Creek | M27: GL | N27: Thomason Flat Ditch | O27: PN | P27: Pasture (Native) | Q27: 5.3357688 | R27: 1 | S27: Flood irrigated | T27: OSE File No. 01446, Thomason Flat Ditch | V27: 8 | X27: 01446 | Y27: 10S | Z27: 20W | AA27: 19 | AB27: CA | AD27: 1890 | AE27: 45 | AI27: 765.81521 | AJ27: 21593.177
A28: 27 | B28: GCGW-00031 | C28: GSF | D28: GSGW | E28: MM | G28: 45854 | H28: 8.8 | I28: Arizona v California | J28: San Francisco River | K28: SF | L28: Glenwood-Mule Creek | M28: GL | N28: Thomason Flat Ditch | O28: PN | P28: Pasture (Native) | Q28: 9.0050345 | R28: 1 | S28: Flood irrigated | T28: OSE File No. 01446, Thomason Flat Ditch | V28: 8 | X28: 01446 | Y28: 10S | Z28: 20W | AA28: 19 | AB28: CA | AD28: 1890 | AE28: 45 | AI28: 869.01862 | AJ28: 36442.228
A29: 28 | B29: GCGW-00032 | C29: GSF | D29: GSGW | E29: MM | G29: 45854 | H29: 1 | I29: Arizona v California | J29: San Francisco River | K29: SF | L29: Glenwood-Mule Creek | M29: GL | N29: Thomason Flat Ditch | O29: PN | P29: Pasture (Native) | Q29: 0.95408873 | R29: 1 | S29: Flood irrigated | T29: OSE File No. 01446, Thomason Flat Ditch | V29: 8 | X29: 01446 | Y29: 10S | Z29: 20W | AA29: 20 | AB29: CA | AD29: 1890 | AE29: 45 | AI29: 269.32391 | AJ29: 3861.0755
A30: 29 | B30: GCGW-00033 | C30: GSF | D30: GSGW | E30: MM | G30: 45854 | H30: 2.3 | I30: Arizona v California | J30: San Francisco River | K30: SF | L30: Glenwood-Mule Creek | M30: GL | N30: Thomason Flat Ditch | O30: PN | P30: Pasture (Native) | Q30: 2.3381289 | R30: 1 | S30: Flood irrigated | T30: OSE File No. 01446, Thomason Flat Ditch | V30: 8 | X30: 01446 | Y30: 10S | Z30: 20W | AA30: 19 | AB30: CA | AD30: 1890 | AE30: 45 | AI30: 412.26278 | AJ30: 9462.1097
A31: 30 | B31: GCGW-00034 | C31: GSF | D31: GSGW | E31: MM | G31: 45854 | H31: 1.6 | I31: Arizona v California | J31: San Francisco River | K31: SF | L31: Glenwood-Mule Creek | M31: GL | N31: Thomason Flat Ditch | O31: PN | P31: Pasture (Native) | Q31: 1.6185631 | R31: 1 | S31: Flood irrigated | T31: OSE File No. 01446, Thomason Flat Ditch | V31: 8 | X31: 01446 | Y31: 10S | Z31: 20W | AA31: 20 | AB31: CA | AD31: 1890 | AE31: 45 | AI31: 337.09381 | AJ31: 6550.1185
A32: 31 | B32: GCGW-00035 | C32: GSF | D32: GSGW | E32: MM | G32: 45854 | H32: 0.5 | I32: Arizona v California | J32: San Francisco River | K32: SF | L32: Glenwood-Mule Creek | M32: GL | N32: Thomason Flat Ditch | O32: PN | P32: Pasture (Native) | Q32: 0.46842338 | R32: 1 | S32: Flood irrigated | T32: OSE File No. 01446, Thomason Flat Ditch | V32: 8 | X32: 01446 | Y32: 10S | Z32: 20W | AA32: 19 | AB32: CA | AD32: 1890 | AE32: 45 | AI32: 285.81967 | AJ32: 1895.6498
A33: 32 | B33: GCGW-00036 | C33: GSF | D33: GSGW | E33: MM | G33: 45854 | H33: 3.7 | I33: Arizona v California | J33: San Francisco River | K33: SF | L33: Glenwood-Mule Creek | M33: GL | N33: Thomason Flat Ditch | O33: PN | P33: Pasture (Native) | Q33: 3.7352818 | R33: 1 | S33: Flood irrigated | T33: OSE File No. 01446, Thomason Flat Ditch | V33: 8 | X33: 01446 | Y33: 10S | Z33: 20W | AA33: 19 | AB33: CA | AD33: 1890 | AE33: 45 | AI33: 484.94922 | AJ33: 15116.209
A34: 33 | B34: GCGW-00039 | C34: GSF | D34: GSGW | E34: MM | G34: 45854 | H34: 2.6 | I34: Arizona v California | J34: San Francisco River | K34: SF | L34: Glenwood-Mule Creek | M34: GL | O34: FA | P34: Fallow, idle or otherwise not irrigated | Q34: 2.4347979 | R34: 4 | S34: Not irrigated | T34: OSE File No. 01906, Private Ditch | V34: 16 | X34: 01906 | Y34: 10S | Z34: 19W | AA34: 30 | AB34: CA | AD34: 1884 | AE34: 46 | AI34: 479.03033 | AJ34: 9853.3171
A35: 34 | B35: GCGW-00040 | C35: GSF | D35: GSGW | E35: MM | G35: 45854 | H35: 0.8 | I35: Arizona v California | J35: San Francisco River | K35: SF | L35: Glenwood-Mule Creek | M35: GL | O35: RD | P35: Reservoir Dry | Q35: 0.32878503 | T35: OSE File No. 01906, Private Ditch, Reservoir, Dry | V35: 16 | X35: 01906 | Y35: 10S | Z35: 19W | AA35: 30 | AB35: CA | AD35: 1884 | AE35: 46 | AI35: 136.27205 | AJ35: 1330.5511
A36: 35 | B36: GCGW-00041 | C36: GSF | D36: GSGW | E36: MM | G36: 45854 | H36: 2.7 | I36: Arizona v California | J36: San Francisco River | K36: SF | L36: Glenwood-Mule Creek | M36: GL | O36: FA | P36: Fallow, idle or otherwise not irrigated | Q36: 2.4522216 | R36: 4 | S36: Not irrigated | T36: OSE File No. 01906, Private Ditch | V36: 16 | X36: 01906 | Y36: 10S | Z36: 19W | AA36: 30 | AB36: CA | AD36: 1884 | AE36: 46 | AI36: 457.69362 | AJ36: 9923.8282
A37: 36 | B37: GCGW-00044 | C37: GSF | D37: GSGW | E37: MM | G37: 45854 | H37: 0.2 | I37: Arizona v California | J37: San Francisco River | K37: SF | L37: Glenwood-Mule Creek | M37: GL | O37: FA | P37: Fallow, idle or otherwise not irrigated | Q37: 0.17551411 | R37: 4 | S37: Not irrigated | T37: OSE File No. 01906, Private Ditch | V37: 16 | X37: 01906 | Y37: 10S | Z37: 19W | AA37: 30 | AB37: CA | AD37: 1884 | AE37: 46 | AI37: 115.8066 | AJ37: 710.28325
A38: 37 | B38: GCGW-00045 | C38: GSF | D38: GSGW | E38: MM | G38: 45854 | H38: 0.2 | I38: Arizona v California | J38: San Francisco River | K38: SF | L38: Glenwood-Mule Creek | M38: GL | O38: FA | P38: Fallow, idle or otherwise not irrigated | Q38: 0.11990793 | R38: 4 | S38: Not irrigated | T38: OSE File No. 01906, Private Ditch | V38: 16 | X38: 01906 | Y38: 10S | Z38: 19W | AA38: 30 | AB38: CA | AD38: 1884 | AE38: 46 | AI38: 111.45358 | AJ38: 485.25211
A39: 38 | B39: GCGW-00046 | C39: GSF | D39: GSGW | E39: MM | G39: 45854 | H39: 0.2 | I39: Arizona v California | J39: San Francisco River | K39: SF | L39: Glenwood-Mule Creek | M39: GL | O39: FA | P39: Fallow, idle or otherwise not irrigated | Q39: 0.15972359 | R39: 4 | S39: Not irrigated | T39: OSE File No. 01906, Private Ditch | V39: 16 | X39: 01906 | Y39: 10S | Z39: 19W | AA39: 30 | AB39: CA | AD39: 1884 | AE39: 46 | AI39: 103.56864 | AJ39: 646.381
A40: 39 | B40: GCGW-00047 | C40: GSF | D40: GSGW | E40: MM | G40: 45854 | H40: 4.8 | I40: Arizona v California | J40: San Francisco River | K40: SF | L40: Glenwood-Mule Creek | M40: GL | O40: FA | P40: Fallow, idle or otherwise not irrigated | Q40: 4.4194285 | R40: 4 | S40: Not irrigated | T40: OSE File No. 01906, Private Ditch | V40: 16 | X40: 01906 | Y40: 10S | Z40: 19W | AA40: 30 | AB40: CA | AD40: 1884 | AE40: 46 | AI40: 522.34473 | AJ40: 17884.864
...

Sheet GSLU_IA_2025
A1: OBJECTID | B1: Field_ID | C1: Basin | D1: Sub_Basin | E1: Inspector_1 | F1: Inspector_2 | G1: Inspection_Date | H1: Water_Righted_Acreage | I1: Decree | J1: System | K1: SysCode | L1: Unit | M1: UCode | N1: Ditch | O1: Crop_Code | P1: Crop_Type | Q1: Computed_Acreage | R1: Irr_Code | S1: Irr_Method | T1: Remarks | U1: Season | V1: Mapsheet | W1: Sections | X1: File_nbr | Y1: Tws | Z1: Rng | AA1: Sec | AB1: County | AC1: Owner | AD1: Priority | AE1: Subfile | AF1: No_Adjudicated_Water_Right | AG1: PLSS QQQ | AH1: Pla_rec_nbr | AI1: Shape_Length | AJ1: Shape_Area
A2: 1 | B2: GSLU-00001 | C2: GSF | D2: GSLU | E2: MM | G2: 45861 | H2: 23.611029 | I2: Arizona v California | J2: San Francisco River | K2: SF | L2: Luna | M2: LU | O2: OUT | P2: Out Areas | Q2: 23.611029 | R2: 0 | S2: <Null> | T2: No Right, Dry Farm | V2: 7 | W2: 11, 10 | X2: No Right | Y2: T5S | Z2: R20W | AA2: 11 | AB2: CA | AC2: Herbert Bastion | AI2: 1385.2307 | AJ2: 95550.826
A3: 2 | B3: GSLU-00002 | C3: GSF | D3: GSLU | E3: MM | G3: 45861 | H3: 2.2703548 | I3: Arizona v California | J3: San Francisco River | K3: SF | L3: Luna | M3: LU | O3: OUT | P3: Out Areas | Q3: 2.2703548 | R3: 0 | S3: <Null> | T3: No Right, Dry Farm | V3: 8 | X3: No Right | Y3: T5S | Z3: R20W | AA3: 15 | AB3: CA | AI3: 427.84416 | AJ3: 9187.8365
A4: 3 | B4: GSLU-00003 | C4: GSF | D4: GSLU | E4: MM | G4: 45861 | H4: 5.3737736 | I4: Arizona v California | J4: San Francisco River | K4: SF | L4: Luna | M4: LU | O4: PN | P4: Pasture (Native) | Q4: 5.3737736 | R4: 1 | S4: Flood irrigated | T4: OSE File No. 01098, William S Laney Ditch | V4: 9 | X4: 01098 | Y4: T5S | Z4: R20W | AA4: 24 | AB4: CA | AC4: Randolph Jenks | AD4: 1894 | AE4: 432 | AI4: 926.59137 | AJ4: 21746.977
A5: 4 | B5: GSLU-00004 | C5: GSF | D5: GSLU | E5: MM | G5: 45861 | H5: 3.7481711 | I5: Arizona v California | J5: San Francisco River | K5: SF | L5: Luna | M5: LU | O5: PN | P5: Pasture (Native) | Q5: 3.7481711 | R5: 1 | S5: Flood irrigated | T5: OSE File No. 01098, William S Laney Ditch | V5: 9 | X5: 01098 | Y5: T5S | Z5: R20W | AA5: 24 | AB5: CA | AC5: Randolph Jenks | AD5: 1894 | AE5: 432 | AI5: 578.57502 | AJ5: 15168.371
A6: 5 | B6: GSLU-00005 | C6: GSF | D6: GSLU | E6: MM | G6: 45861 | H6: 1.1742685 | I6: Arizona v California | J6: San Francisco River | K6: SF | L6: Luna | M6: LU | O6: PN | P6: Pasture (Native) | Q6: 1.1742685 | R6: 1 | S6: Flood irrigated | T6: OSE File No. 01098, William S Laney Ditch | V6: 9 | X6: 01098 | Y6: T5S | Z6: R20W | AA6: 24 | AB6: CA | AC6: Randolph Jenks | AD6: 1894 | AE6: 432 | AI6: 314.5869 | AJ6: 4752.1149
A7: 6 | B7: GSLU-00006 | C7: GSF | D7: GSLU | E7: MM | G7: 45861 | H7: 3.6047351 | I7: Arizona v California | J7: San Francisco River | K7: SF | L7: Luna | M7: LU | O7: PN | P7: Pasture (Native) | Q7: 3.6047351 | R7: 1 | S7: Flood irrigated | T7: OSE File No. 01098, William S Laney Ditch | V7: 9 | X7: 01098 | Y7: T5S | Z7: R20W | AA7: 24 | AB7: CA | AC7: Randolph Jenks | AD7: 1894 | AE7: 432 | AI7: 535.16624 | AJ7: 14587.904
A8: 7 | B8: GSLU-00007 | C8: GSF | D8: GSLU | E8: MM | G8: 45861 | H8: 1.4092835 | I8: Arizona v California | J8: San Francisco River | K8: SF | L8: Luna | M8: LU | O8: PN | P8: Pasture (Native) | Q8: 1.4092835 | R8: 1 | S8: Flood irrigated | T8: OSE File No. 01098, William S Laney Ditch | V8: 9 | X8: 01098 | Y8: T5S | Z8: R20W | AA8: 24 | AB8: CA | AC8: Randolph Jenks | AD8: 1892 | AE8: 430 | AI8: 324.6593 | AJ8: 5703.1907
A9: 8 | B9: GSLU-00008 | C9: GSF | D9: GSLU | E9: MM | G9: 45861 | H9: 0.85459799 | I9: Arizona v California | J9: San Francisco River | K9: SF | L9: Luna | M9: LU | O9: STD | P9: Stock Rank, Dry | Q9: 0.85459799 | R9: 0 | S9: <Null> | T9: OSE File No. LWD-SF-0310, Stock Tank, | V9: 9 | X9: LWD-SF-0310 | Y9: T5S | Z9: R20W | AA9: 24 | AB9: CA | AC9: Clyde Hamblin | AD9: 1894 | AE9: 428 | AI9: 253.68967 | AJ9: 3458.4492
A10: 9 | B10: GSLU-00009 | C10: GSF | D10: GSLU | E10: MM | G10: 45861 | H10: 0.38043626 | I10: Arizona v California | J10: San Francisco River | K10: SF | L10: Luna | M10: LU | O10: STD | P10: Stock Rank, Dry | Q10: 0.38043626 | R10: 0 | S10: <Null> | T10: OSE File No. LWD-SF-0310, Stock Tank, | V10: 9 | X10: LWD-SF-0310 | Y10: T5S | Z10: R20W | AA10: 24 | AB10: CA | AC10: Reynolds Bros. | AD10: 1894 | AE10: 428 | AI10: 197.63554 | AJ10: 1539.5771
A11: 10 | B11: GSLU-00010 | C11: GSF | D11: GSLU | E11: MM | G11: 45861 | H11: 4.4841213 | I11: Arizona v California | J11: San Francisco River | K11: SF | L11: Luna | M11: LU | O11: PN | P11: Pasture (Native) | Q11: 4.4841213 | R11: 1 | S11: Flood irrigated | T11: OSE File No. 01098, William S Laney Ditch | V11: 9 | X11: 01098 | Y11: T5S | Z11: R20W | AA11: 24 | AB11: CA | AC11: Randolph Jenks | AD11: 1892 | AE11: 430 | AI11: 563.50372 | AJ11: 18146.668
A12: 11 | B12: GSLU-00013 | C12: GSF | D12: GSLU | E12: MM | G12: 45861 | H12: 2.2756253 | I12: Arizona v California | J12: San Francisco River | K12: SF | L12: Luna | M12: LU | O12: PN | P12: Pasture (Native) | Q12: 2.2756253 | R12: 1 | S12: Flood irrigated | T12: OSE File No. 01098, William S Laney Ditch | V12: 9 | X12: 01098 | Y12: T5S | Z12: R20W | AA12: 24 | AB12: CA | AC12: Randolph Jenks | AD12: 1894 | AE12: 432 | AI12: 419.92362 | AJ12: 9209.1657
A13: 12 | B13: GSLU-00014 | C13: GSF | D13: GSLU | E13: MM | G13: 45861 | H13: 3.4686161 | I13: Arizona v California | J13: San Francisco River | K13: SF | L13: Luna | M13: LU | O13: PN | P13: Pasture (Native) | Q13: 3.4686161 | R13: 1 | S13: Flood irrigated | T13: OSE File No. 01098, William S Laney Ditch | V13: 10 | X13: 01098 | Y13: T5S | Z13: R20W | AA13: 24 | AB13: CA | AC13: Reynolds Bros. | AD13: 1894 | AE13: 425 & 428 | AI13: 485.62566 | AJ13: 14037.048
A14: 13 | B14: GSLU-00015 | C14: GSF | D14: GSLU | E14: MM | G14: 45861 | H14: 1.8545625 | I14: Arizona v California | J14: San Francisco River | K14: SF | L14: Luna | M14: LU | O14: PN | P14: Pasture (Native) | Q14: 1.8545625 | R14: 1 | S14: Flood irrigated | T14: OSE File No. 01098, William S Laney Ditch | V14: 10 | X14: 01098 | Y14: T5S | Z14: R20W | AA14: 24 | AB14: CA | AC14: Reynolds Bros. | AD14: 1894 | AE14: 425 & 428 | AI14: 403.31654 | AJ14: 7505.178
